Workbook

Sheet TABLE CORRECTED
C1: Rate Poundage 72-73 | D1: Rate Poundage 73-74 | E1: Rate Poundage 73-74 Local purpose | F1: Rate Poundage 73-74 County Purposes | G1: Rate Poundage 73-74 Other Purpose | H1: Average rate Poundage 1973-74 | I1: Peeny rate Product 1971-73 | J1: Change in penney rate product from 1972-73 | K1: Rate Call 1973-74 | L1: Resources element of rate support Grant | M1: Total rateable value in April 1973 | N1: N Total Domestic(Including Crown Domestic) | O1: POUNDS Total Domestic(Including Crown Domestic) | P1: N £1-£150 | Q1: POUNDS £1-£150 | R1: N£151-£400 | S1: POUNDS £151-£400 | T1: N Over £400 | U1: POUNDS Over £400 | V1: Shops | W1: Offices | X1: Other Commercial | Y1: Industrial | Z1: All other including non-domestic Crown Property | AA1: Domestic heriditaments total | AB1: Domestic heriditaments ratio | AD1: CONCAT | AE1: CONCAT EDITED | AF1: equiv_1971_nm | AG1: equiv_1971_cd | AH1: cty_1981 | AI1: rgn | AJ1: srgn
A2: County totals | B2: ='TABLE Summary'!B2 -> 3110000 | C2: ='TABLE Summary'!C2 -> 0 | D2: ='TABLE Summary'!D2 -> 0 | E2: ='TABLE Summary'!E2 -> 0 | F2: ='TABLE Summary'!F2 -> 0 | G2: ='TABLE Summary'!G2 -> 0 | H2: ='TABLE Summary'!H2 -> 46.4 | I2: ='TABLE Summary'!I2 -> 411943 | ... L2: ='TABLE Summary'!L2 -> 0 | M2: ='TABLE Summary'!M2*1000 -> 41815300 | N2: ='TABLE Summary'!N2 -> 100574 | O2: ='TABLE Summary'!O2*1000 -> 21763900 | P2: ='TABLE Summary'!P2 -> 20041 | Q2: ='TABLE Summary'!Q2*1000 -> 2308600 | R2: ='TABLE Summary'!R2 -> 78229 | S2: ='TABLE Summary'!S2*1000 -> 18300200 | T2: ='TABLE Summary'!T2 -> 2176 | U2: ='TABLE Summary'!U2*1000 -> 1055000 | V2: ='TABLE Summary'!V2*1000 -> 3091400 | W2: ='TABLE Summary'!W2*1000 -> 1004300 | X2: ='TABLE Summary'!X2*1000 -> 3426800 | Y2: ='TABLE Summary'!Y2*1000 -> 6536900 | Z2: ='TABLE Summary'!Z2*1000 -> 5992000 | AA2: =SUM(Q2+S2+U2) -> 21663800 | AB2: =AA2/M2 -> 0.51808309
A3: Bedford | B3: ='TABLE Summary'!B3 -> 73960 | C3: ='TABLE Summary'!C3 -> 101.5 | D3: ='TABLE Summary'!D3 -> 50 | E3: ='TABLE Summary'!E3 -> 17 | F3: ='TABLE Summary'!F3 -> 33 | G3: ='TABLE Summary'!G3 -> 0 | H3: ='TABLE Summary'!H3 -> 0 | I3: ='TABLE Summary'!I3 -> 103250 | ... L3: ='TABLE Summary'!L3 -> 0 | M3: ='TABLE Summary'!M3*1000 -> 10503200 | N3: ='TABLE Summary'!N3 -> 23506 | O3: ='TABLE Summary'!O3*1000 -> 4835700 | P3: ='TABLE Summary'!P3 -> 6125 | Q3: ='TABLE Summary'!Q3*1000 -> 751000 | R3: ='TABLE Summary'!R3 -> 16955 | S3: ='TABLE Summary'!S3*1000 -> 3892000 | T3: ='TABLE Summary'!T3 -> 406 | U3: ='TABLE Summary'!U3*1000 -> 185800 | V3: ='TABLE Summary'!V3*1000 -> 1593900 | W3: ='TABLE Summary'!W3*1000 -> 459900 | X3: ='TABLE Summary'!X3*1000 -> 805500 | Y3: ='TABLE Summary'!Y3*1000 -> 1219000 | Z3: ='TABLE Summary'!Z3*1000 -> 1589200 | AA3: =SUM(Q3+S3+U3) -> 4828800 | AB3: =AA3/M3 -> 0.4597456 | AC3: M.B. | AD3: =_xlfn.CONCAT(A3," ",AC3) -> Bedford M.B. | AE3: =AD3 -> Bedford M.B. | AF3: =INDEX(Lookup!G$2:G$1349, MATCH($AE3, Lookup!$G$2:$G$1349,0)) -> BEDFORD M.B. | AG3: =INDEX(Lookup!F$2:F$1349, MATCH($AE3, Lookup!$G$2:$G$1349,0)) -> e010002 | AH3: =INDEX(Lookup!C$2:C$1349, MATCH($AE3, Lookup!$G$2:$G$1349,0)) -> Bedfordshire | AI3: =INDEX(Lookup!D$2:D$1349, MATCH($AE3, Lookup!$G$2:$G$1349,0)) -> East of England | AJ3: =INDEX(Lookup!E$2:E$1349, MATCH($AE3, Lookup!$G$2:$G$1349,0)) -> Greater South East
A4: Dunstable | B4: ='TABLE Summary'!B4 -> 32040 | C4: ='TABLE Summary'!C4 -> 97.5 | D4: ='TABLE Summary'!D4 -> 47.5 | E4: ='TABLE Summary'!E4 -> 13 | F4: ='TABLE Summary'!F4 -> 34.5 | G4: ='TABLE Summary'!G4 -> 0 | H4: ='TABLE Summary'!H4 -> 0 | I4: ='TABLE Summary'!I4 -> 66200 | ... L4: ='TABLE Summary'!L4 -> 0 | M4: ='TABLE Summary'!M4*1000 -> 6797800 | N4: ='TABLE Summary'!N4 -> 10384 | O4: ='TABLE Summary'!O4*1000 -> 2571900 | P4: ='TABLE Summary'!P4 -> 423 | Q4: ='TABLE Summary'!Q4*1000 -> 57500 | R4: ='TABLE Summary'!R4 -> 9805 | S4: ='TABLE Summary'!S4*1000 -> 2441500 | T4: ='TABLE Summary'!T4 -> 154 | U4: ='TABLE Summary'!U4*1000 -> 72800 | V4: ='TABLE Summary'!V4*1000 -> 576400 | W4: ='TABLE Summary'!W4*1000 -> 117200 | X4: ='TABLE Summary'!X4*1000 -> 273800 | Y4: ='TABLE Summary'!Y4*1000 -> 2720400 | Z4: ='TABLE Summary'!Z4*1000 -> 538100 | AA4: =SUM(Q4+S4+U4) -> 2571800 | AB4: =AA4/M4 -> 0.37832828 | AC4: M.B. | AD4: =_xlfn.CONCAT(A4," ",AC4) -> Dunstable M.B. | AE4: Luton C.B. | AF4: =INDEX(Lookup!G$2:G$1349, MATCH($AE4, Lookup!$G$2:$G$1349,0)) -> LUTON C.B. | AG4: =INDEX(Lookup!F$2:F$1349, MATCH($AE4, Lookup!$G$2:$G$1349,0)) -> e010000 | AH4: =INDEX(Lookup!C$2:C$1349, MATCH($AE4, Lookup!$G$2:$G$1349,0)) -> Bedfordshire | AI4: =INDEX(Lookup!D$2:D$1349, MATCH($AE4, Lookup!$G$2:$G$1349,0)) -> East of England | AJ4: =INDEX(Lookup!E$2:E$1349, MATCH($AE4, Lookup!$G$2:$G$1349,0)) -> Greater South East
A5: Ampthill | B5: ='TABLE Summary'!B5 -> 5750 | C5: ='TABLE Summary'!C5 -> 90.5 | D5: ='TABLE Summary'!D5 -> 41.5 | E5: ='TABLE Summary'!E5 -> 7 | F5: ='TABLE Summary'!F5 -> 34.5 | G5: ='TABLE Summary'!G5 -> 0 | H5: ='TABLE Summary'!H5 -> 0 | I5: ='TABLE Summary'!I5 -> 6500 | ... L5: ='TABLE Summary'!L5 -> 11.2 | M5: ='TABLE Summary'!M5*1000 -> 689900 | N5: ='TABLE Summary'!N5 -> 1934 | O5: ='TABLE Summary'!O5*1000 -> 439500 | P5: ='TABLE Summary'!P5 -> 384 | Q5: ='TABLE Summary'!Q5*1000 -> 42000 | R5: ='TABLE Summary'!R5 -> 1509 | S5: ='TABLE Summary'!S5*1000 -> 378100 | T5: ='TABLE Summary'!T5 -> 41 | U5: ='TABLE Summary'!U5*1000 -> 19400 | V5: ='TABLE Summary'!V5*1000 -> 58800 | W5: ='TABLE Summary'!W5*1000 -> 15800 | X5: ='TABLE Summary'!X5*1000 -> 61700 | Y5: ='TABLE Summary'!Y5*1000 -> 14900 | Z5: ='TABLE Summary'!Z5*1000 -> 99200 | AA5: =SUM(Q5+S5+U5) -> 439500 | AB5: =AA5/M5 -> 0.63704885 | AC5: U.D. | AD5: =_xlfn.CONCAT(A5," ",AC5) -> Ampthill U.D. | AE5: =AD5 -> Ampthill U.D. | AF5: =INDEX(Lookup!G$2:G$1349, MATCH($AE5, Lookup!$G$2:$G$1349,0)) -> AMPTHILL U.D. | AG5: =INDEX(Lookup!F$2:F$1349, MATCH($AE5, Lookup!$G$2:$G$1349,0)) -> e010001 | AH5: =INDEX(Lookup!C$2:C$1349, MATCH($AE5, Lookup!$G$2:$G$1349,0)) -> Bedfordshire | AI5: =INDEX(Lookup!D$2:D$1349, MATCH($AE5, Lookup!$G$2:$G$1349,0)) -> East of England | AJ5: =INDEX(Lookup!E$2:E$1349, MATCH($AE5, Lookup!$G$2:$G$1349,0)) -> Greater South East
A6: Biggleswade | B6: ='TABLE Summary'!B6 -> 9790 | C6: ='TABLE Summary'!C6 -> 101.4 | D6: ='TABLE Summary'!D6 -> 46 | E6: ='TABLE Summary'!E6 -> 11.5 | F6: ='TABLE Summary'!F6 -> 34.5 | G6: ='TABLE Summary'!G6 -> 0 | H6: ='TABLE Summary'!H6 -> 0 | I6: ='TABLE Summary'!I6 -> 15120 | ... L6: ='TABLE Summary'!L6 -> 0 | M6: ='TABLE Summary'!M6*1000 -> 1568100 | N6: ='TABLE Summary'!N6 -> 3381 | O6: ='TABLE Summary'!O6*1000 -> 665000 | P6: ='TABLE Summary'!P6 -> 824 | Q6: ='TABLE Summary'!Q6*1000 -> 98100 | R6: ='TABLE Summary'!R6 -> 1536 | S6: ='TABLE Summary'!S6*1000 -> 558300 | T6: ='TABLE Summary'!T6 -> 18 | U6: ='TABLE Summary'!U6*1000 -> 8300 | V6: ='TABLE Summary'!V6*1000 -> 180200 | W6: ='TABLE Summary'!W6*1000 -> 32200 | X6: ='TABLE Summary'!X6*1000 -> 141900 | Y6: ='TABLE Summary'!Y6*1000 -> 405900 | Z6: ='TABLE Summary'!Z6*1000 -> 143000 | AA6: =SUM(Q6+S6+U6) -> 664700 | AB6: =AA6/M6 -> 0.42388878 | AC6: U.D. | AD6: =_xlfn.CONCAT(A6," ",AC6) -> Biggleswade U.D. | AE6: =AD6 -> Biggleswade U.D. | AF6: =INDEX(Lookup!G$2:G$1349, MATCH($AE6, Lookup!$G$2:$G$1349,0)) -> BIGGLESWADE U.D. | AG6: =INDEX(Lookup!F$2:F$1349, MATCH($AE6, Lookup!$G$2:$G$1349,0)) -> e010003 | AH6: =INDEX(Lookup!C$2:C$1349, MATCH($AE6, Lookup!$G$2:$G$1349,0)) -> Bedfordshire | AI6: =INDEX(Lookup!D$2:D$1349, MATCH($AE6, Lookup!$G$2:$G$1349,0)) -> East of England | AJ6: =INDEX(Lookup!E$2:E$1349, MATCH($AE6, Lookup!$G$2:$G$1349,0)) -> Greater South East
A7: Kempston | B7: ='TABLE Summary'!B7 -> 13060 | C7: ='TABLE Summary'!C7 -> 95 | D7: ='TABLE Summary'!D7 -> 46.5 | E7: ='TABLE Summary'!E7 -> 11.8 | F7: ='TABLE Summary'!F7 -> 34.5 | G7: ='TABLE Summary'!G7 -> 0.2 | H7: ='TABLE Summary'!H7 -> 0 | I7: ='TABLE Summary'!I7 -> 16650 | ... L7: ='TABLE Summary'!L7 -> 4.9 | M7: ='TABLE Summary'!M7*1000 -> 1650600 | N7: ='TABLE Summary'!N7 -> 4550 | O7: ='TABLE Summary'!O7*1000 -> 904700 | P7: ='TABLE Summary'!P7 -> 765 | Q7: ='TABLE Summary'!Q7*1000 -> 91300 | R7: ='TABLE Summary'!R7 -> 3740 | S7: ='TABLE Summary'!S7*1000 -> 805200 | T7: ='TABLE Summary'!T7 -> 8 | U7: ='TABLE Summary'!U7*1000 -> 3600 | V7: ='TABLE Summary'!V7*1000 -> 75800 | W7: ='TABLE Summary'!W7*1000 -> 85200 | X7: ='TABLE Summary'!X7*1000 -> 141900 | Y7: ='TABLE Summary'!Y7*1000 -> 288700 | Z7: ='TABLE Summary'!Z7*1000 -> 154400 | AA7: =SUM(Q7+S7+U7) -> 900100 | AB7: =AA7/M7 -> 0.54531685 | AC7: U.D. | AD7: =_xlfn.CONCAT(A7," ",AC7) -> Kempston U.D. | AE7: =AD7 -> Kempston U.D. | AF7: =INDEX(Lookup!G$2:G$1349, MATCH($AE7, Lookup!$G$2:$G$1349,0)) -> KEMPSTON U.D. | AG7: =INDEX(Lookup!F$2:F$1349, MATCH($AE7, Lookup!$G$2:$G$1349,0)) -> e010005 | AH7: =INDEX(Lookup!C$2:C$1349, MATCH($AE7, Lookup!$G$2:$G$1349,0)) -> Bedfordshire | AI7: =INDEX(Lookup!D$2:D$1349, MATCH($AE7, Lookup!$G$2:$G$1349,0)) -> East of England | AJ7: =INDEX(Lookup!E$2:E$1349, MATCH($AE7, Lookup!$G$2:$G$1349,0)) -> Greater South East
A8: Leighton-Linslade | B8: ='TABLE Summary'!B8 -> 21650 | C8: ='TABLE Summary'!C8 -> 105.5 | D8: ='TABLE Summary'!D8 -> 48 | E8: ='TABLE Summary'!E8 -> 13.5 | F8: ='TABLE Summary'!F8 -> 34.5 | G8: ='TABLE Summary'!G8 -> 0 | H8: ='TABLE Summary'!H8 -> 0 | I8: ='TABLE Summary'!I8 -> 29875 | ... L8: ='TABLE Summary'!L8 -> 0 | M8: ='TABLE Summary'!M8*1000 -> 3086000 | N8: ='TABLE Summary'!N8 -> 7252 | O8: ='TABLE Summary'!O8*1000 -> 1730000 | P8: ='TABLE Summary'!P8 -> 991 | Q8: ='TABLE Summary'!Q8*1000 -> 124500 | R8: ='TABLE Summary'!R8 -> 5984 | S8: ='TABLE Summary'!S8*1000 -> 1470700 | T8: ='TABLE Summary'!T8 -> 274 | U8: ='TABLE Summary'!U8*1000 -> 124000 | V8: ='TABLE Summary'!V8*1000 -> 195200 | W8: ='TABLE Summary'!W8*1000 -> 53200 | X8: ='TABLE Summary'!X8*1000 -> 285500 | Y8: ='TABLE Summary'!Y8*1000 -> 553000 | Z8: ='TABLE Summary'!Z8*1000 -> 268300 | AA8: =SUM(Q8+S8+U8) -> 1719200 | AB8: =AA8/M8 -> 0.55709657 | AC8: U.D. | AD8: =_xlfn.CONCAT(A8," ",AC8) -> Leighton-Linslade U.D. | AE8: =AD8 -> Leighton-Linslade U.D. | AF8: =INDEX(Lookup!G$2:G$1349, MATCH($AE8, Lookup!$G$2:$G$1349,0)) -> LEIGHTON-LINSLADE U.D. | AG8: =INDEX(Lookup!F$2:F$1349, MATCH($AE8, Lookup!$G$2:$G$1349,0)) -> e010006 | AH8: =INDEX(Lookup!C$2:C$1349, MATCH($AE8, Lookup!$G$2:$G$1349,0)) -> Bedfordshire | AI8: =INDEX(Lookup!D$2:D$1349, MATCH($AE8, Lookup!$G$2:$G$1349,0)) -> East of England | AJ8: =INDEX(Lookup!E$2:E$1349, MATCH($AE8, Lookup!$G$2:$G$1349,0)) -> Greater South East
A9: Sandy | B9: ='TABLE Summary'!B9 -> 5660 | C9: ='TABLE Summary'!C9 -> 103.5 | D9: ='TABLE Summary'!D9 -> 46.8 | E9: ='TABLE Summary'!E9 -> 12.3 | F9: ='TABLE Summary'!F9 -> 34.5 | G9: ='TABLE Summary'!G9 -> 0 | H9: ='TABLE Summary'!H9 -> 0 | I9: ='TABLE Summary'!I9 -> 7600 | ... L9: ='TABLE Summary'!L9 -> 1 | M9: ='TABLE Summary'!M9*1000 -> 758200 | N9: ='TABLE Summary'!N9 -> 2145 | O9: ='TABLE Summary'!O9*1000 -> 432000 | P9: ='TABLE Summary'!P9 -> 509 | Q9: ='TABLE Summary'!Q9*1000 -> 56100 | R9: ='TABLE Summary'!R9 -> 1598 | S9: ='TABLE Summary'!S9*1000 -> 356400 | T9: ='TABLE Summary'!T9 -> 37 | U9: ='TABLE Summary'!U9*1000 -> 19500 | V9: ='TABLE Summary'!V9*1000 -> 41100 | W9: ='TABLE Summary'!W9*1000 -> 14900 | X9: ='TABLE Summary'!X9*1000 -> 62800 | Y9: ='TABLE Summary'!Y9*1000 -> 119000 | Z9: ='TABLE Summary'!Z9*1000 -> 88300 | AA9: =SUM(Q9+S9+U9) -> 432000 | AB9: =AA9/M9 -> 0.56977051 | AC9: U.D. | AD9: =_xlfn.CONCAT(A9," ",AC9) -> Sandy U.D. | AE9: =AD9 -> Sandy U.D. | AF9: =INDEX(Lookup!G$2:G$1349, MATCH($AE9, Lookup!$G$2:$G$1349,0)) -> SANDY U.D. | AG9: =INDEX(Lookup!F$2:F$1349, MATCH($AE9, Lookup!$G$2:$G$1349,0)) -> e010007 | AH9: =INDEX(Lookup!C$2:C$1349, MATCH($AE9, Lookup!$G$2:$G$1349,0)) -> Bedfordshire | AI9: =INDEX(Lookup!D$2:D$1349, MATCH($AE9, Lookup!$G$2:$G$1349,0)) -> East of England | AJ9: =INDEX(Lookup!E$2:E$1349, MATCH($AE9, Lookup!$G$2:$G$1349,0)) -> Greater South East
A10: Ampthill | B10: ='TABLE Summary'!B10 -> 34570 | C10: ='TABLE Summary'!C10 -> 89 | D10: ='TABLE Summary'!D10 -> 42.8 | E10: ='TABLE Summary'!E10 -> 8.3 | F10: ='TABLE Summary'!F10 -> 34.5 | G10: ='TABLE Summary'!G10 -> 0 | H10: ='TABLE Summary'!H10 -> 43.9 | I10: ='TABLE Summary'!I10 -> 36220 | ... L10: ='TABLE Summary'!L10 -> 13.7 | M10: ='TABLE Summary'!M10*1000 -> 4008500 | N10: ='TABLE Summary'!N10 -> 11153 | O10: ='TABLE Summary'!O10*1000 -> 2325900 | P10: ='TABLE Summary'!P10 -> 2723 | Q10: ='TABLE Summary'!Q10*1000 -> 298200 | R10: ='TABLE Summary'!R10 -> 8121 | S10: ='TABLE Summary'!S10*1000 -> 1877200 | T10: ='TABLE Summary'!T10 -> 306 | U10: ='TABLE Summary'!U10*1000 -> 150400 | V10: ='TABLE Summary'!V10*1000 -> 79300 | W10: ='TABLE Summary'!W10*1000 -> 16000 | X10: ='TABLE Summary'!X10*1000 -> 281600 | Y10: ='TABLE Summary'!Y10*1000 -> 129900 | Z10: ='TABLE Summary'!Z10*1000 -> 1175900 | AA10: =SUM(Q10+S10+U10) -> 2325800 | AB10: =AA10/M10 -> 0.58021704 | AC10: R.D. | AD10: =_xlfn.CONCAT(A10," ",AC10) -> Ampthill R.D. | AE10: =AD10 -> Ampthill R.D. | AF10: =INDEX(Lookup!G$2:G$1349, MATCH($AE10, Lookup!$G$2:$G$1349,0)) -> AMPTHILL R.D. | AG10: =INDEX(Lookup!F$2:F$1349, MATCH($AE10, Lookup!$G$2:$G$1349,0)) -> e010008 | AH10: =INDEX(Lookup!C$2:C$1349, MATCH($AE10, Lookup!$G$2:$G$1349,0)) -> Bedfordshire | AI10: =INDEX(Lookup!D$2:D$1349, MATCH($AE10, Lookup!$G$2:$G$1349,0)) -> East of England | AJ10: =INDEX(Lookup!E$2:E$1349, MATCH($AE10, Lookup!$G$2:$G$1349,0)) -> Greater South East
A11: Bedford | B11: ='TABLE Summary'!B11 -> 39540 | C11: ='TABLE Summary'!C11 -> 87.3 | D11: ='TABLE Summary'!D11 -> 41.6 | E11: ='TABLE Summary'!E11 -> 7.1 | F11: ='TABLE Summary'!F11 -> 34.5 | G11: ='TABLE Summary'!G11 -> 0 | H11: ='TABLE Summary'!H11 -> 42.3 | I11: ='TABLE Summary'!I11 -> 47328 | ... L11: ='TABLE Summary'!L11 -> 13.1 | M11: ='TABLE Summary'!M11*1000 -> 4631700 | N11: ='TABLE Summary'!N11 -> 13667 | O11: ='TABLE Summary'!O11*1000 -> 2853600 | P11: ='TABLE Summary'!P11 -> 3471 | Q11: ='TABLE Summary'!Q11*1000 -> 367500 | R11: ='TABLE Summary'!R11 -> 9723 | S11: ='TABLE Summary'!S11*1000 -> 2234900 | T11: ='TABLE Summary'!T11 -> 443 | U11: ='TABLE Summary'!U11*1000 -> 228900 | V11: ='TABLE Summary'!V11*1000 -> 54900 | W11: ='TABLE Summary'!W11*1000 -> 106900 | X11: ='TABLE Summary'!X11*1000 -> 251500 | Y11: ='TABLE Summary'!Y11*1000 -> 606800 | Z11: ='TABLE Summary'!Z11*1000 -> 758000 | AA11: =SUM(Q11+S11+U11) -> 2831300 | AB11: =AA11/M11 -> 0.61128743 | AC11: R.D. | AD11: =_xlfn.CONCAT(A11," ",AC11) -> Bedford R.D. | AE11: =AD11 -> Bedford R.D. | AF11: =INDEX(Lookup!G$2:G$1349, MATCH($AE11, Lookup!$G$2:$G$1349,0)) -> BEDFORD R.D. | AG11: =INDEX(Lookup!F$2:F$1349, MATCH($AE11, Lookup!$G$2:$G$1349,0)) -> e010009 | AH11: =INDEX(Lookup!C$2:C$1349, MATCH($AE11, Lookup!$G$2:$G$1349,0)) -> Bedfordshire | AI11: =INDEX(Lookup!D$2:D$1349, MATCH($AE11, Lookup!$G$2:$G$1349,0)) -> East of England | AJ11: =INDEX(Lookup!E$2:E$1349, MATCH($AE11, Lookup!$G$2:$G$1349,0)) -> Greater South East
A12: Biggleswade | B12: ='TABLE Summary'!B12 -> 37690 | C12: ='TABLE Summary'!C12 -> 84 | D12: ='TABLE Summary'!D12 -> 38.3 | E12: ='TABLE Summary'!E12 -> 3.8 | F12: ='TABLE Summary'!F12 -> 34.5 | G12: ='TABLE Summary'!G12 -> 0 | H12: ='TABLE Summary'!H12 -> 39.5 | I12: ='TABLE Summary'!I12 -> 33000 | ... L12: ='TABLE Summary'!L12 -> 37.7 | M12: ='TABLE Summary'!M12*1000 -> 3156600 | N12: ='TABLE Summary'!N12 -> 10515 | O12: ='TABLE Summary'!O12*1000 -> 2218600 | P12: ='TABLE Summary'!P12 -> 2328 | Q12: ='TABLE Summary'!Q12*1000 -> 251100 | R12: ='TABLE Summary'!R12 -> 8014 | S12: ='TABLE Summary'!S12*1000 -> 1845000 | T12: ='TABLE Summary'!T12 -> 147 | U12: ='TABLE Summary'!U12*1000 -> 72100 | V12: ='TABLE Summary'!V12*1000 -> 124400 | W12: ='TABLE Summary'!W12*1000 -> 45300 | X12: ='TABLE Summary'!X12*1000 -> 182500 | Y12: ='TABLE Summary'!Y12*1000 -> 173000 | Z12: ='TABLE Summary'!Z12*1000 -> 412900 | AA12: =SUM(Q12+S12+U12) -> 2168200 | AB12: =AA12/M12 -> 0.68687829 | AC12: R.D. | AD12: =_xlfn.CONCAT(A12," ",AC12) -> Biggleswade R.D. | AE12: =AD12 -> Biggleswade R.D. | AF12: =INDEX(Lookup!G$2:G$1349, MATCH($AE12, Lookup!$G$2:$G$1349,0)) -> BIGGLESWADE R.D. | AG12: =INDEX(Lookup!F$2:F$1349, MATCH($AE12, Lookup!$G$2:$G$1349,0)) -> e010010 | AH12: =INDEX(Lookup!C$2:C$1349, MATCH($AE12, Lookup!$G$2:$G$1349,0)) -> Bedfordshire | AI12: =INDEX(Lookup!D$2:D$1349, MATCH($AE12, Lookup!$G$2:$G$1349,0)) -> East of England | AJ12: =INDEX(Lookup!E$2:E$1349, MATCH($AE12, Lookup!$G$2:$G$1349,0)) -> Greater South East
A13: Luton | B13: ='TABLE Summary'!B13 -> 37920 | C13: ='TABLE Summary'!C13 -> 99.5 | D13: ='TABLE Summary'!D13 -> 47 | E13: ='TABLE Summary'!E13 -> 12.5 | F13: ='TABLE Summary'!F13 -> 34.5 | G13: ='TABLE Summary'!G13 -> 0 | H13: ='TABLE Summary'!H13 -> 47.4 | I13: ='TABLE Summary'!I13 -> 50200 | ... L13: ='TABLE Summary'!L13 -> 1.1 | M13: ='TABLE Summary'!M13*1000 -> 4964600 | N13: ='TABLE Summary'!N13 -> 12087 | O13: ='TABLE Summary'!O13*1000 -> 2786300 | P13: ='TABLE Summary'!P13 -> 1498 | Q13: ='TABLE Summary'!Q13*1000 -> 171300 | R13: ='TABLE Summary'!R13 -> 10244 | S13: ='TABLE Summary'!S13*1000 -> 2440900 | T13: ='TABLE Summary'!T13 -> 342 | U13: ='TABLE Summary'!U13*1000 -> 170200 | V13: ='TABLE Summary'!V13*1000 -> 111600 | W13: ='TABLE Summary'!W13*1000 -> 57400 | X13: ='TABLE Summary'!X13*1000 -> 938100 | Y13: ='TABLE Summary'!Y13*1000 -> 306300 | Z13: ='TABLE Summary'!Z13*1000 -> 764900 | AA13: =SUM(Q13+S13+U13) -> 2782400 | AB13: =AA13/M13 -> 0.56044797 | AC13: R.D. | AD13: =_xlfn.CONCAT(A13," ",AC13) -> Luton R.D. | AE13: Luton C.B. | AF13: =INDEX(Lookup!G$2:G$1349, MATCH($AE13, Lookup!$G$2:$G$1349,0)) -> LUTON C.B. | AG13: =INDEX(Lookup!F$2:F$1349, MATCH($AE13, Lookup!$G$2:$G$1349,0)) -> e010000 | AH13: =INDEX(Lookup!C$2:C$1349, MATCH($AE13, Lookup!$G$2:$G$1349,0)) -> Bedfordshire | AI13: =INDEX(Lookup!D$2:D$1349, MATCH($AE13, Lookup!$G$2:$G$1349,0)) -> East of England | AJ13: =INDEX(Lookup!E$2:E$1349, MATCH($AE13, Lookup!$G$2:$G$1349,0)) -> Greater South East
A14: BERKSHIRE | B14: ='TABLE Summary'!B14 -> 0 | C14: ='TABLE Summary'!C14 -> 0 | D14: ='TABLE Summary'!D14 -> 0 | E14: ='TABLE Summary'!E14 -> 0 | F14: ='TABLE Summary'!F14 -> 0 | G14: ='TABLE Summary'!G14 -> 0 | H14: ='TABLE Summary'!H14 -> 0 | I14: ='TABLE Summary'!I14 -> 0 | ... L14: ='TABLE Summary'!L14 -> 0 | M14: ='TABLE Summary'!M14*1000 -> 0 | N14: ='TABLE Summary'!N14 -> 0 | O14: ='TABLE Summary'!O14*1000 -> 0 | P14: ='TABLE Summary'!P14 -> 0 | Q14: ='TABLE Summary'!Q14*1000 -> 0 | R14: ='TABLE Summary'!R14 -> 0 | S14: ='TABLE Summary'!S14*1000 -> 0 | T14: ='TABLE Summary'!T14 -> 0 | U14: ='TABLE Summary'!U14*1000 -> 0 | V14: ='TABLE Summary'!V14*1000 -> 0 | W14: ='TABLE Summary'!W14*1000 -> 0 | X14: ='TABLE Summary'!X14*1000 -> 0 | Y14: ='TABLE Summary'!Y14*1000 -> 0 | Z14: ='TABLE Summary'!Z14*1000 -> 0 | AA14: =SUM(Q14+S14+U14) -> 0 | AB14: =AA14/M14 -> #DIV/0! | AE14: =AD14 -> 0 | AF14: =INDEX(Lookup!G$2:G$1349, MATCH($AE14, Lookup!$G$2:$G$1349,0)) -> #N/A | AG14: =INDEX(Lookup!F$2:F$1349, MATCH($AE14, Lookup!$G$2:$G$1349,0)) -> #N/A | AH14: =INDEX(Lookup!C$2:C$1349, MATCH($AE14, Lookup!$G$2:$G$1349,0)) -> #N/A | AI14: =INDEX(Lookup!D$2:D$1349, MATCH($AE14, Lookup!$G$2:$G$1349,0)) -> #N/A | AJ14: =INDEX(Lookup!E$2:E$1349, MATCH($AE14, Lookup!$G$2:$G$1349,0)) -> #N/A
A15: General County Precept | B15: ='TABLE Summary'!B15 -> 0 | C15: ='TABLE Summary'!C15 -> 56.2 | D15: ='TABLE Summary'!D15 -> 23.2 | E15: ='TABLE Summary'!E15 -> 0 | F15: ='TABLE Summary'!F15 -> 0 | G15: ='TABLE Summary'!G15 -> 0 | H15: ='TABLE Summary'!H15 -> 0 | I15: ='TABLE Summary'!I15 -> 687812 | ... L15: ='TABLE Summary'!L15 -> 1.5 | M15: ='TABLE Summary'!M15*1000 -> 0 | N15: ='TABLE Summary'!N15 -> 0 | O15: ='TABLE Summary'!O15*1000 -> 0 | P15: ='TABLE Summary'!P15 -> 0 | Q15: ='TABLE Summary'!Q15*1000 -> 0 | R15: ='TABLE Summary'!R15 -> 0 | S15: ='TABLE Summary'!S15*1000 -> 0 | T15: ='TABLE Summary'!T15 -> 0 | U15: ='TABLE Summary'!U15*1000 -> 0 | V15: ='TABLE Summary'!V15*1000 -> 0 | W15: ='TABLE Summary'!W15*1000 -> 0 | X15: ='TABLE Summary'!X15*1000 -> 0 | Y15: ='TABLE Summary'!Y15*1000 -> 0 | Z15: ='TABLE Summary'!Z15*1000 -> 0 | AA15: =SUM(Q15+S15+U15) -> 0 | AB15: =AA15/M15 -> #DIV/0! | AE15: =AD15 -> 0 | AF15: =INDEX(Lookup!G$2:G$1349, MATCH($AE15, Lookup!$G$2:$G$1349,0)) -> #N/A | AG15: =INDEX(Lookup!F$2:F$1349, MATCH($AE15, Lookup!$G$2:$G$1349,0)) -> #N/A | AH15: =INDEX(Lookup!C$2:C$1349, MATCH($AE15, Lookup!$G$2:$G$1349,0)) -> #N/A | AI15: =INDEX(Lookup!D$2:D$1349, MATCH($AE15, Lookup!$G$2:$G$1349,0)) -> #N/A | AJ15: =INDEX(Lookup!E$2:E$1349, MATCH($AE15, Lookup!$G$2:$G$1349,0)) -> #N/A
A16: County totals | B16: ='TABLE Summary'!B16 -> 523280 | C16: ='TABLE Summary'!C16 -> 0 | D16: ='TABLE Summary'!D16 -> 0 | E16: ='TABLE Summary'!E16 -> 0 | F16: ='TABLE Summary'!F16 -> 0 | G16: ='TABLE Summary'!G16 -> 0 | H16: ='TABLE Summary'!H16 -> 34.3 | I16: ='TABLE Summary'!I16 -> 691927 | ... L16: ='TABLE Summary'!L16 -> 0 | M16: ='TABLE Summary'!M16*1000 -> 69291200 | N16: ='TABLE Summary'!N16 -> 167337 | O16: ='TABLE Summary'!O16*1000 -> 41061100 | P16: ='TABLE Summary'!P16 -> 22724 | Q16: ='TABLE Summary'!Q16*1000 -> 2460000 | R16: ='TABLE Summary'!R16 -> 129325 | S16: ='TABLE Summary'!S16*1000 -> 31820000 | T16: ='TABLE Summary'!T16 -> 12104 | U16: ='TABLE Summary'!U16*1000 -> 6487600 | V16: ='TABLE Summary'!V16*1000 -> 4907000 | W16: ='TABLE Summary'!W16*1000 -> 1877800 | X16: ='TABLE Summary'!X16*1000 -> 4726700 | Y16: ='TABLE Summary'!Y16*1000 -> 7012900 | Z16: ='TABLE Summary'!Z16*1000 -> 9705700 | AA16: =SUM(Q16+S16+U16) -> 40767600 | AB16: =AA16/M16 -> 0.58835177 | AE16: =AD16 -> 0 | AF16: =INDEX(Lookup!G$2:G$1349, MATCH($AE16, Lookup!$G$2:$G$1349,0)) -> #N/A | AG16: =INDEX(Lookup!F$2:F$1349, MATCH($AE16, Lookup!$G$2:$G$1349,0)) -> #N/A | AH16: =INDEX(Lookup!C$2:C$1349, MATCH($AE16, Lookup!$G$2:$G$1349,0)) -> #N/A | AI16: =INDEX(Lookup!D$2:D$1349, MATCH($AE16, Lookup!$G$2:$G$1349,0)) -> #N/A | AJ16: =INDEX(Lookup!E$2:E$1349, MATCH($AE16, Lookup!$G$2:$G$1349,0)) -> #N/A
A17: Abingdon | B17: ='TABLE Summary'!B17 -> 19470 | C17: ='TABLE Summary'!C17 -> 86.5 | D17: ='TABLE Summary'!D17 -> 35 | E17: ='TABLE Summary'!E17 -> 11 | F17: ='TABLE Summary'!F17 -> 24 | G17: ='TABLE Summary'!G17 -> 0 | H17: ='TABLE Summary'!H17 -> 0 | I17: ='TABLE Summary'!I17 -> 25340 | ... L17: ='TABLE Summary'!L17 -> 2.7 | M17: ='TABLE Summary'!M17*1000 -> 2541600 | N17: ='TABLE Summary'!N17 -> 6294 | O17: ='TABLE Summary'!O17*1000 -> 1430800 | P17: ='TABLE Summary'!P17 -> 563 | Q17: ='TABLE Summary'!Q17*1000 -> 67700 | R17: ='TABLE Summary'!R17 -> 5583 | S17: ='TABLE Summary'!S17*1000 -> 1311600 | T17: ='TABLE Summary'!T17 -> 102 | U17: ='TABLE Summary'!U17*1000 -> 48600 | V17: ='TABLE Summary'!V17*1000 -> 309400 | W17: ='TABLE Summary'!W17*1000 -> 32600 | X17: ='TABLE Summary'!X17*1000 -> 116900 | Y17: ='TABLE Summary'!Y17*1000 -> 330000 | Z17: ='TABLE Summary'!Z17*1000 -> 321900 | AA17: =SUM(Q17+S17+U17) -> 1427900 | AB17: =AA17/M17 -> 0.56181146 | AC17: M.B. | AD17: =_xlfn.CONCAT(A17," ",AC17) -> Abingdon M.B. | AE17: =AD17 -> Abingdon M.B. | AF17: =INDEX(Lookup!G$2:G$1349, MATCH($AE17, Lookup!$G$2:$G$1349,0)) -> ABINGDON M.B. | AG17: =INDEX(Lookup!F$2:F$1349, MATCH($AE17, Lookup!$G$2:$G$1349,0)) -> e020013 | AH17: =INDEX(Lookup!C$2:C$1349, MATCH($AE17, Lookup!$G$2:$G$1349,0)) -> Oxfordshire | AI17: =INDEX(Lookup!D$2:D$1349, MATCH($AE17, Lookup!$G$2:$G$1349,0)) -> South East | AJ17: =INDEX(Lookup!E$2:E$1349, MATCH($AE17, Lookup!$G$2:$G$1349,0)) -> Greater South East
A18: Maidenhead | B18: ='TABLE Summary'!B18 -> 47220 | C18: ='TABLE Summary'!C18 -> 81 | D18: ='TABLE Summary'!D18 -> 34 | E18: ='TABLE Summary'!E18 -> 10.8 | F18: ='TABLE Summary'!F18 -> 23.2 | G18: ='TABLE Summary'!G18 -> 0 | H18: ='TABLE Summary'!H18 -> 0 | I18: ='TABLE Summary'!I18 -> 77700 | ... L18: ='TABLE Summary'!L18 -> 0 | M18: ='TABLE Summary'!M18*1000 -> 8066300 | N18: ='TABLE Summary'!N18 -> 15199 | O18: ='TABLE Summary'!O18*1000 -> 4250400 | P18: ='TABLE Summary'!P18 -> 1070 | Q18: ='TABLE Summary'!Q18*1000 -> 130900 | R18: ='TABLE Summary'!R18 -> 12153 | S18: ='TABLE Summary'!S18*1000 -> 3092600 | T18: ='TABLE Summary'!T18 -> 1968 | U18: ='TABLE Summary'!U18*1000 -> 1026100 | V18: ='TABLE Summary'!V18*1000 -> 773700 | W18: ='TABLE Summary'!W18*1000 -> 279300 | X18: ='TABLE Summary'!X18*1000 -> 591800 | Y18: ='TABLE Summary'!Y18*1000 -> 1426600 | Z18: ='TABLE Summary'!Z18*1000 -> 684400 | AA18: =SUM(Q18+S18+U18) -> 4249600 | AB18: =AA18/M18 -> 0.52683386 | AC18: M.B. | AD18: =_xlfn.CONCAT(A18," ",AC18) -> Maidenhead M.B. | AE18: =AD18 -> Maidenhead M.B. | AF18: =INDEX(Lookup!G$2:G$1349, MATCH($AE18, Lookup!$G$2:$G$1349,0)) -> MAIDENHEAD M.B. | AG18: =INDEX(Lookup!F$2:F$1349, MATCH($AE18, Lookup!$G$2:$G$1349,0)) -> e020014 | AH18: =INDEX(Lookup!C$2:C$1349, MATCH($AE18, Lookup!$G$2:$G$1349,0)) -> Berkshire | AI18: =INDEX(Lookup!D$2:D$1349, MATCH($AE18, Lookup!$G$2:$G$1349,0)) -> South East | AJ18: =INDEX(Lookup!E$2:E$1349, MATCH($AE18, Lookup!$G$2:$G$1349,0)) -> Greater South East
A19: Newbury | B19: ='TABLE Summary'!B19 -> 24310 | C19: ='TABLE Summary'!C19 -> 84 | D19: ='TABLE Summary'!D19 -> 33 | E19: ='TABLE Summary'!E19 -> 9.8 | F19: ='TABLE Summary'!F19 -> 23.2 | G19: ='TABLE Summary'!G19 -> 0 | H19: ='TABLE Summary'!H19 -> 0 | I19: ='TABLE Summary'!I19 -> 39450 | ... L19: ='TABLE Summary'!L19 -> 0 | M19: ='TABLE Summary'!M19*1000 -> 4059100 | N19: ='TABLE Summary'!N19 -> 8321 | O19: ='TABLE Summary'!O19*1000 -> 1949200 | P19: ='TABLE Summary'!P19 -> 1474 | Q19: ='TABLE Summary'!Q19*1000 -> 177000 | R19: ='TABLE Summary'!R19 -> 6536 | S19: ='TABLE Summary'!S19*1000 -> 1623100 | T19: ='TABLE Summary'!T19 -> 304 | U19: ='TABLE Summary'!U19*1000 -> 147900 | V19: ='TABLE Summary'!V19*1000 -> 801000 | W19: ='TABLE Summary'!W19*1000 -> 183600 | X19: ='TABLE Summary'!X19*1000 -> 430400 | Y19: ='TABLE Summary'!Y19*1000 -> 399200 | Z19: ='TABLE Summary'!Z19*1000 -> 295700 | AA19: =SUM(Q19+S19+U19) -> 1948000 | AB19: =AA19/M19 -> 0.47990934 | AC19: M.B. | AD19: =_xlfn.CONCAT(A19," ",AC19) -> Newbury M.B. | AE19: =AD19 -> Newbury M.B. | AF19: =INDEX(Lookup!G$2:G$1349, MATCH($AE19, Lookup!$G$2:$G$1349,0)) -> NEWBURY M.B. | AG19: =INDEX(Lookup!F$2:F$1349, MATCH($AE19, Lookup!$G$2:$G$1349,0)) -> e020015 | AH19: =INDEX(Lookup!C$2:C$1349, MATCH($AE19, Lookup!$G$2:$G$1349,0)) -> Berkshire | AI19: =INDEX(Lookup!D$2:D$1349, MATCH($AE19, Lookup!$G$2:$G$1349,0)) -> South East | AJ19: =INDEX(Lookup!E$2:E$1349, MATCH($AE19, Lookup!$G$2:$G$1349,0)) -> Greater South East
A20: New Windsor | B20: ='TABLE Summary'!B20 -> 30360 | C20: ='TABLE Summary'!C20 -> 85 | D20: ='TABLE Summary'!D20 -> 36.3 | E20: ='TABLE Summary'!E20 -> 12.3 | F20: ='TABLE Summary'!F20 -> 24 | G20: ='TABLE Summary'!G20 -> 0 | H20: ='TABLE Summary'!H20 -> 0 | I20: ='TABLE Summary'!I20 -> 43590 | ... L20: ='TABLE Summary'!L20 -> 0 | M20: ='TABLE Summary'!M20*1000 -> 4302500 | N20: ='TABLE Summary'!N20 -> 9978 | O20: ='TABLE Summary'!O20*1000 -> 2347600 | P20: ='TABLE Summary'!P20 -> 1665 | Q20: ='TABLE Summary'!Q20*1000 -> 190400 | R20: ='TABLE Summary'!R20 -> 7562 | S20: ='TABLE Summary'!S20*1000 -> 1881900 | T20: ='TABLE Summary'!T20 -> 493 | U20: ='TABLE Summary'!U20*1000 -> 255500 | V20: ='TABLE Summary'!V20*1000 -> 601400 | W20: ='TABLE Summary'!W20*1000 -> 156900 | X20: ='TABLE Summary'!X20*1000 -> 433100 | Y20: ='TABLE Summary'!Y20*1000 -> 239200 | Z20: ='TABLE Summary'!Z20*1000 -> 524400 | AA20: =SUM(Q20+S20+U20) -> 2327800 | AB20: =AA20/M20 -> 0.54103428 | AC20: M.B. | AD20: =_xlfn.CONCAT(A20," ",AC20) -> New Windsor M.B. | AE20: =AD20 -> New Windsor M.B. | AF20: =INDEX(Lookup!G$2:G$1349, MATCH($AE20, Lookup!$G$2:$G$1349,0)) -> NEW WINDSOR M.B. | AG20: =INDEX(Lookup!F$2:F$1349, MATCH($AE20, Lookup!$G$2:$G$1349,0)) -> e020016 | AH20: =INDEX(Lookup!C$2:C$1349, MATCH($AE20, Lookup!$G$2:$G$1349,0)) -> Berkshire | AI20: =INDEX(Lookup!D$2:D$1349, MATCH($AE20, Lookup!$G$2:$G$1349,0)) -> South East | AJ20: =INDEX(Lookup!E$2:E$1349, MATCH($AE20, Lookup!$G$2:$G$1349,0)) -> Greater South East
A21: Wallingford | B21: ='TABLE Summary'!B21 -> 6180 | C21: ='TABLE Summary'!C21 -> 93 | D21: ='TABLE Summary'!D21 -> 37 | E21: ='TABLE Summary'!E21 -> 13 | F21: ='TABLE Summary'!F21 -> 24 | G21: ='TABLE Summary'!G21 -> 0 | H21: ='TABLE Summary'!H21 -> 0 | I21: ='TABLE Summary'!I21 -> 8461 | ... L21: ='TABLE Summary'!L21 -> 0 | M21: ='TABLE Summary'!M21*1000 -> 942100 | N21: ='TABLE Summary'!N21 -> 1959 | O21: ='TABLE Summary'!O21*1000 -> 404300 | P21: ='TABLE Summary'!P21 -> 425 | Q21: ='TABLE Summary'!Q21*1000 -> 46400 | R21: ='TABLE Summary'!R21 -> 1482 | S21: ='TABLE Summary'!S21*1000 -> 348400 | T21: ='TABLE Summary'!T21 -> 14 | U21: ='TABLE Summary'!U21*1000 -> 6300 | V21: ='TABLE Summary'!V21*1000 -> 161100 | W21: ='TABLE Summary'!W21*1000 -> 15300 | X21: ='TABLE Summary'!X21*1000 -> 105800 | Y21: ='TABLE Summary'!Y21*1000 -> 149500 | Z21: ='TABLE Summary'!Z21*1000 -> 106100 | AA21: =SUM(Q21+S21+U21) -> 401100 | AB21: =AA21/M21 -> 0.42575098 | AC21: M.B. | AD21: =_xlfn.CONCAT(A21," ",AC21) -> Wallingford M.B. | AE21: =AD21 -> Wallingford M.B. | AF21: =INDEX(Lookup!G$2:G$1349, MATCH($AE21, Lookup!$G$2:$G$1349,0)) -> WALLINGFORD M.B. | AG21: =INDEX(Lookup!F$2:F$1349, MATCH($AE21, Lookup!$G$2:$G$1349,0)) -> e020017 | AH21: =INDEX(Lookup!C$2:C$1349, MATCH($AE21, Lookup!$G$2:$G$1349,0)) -> Oxfordshire | AI21: =INDEX(Lookup!D$2:D$1349, MATCH($AE21, Lookup!$G$2:$G$1349,0)) -> South East | AJ21: =INDEX(Lookup!E$2:E$1349, MATCH($AE21, Lookup!$G$2:$G$1349,0)) -> Greater South East
A22: Wokingham | B22: ='TABLE Summary'!B22 -> 22070 | C22: ='TABLE Summary'!C22 -> 89 | D22: ='TABLE Summary'!D22 -> 38.5 | E22: ='TABLE Summary'!E22 -> 14.5 | F22: ='TABLE Summary'!F22 -> 24 | G22: ='TABLE Summary'!G22 -> 0 | H22: ='TABLE Summary'!H22 -> 0 | I22: ='TABLE Summary'!I22 -> 30350 | ... L22: ='TABLE Summary'!L22 -> 0 | M22: ='TABLE Summary'!M22*1000 -> 3206400 | N22: ='TABLE Summary'!N22 -> 6945 | O22: ='TABLE Summary'!O22*1000 -> 1906600 | P22: ='TABLE Summary'!P22 -> 813 | Q22: ='TABLE Summary'!Q22*1000 -> 96300 | R22: ='TABLE Summary'!R22 -> 5335 | S22: ='TABLE Summary'!S22*1000 -> 1432000 | T22: ='TABLE Summary'!T22 -> 797 | U22: ='TABLE Summary'!U22*1000 -> 378300 | V22: ='TABLE Summary'!V22*1000 -> 276100 | W22: ='TABLE Summary'!W22*1000 -> 61600 | X22: ='TABLE Summary'!X22*1000 -> 211400 | Y22: ='TABLE Summary'!Y22*1000 -> 472500 | Z22: ='TABLE Summary'!Z22*1000 -> 278300 | AA22: =SUM(Q22+S22+U22) -> 1906600 | AB22: =AA22/M22 -> 0.59462325 | AC22: M.B. | AD22: =_xlfn.CONCAT(A22," ",AC22) -> Wokingham M.B. | AE22: =AD22 -> Wokingham M.B. | AF22: =INDEX(Lookup!G$2:G$1349, MATCH($AE22, Lookup!$G$2:$G$1349,0)) -> WOKINGHAM M.B. | AG22: =INDEX(Lookup!F$2:F$1349, MATCH($AE22, Lookup!$G$2:$G$1349,0)) -> e020019 | AH22: =INDEX(Lookup!C$2:C$1349, MATCH($AE22, Lookup!$G$2:$G$1349,0)) -> Berkshire | AI22: =INDEX(Lookup!D$2:D$1349, MATCH($AE22, Lookup!$G$2:$G$1349,0)) -> South East | AJ22: =INDEX(Lookup!E$2:E$1349, MATCH($AE22, Lookup!$G$2:$G$1349,0)) -> Greater South East
A23: Wantage | B23: ='TABLE Summary'!B23 -> 8440 | C23: ='TABLE Summary'!C23 -> 81.5 | D23: ='TABLE Summary'!D23 -> 35 | E23: ='TABLE Summary'!E23 -> 11 | F23: ='TABLE Summary'!F23 -> 24 | G23: ='TABLE Summary'!G23 -> 0 | H23: ='TABLE Summary'!H23 -> 0 | I23: ='TABLE Summary'!I23 -> 7566 | ... L23: ='TABLE Summary'!L23 -> 25.3 | M23: ='TABLE Summary'!M23*1000 -> 835600 | N23: ='TABLE Summary'!N23 -> 2420 | O23: ='TABLE Summary'!O23*1000 -> 513700 | P23: ='TABLE Summary'!P23 -> 542 | Q23: ='TABLE Summary'!Q23*1000 -> 59800 | R23: ='TABLE Summary'!R23 -> 1841 | S23: ='TABLE Summary'!S23*1000 -> 431500 | T23: ='TABLE Summary'!T23 -> 35 | U23: ='TABLE Summary'!U23*1000 -> 17300 | V23: ='TABLE Summary'!V23*1000 -> 121500 | W23: ='TABLE Summary'!W23*1000 -> 11800 | X23: ='TABLE Summary'!X23*1000 -> 56000 | Y23: ='TABLE Summary'!Y23*1000 -> 29800 | Z23: ='TABLE Summary'!Z23*1000 -> 102800 | AA23: =SUM(Q23+S23+U23) -> 508600 | AB23: =AA23/M23 -> 0.60866443 | AC23: U.D. | AD23: =_xlfn.CONCAT(A23," ",AC23) -> Wantage U.D. | AE23: =AD23 -> Wantage U.D. | AF23: =INDEX(Lookup!G$2:G$1349, MATCH($AE23, Lookup!$G$2:$G$1349,0)) -> WANTAGE U.D. | AG23: =INDEX(Lookup!F$2:F$1349, MATCH($AE23, Lookup!$G$2:$G$1349,0)) -> e020018 | AH23: =INDEX(Lookup!C$2:C$1349, MATCH($AE23, Lookup!$G$2:$G$1349,0)) -> Oxfordshire | AI23: =INDEX(Lookup!D$2:D$1349, MATCH($AE23, Lookup!$G$2:$G$1349,0)) -> South East | AJ23: =INDEX(Lookup!E$2:E$1349, MATCH($AE23, Lookup!$G$2:$G$1349,0)) -> Greater South East
A24: Rural Districts- | B24: ='TABLE Summary'!B24 -> 0 | C24: ='TABLE Summary'!C24 -> 0 | D24: ='TABLE Summary'!D24 -> 0 | E24: ='TABLE Summary'!E24 -> 0 | F24: ='TABLE Summary'!F24 -> 0 | G24: ='TABLE Summary'!G24 -> 0 | H24: ='TABLE Summary'!H24 -> 0 | I24: ='TABLE Summary'!I24 -> 0 | ... L24: ='TABLE Summary'!L24 -> 0 | M24: ='TABLE Summary'!M24*1000 -> 0 | N24: ='TABLE Summary'!N24 -> 0 | O24: ='TABLE Summary'!O24*1000 -> 0 | P24: ='TABLE Summary'!P24 -> 0 | Q24: ='TABLE Summary'!Q24*1000 -> 0 | R24: ='TABLE Summary'!R24 -> 0 | S24: ='TABLE Summary'!S24*1000 -> 0 | T24: ='TABLE Summary'!T24 -> 0 | U24: ='TABLE Summary'!U24*1000 -> 0 | V24: ='TABLE Summary'!V24*1000 -> 0 | W24: ='TABLE Summary'!W24*1000 -> 0 | X24: ='TABLE Summary'!X24*1000 -> 0 | Y24: ='TABLE Summary'!Y24*1000 -> 0 | Z24: ='TABLE Summary'!Z24*1000 -> 0 | AA24: =SUM(Q24+S24+U24) -> 0 | AB24: =AA24/M24 -> #DIV/0! | AD24: =_xlfn.CONCAT(A24," ",AC24) -> Rural Districts- | AE24: =AD24 -> Rural Districts- | AF24: =INDEX(Lookup!G$2:G$1349, MATCH($AE24, Lookup!$G$2:$G$1349,0)) -> #N/A | AG24: =INDEX(Lookup!F$2:F$1349, MATCH($AE24, Lookup!$G$2:$G$1349,0)) -> #N/A | AH24: =INDEX(Lookup!C$2:C$1349, MATCH($AE24, Lookup!$G$2:$G$1349,0)) -> #N/A | AI24: =INDEX(Lookup!D$2:D$1349, MATCH($AE24, Lookup!$G$2:$G$1349,0)) -> #N/A | AJ24: =INDEX(Lookup!E$2:E$1349, MATCH($AE24, Lookup!$G$2:$G$1349,0)) -> #N/A
A25: Abingdon | B25: ='TABLE Summary'!B25 -> 37170 | C25: ='TABLE Summary'!C25 -> 73 | D25: ='TABLE Summary'!D25 -> 30 | E25: ='TABLE Summary'!E25 -> 6 | F25: ='TABLE Summary'!F25 -> 24 | G25: ='TABLE Summary'!G25 -> 0 | H25: ='TABLE Summary'!H25 -> 30.7 | I25: ='TABLE Summary'!I25 -> 48123 | ... L25: ='TABLE Summary'!L25 -> 3.4 | M25: ='TABLE Summary'!M25*1000 -> 4788900 | N25: ='TABLE Summary'!N25 -> 11646 | O25: ='TABLE Summary'!O25*1000 -> 2764800 | P25: ='TABLE Summary'!P25 -> 1252 | Q25: ='TABLE Summary'!Q25*1000 -> 125500 | R25: ='TABLE Summary'!R25 -> 8959 | S25: ='TABLE Summary'!S25*1000 -> 2163100 | T25: ='TABLE Summary'!T25 -> 896 | U25: ='TABLE Summary'!U25*1000 -> 434800 | V25: ='TABLE Summary'!V25*1000 -> 97600 | W25: ='TABLE Summary'!W25*1000 -> 38400 | X25: ='TABLE Summary'!X25*1000 -> 455200 | Y25: ='TABLE Summary'!Y25*1000 -> 78300 | Z25: ='TABLE Summary'!Z25*1000 -> 1354500 | AA25: =SUM(Q25+S25+U25) -> 2723400 | AB25: =AA25/M25 -> 0.5686901 | AC25: R.D. | AD25: =_xlfn.CONCAT(A25," ",AC25) -> Abingdon R.D. | AE25: =AD25 -> Abingdon R.D. | AF25: =INDEX(Lookup!G$2:G$1349, MATCH($AE25, Lookup!$G$2:$G$1349,0)) -> ABINGDON R.D. | AG25: =INDEX(Lookup!F$2:F$1349, MATCH($AE25, Lookup!$G$2:$G$1349,0)) -> e020020 | AH25: =INDEX(Lookup!C$2:C$1349, MATCH($AE25, Lookup!$G$2:$G$1349,0)) -> Oxfordshire | AI25: =INDEX(Lookup!D$2:D$1349, MATCH($AE25, Lookup!$G$2:$G$1349,0)) -> South East | AJ25: =INDEX(Lookup!E$2:E$1349, MATCH($AE25, Lookup!$G$2:$G$1349,0)) -> Greater South East
A26: Bradfield | B26: ='TABLE Summary'!B26 -> 41710 | C26: ='TABLE Summary'!C26 -> 77 | D26: ='TABLE Summary'!D26 -> 31 | E26: ='TABLE Summary'!E26 -> 7 | F26: ='TABLE Summary'!F26 -> 24 | G26: ='TABLE Summary'!G26 -> 0 | H26: ='TABLE Summary'!H26 -> 31.4 | I26: ='TABLE Summary'!I26 -> 58000 | ... L26: ='TABLE Summary'!L26 -> 7.6 | M26: ='TABLE Summary'!M26*1000 -> 5131300 | N26: ='TABLE Summary'!N26 -> 13231 | O26: ='TABLE Summary'!O26*1000 -> 3298400 | P26: ='TABLE Summary'!P26 -> 1621 | Q26: ='TABLE Summary'!Q26*1000 -> 162400 | R26: ='TABLE Summary'!R26 -> 10653 | S26: ='TABLE Summary'!S26*1000 -> 2607500 | T26: ='TABLE Summary'!T26 -> 951 | U26: ='TABLE Summary'!U26*1000 -> 527000 | V26: ='TABLE Summary'!V26*1000 -> 157500 | W26: ='TABLE Summary'!W26*1000 -> 56000 | X26: ='TABLE Summary'!X26*1000 -> 216400 | Y26: ='TABLE Summary'!Y26*1000 -> 483500 | Z26: ='TABLE Summary'!Z26*1000 -> 919500 | AA26: =SUM(Q26+S26+U26) -> 3296900 | AB26: =AA26/M26 -> 0.64250775 | AC26: R.D. | AD26: =_xlfn.CONCAT(A26," ",AC26) -> Bradfield R.D. | AE26: =AD26 -> Bradfield R.D. | AF26: =INDEX(Lookup!G$2:G$1349, MATCH($AE26, Lookup!$G$2:$G$1349,0)) -> BRADFIELD R.D. | AG26: =INDEX(Lookup!F$2:F$1349, MATCH($AE26, Lookup!$G$2:$G$1349,0)) -> e020021 | AH26: =INDEX(Lookup!C$2:C$1349, MATCH($AE26, Lookup!$G$2:$G$1349,0)) -> Berkshire | AI26: =INDEX(Lookup!D$2:D$1349, MATCH($AE26, Lookup!$G$2:$G$1349,0)) -> South East | AJ26: =INDEX(Lookup!E$2:E$1349, MATCH($AE26, Lookup!$G$2:$G$1349,0)) -> Greater South East
A27: Cookham | B27: ='TABLE Summary'!B27 -> 19290 | C27: ='TABLE Summary'!C27 -> 87 | D27: ='TABLE Summary'!D27 -> 38 | E27: ='TABLE Summary'!E27 -> 14 | F27: ='TABLE Summary'!F27 -> 24 | G27: ='TABLE Summary'!G27 -> 0 | H27: ='TABLE Summary'!H27 -> 38.5 | I27: ='TABLE Summary'!I27 -> 27000 | ... L27: ='TABLE Summary'!L27 -> 0 | M27: ='TABLE Summary'!M27*1000 -> 2834100 | N27: ='TABLE Summary'!N27 -> 7142 | O27: ='TABLE Summary'!O27*1000 -> 1856000 | P27: ='TABLE Summary'!P27 -> 1884 | Q27: ='TABLE Summary'!Q27*1000 -> 170400 | R27: ='TABLE Summary'!R27 -> 3973 | S27: ='TABLE Summary'!S27*1000 -> 999400 | T27: ='TABLE Summary'!T27 -> 1163 | U27: ='TABLE Summary'!U27*1000 -> 674800 | V27: ='TABLE Summary'!V27*1000 -> 75200 | W27: ='TABLE Summary'!W27*1000 -> 132600 | X27: ='TABLE Summary'!X27*1000 -> 236100 | Y27: ='TABLE Summary'!Y27*1000 -> 248400 | Z27: ='TABLE Summary'!Z27*1000 -> 285800 | AA27: =SUM(Q27+S27+U27) -> 1844600 | AB27: =AA27/M27 -> 0.65085918 | AC27: R.D. | AD27: =_xlfn.CONCAT(A27," ",AC27) -> Cookham R.D. | AE27: =AD27 -> Cookham R.D. | AF27: =INDEX(Lookup!G$2:G$1349, MATCH($AE27, Lookup!$G$2:$G$1349,0)) -> COOKHAM R.D. | AG27: =INDEX(Lookup!F$2:F$1349, MATCH($AE27, Lookup!$G$2:$G$1349,0)) -> e020022 | AH27: =INDEX(Lookup!C$2:C$1349, MATCH($AE27, Lookup!$G$2:$G$1349,0)) -> Berkshire | AI27: =INDEX(Lookup!D$2:D$1349, MATCH($AE27, Lookup!$G$2:$G$1349,0)) -> South East | AJ27: =INDEX(Lookup!E$2:E$1349, MATCH($AE27, Lookup!$G$2:$G$1349,0)) -> Greater South East
A28: Easthampstead | B28: ='TABLE Summary'!B28 -> 67690 | C28: ='TABLE Summary'!C28 -> 89 | D28: ='TABLE Summary'!D28 -> 38.5 | E28: ='TABLE Summary'!E28 -> 14.5 | F28: ='TABLE Summary'!F28 -> 24 | G28: ='TABLE Summary'!G28 -> 0 | H28: ='TABLE Summary'!H28 -> 40 | I28: ='TABLE Summary'!I28 -> 97487 | ... L28: ='TABLE Summary'!L28 -> 0 | M28: ='TABLE Summary'!M28*1000 -> 9741500 | N28: ='TABLE Summary'!N28 -> 21251 | O28: ='TABLE Summary'!O28*1000 -> 5155400 | P28: ='TABLE Summary'!P28 -> 2483 | Q28: ='TABLE Summary'!Q28*1000 -> 273900 | R28: ='TABLE Summary'!R28 -> 17050 | S28: ='TABLE Summary'!S28*1000 -> 4265400 | T28: ='TABLE Summary'!T28 -> 1030 | U28: ='TABLE Summary'!U28*1000 -> 555600 | V28: ='TABLE Summary'!V28*1000 -> 638500 | W28: ='TABLE Summary'!W28*1000 -> 663500 | X28: ='TABLE Summary'!X28*1000 -> 732500 | Y28: ='TABLE Summary'!Y28*1000 -> 1314400 | Z28: ='TABLE Summary'!Z28*1000 -> 1237100 | AA28: =SUM(Q28+S28+U28) -> 5094900 | AB28: =AA28/M28 -> 0.5230098 | AC28: R.D. | AD28: =_xlfn.CONCAT(A28," ",AC28) -> Easthampstead R.D. | AE28: =AD28 -> Easthampstead R.D. | AF28: =INDEX(Lookup!G$2:G$1349, MATCH($AE28, Lookup!$G$2:$G$1349,0)) -> EASTHAMPSTEAD R.D. | AG28: =INDEX(Lookup!F$2:F$1349, MATCH($AE28, Lookup!$G$2:$G$1349,0)) -> e020023 | AH28: =INDEX(Lookup!C$2:C$1349, MATCH($AE28, Lookup!$G$2:$G$1349,0)) -> Berkshire | AI28: =INDEX(Lookup!D$2:D$1349, MATCH($AE28, Lookup!$G$2:$G$1349,0)) -> South East | AJ28: =INDEX(Lookup!E$2:E$1349, MATCH($AE28, Lookup!$G$2:$G$1349,0)) -> Greater South East
A29: Faringdon | B29: ='TABLE Summary'!B29 -> 14830 | C29: ='TABLE Summary'!C29 -> 80 | D29: ='TABLE Summary'!D29 -> 31 | E29: ='TABLE Summary'!E29 -> 7 | F29: ='TABLE Summary'!F29 -> 24 | G29: ='TABLE Summary'!G29 -> 0 | H29: ='TABLE Summary'!H29 -> 31.4 | I29: ='TABLE Summary'!I29 -> 14305 | ... L29: ='TABLE Summary'!L29 -> 36.3 | M29: ='TABLE Summary'!M29*1000 -> 1266100 | N29: ='TABLE Summary'!N29 -> 5036 | O29: ='TABLE Summary'!O29*1000 -> 850900 | P29: ='TABLE Summary'!P29 -> 1494 | Q29: ='TABLE Summary'!Q29*1000 -> 158700 | R29: ='TABLE Summary'!R29 -> 2995 | S29: ='TABLE Summary'!S29*1000 -> 608900 | T29: ='TABLE Summary'!T29 -> 94 | U29: ='TABLE Summary'!U29*1000 -> 50500 | V29: ='TABLE Summary'!V29*1000 -> 66700 | W29: ='TABLE Summary'!W29*1000 -> 8000 | X29: ='TABLE Summary'!X29*1000 -> 82200 | Y29: ='TABLE Summary'!Y29*1000 -> 22600 | Z29: ='TABLE Summary'!Z29*1000 -> 235700 | AA29: =SUM(Q29+S29+U29) -> 818100 | AB29: =AA29/M29 -> 0.64615749 | AC29: R.D. | AD29: =_xlfn.CONCAT(A29," ",AC29) -> Faringdon R.D. | AE29: =AD29 -> Faringdon R.D. | AF29: =INDEX(Lookup!G$2:G$1349, MATCH($AE29, Lookup!$G$2:$G$1349,0)) -> FARINGDON R.D. | AG29: =INDEX(Lookup!F$2:F$1349, MATCH($AE29, Lookup!$G$2:$G$1349,0)) -> e020025 | AH29: =INDEX(Lookup!C$2:C$1349, MATCH($AE29, Lookup!$G$2:$G$1349,0)) -> Oxfordshire | AI29: =INDEX(Lookup!D$2:D$1349, MATCH($AE29, Lookup!$G$2:$G$1349,0)) -> South East | AJ29: =INDEX(Lookup!E$2:E$1349, MATCH($AE29, Lookup!$G$2:$G$1349,0)) -> Greater South East
A30: Hungerford | B30: ='TABLE Summary'!B30 -> 11680 | C30: ='TABLE Summary'!C30 -> 76.5 | D30: ='TABLE Summary'!D30 -> 29.8 | E30: ='TABLE Summary'!E30 -> 5.8 | F30: ='TABLE Summary'!F30 -> 24 | G30: ='TABLE Summary'!G30 -> 0 | H30: ='TABLE Summary'!H30 -> 31 | I30: ='TABLE Summary'!I30 -> 10991 | ... L30: ='TABLE Summary'!L30 -> 29.5 | M30: ='TABLE Summary'!M30*1000 -> 1094500 | N30: ='TABLE Summary'!N30 -> 3790 | O30: ='TABLE Summary'!O30*1000 -> 704700 | P30: ='TABLE Summary'!P30 -> 1264 | Q30: ='TABLE Summary'!Q30*1000 -> 136000 | R30: ='TABLE Summary'!R30 -> 2418 | S30: ='TABLE Summary'!S30*1000 -> 497100 | T30: ='TABLE Summary'!T30 -> 107 | U30: ='TABLE Summary'!U30*1000 -> 71500 | V30: ='TABLE Summary'!V30*1000 -> 67200 | W30: ='TABLE Summary'!W30*1000 -> 13300 | X30: ='TABLE Summary'!X30*1000 -> 93800 | Y30: ='TABLE Summary'!Y30*1000 -> 78400 | Z30: ='TABLE Summary'!Z30*1000 -> 137200 | AA30: =SUM(Q30+S30+U30) -> 704600 | AB30: =AA30/M30 -> 0.64376428 | AC30: R.D. | AD30: =_xlfn.CONCAT(A30," ",AC30) -> Hungerford R.D. | AE30: =AD30 -> Hungerford R.D. | AF30: =INDEX(Lookup!G$2:G$1349, MATCH($AE30, Lookup!$G$2:$G$1349,0)) -> HUNGERFORD R.D. | AG30: =INDEX(Lookup!F$2:F$1349, MATCH($AE30, Lookup!$G$2:$G$1349,0)) -> e020026 | AH30: =INDEX(Lookup!C$2:C$1349, MATCH($AE30, Lookup!$G$2:$G$1349,0)) -> Berkshire | AI30: =INDEX(Lookup!D$2:D$1349, MATCH($AE30, Lookup!$G$2:$G$1349,0)) -> South East | AJ30: =INDEX(Lookup!E$2:E$1349, MATCH($AE30, Lookup!$G$2:$G$1349,0)) -> Greater South East
A31: Newbury | B31: ='TABLE Summary'!B31 -> 26260 | C31: ='TABLE Summary'!C31 -> 72.5 | D31: ='TABLE Summary'!D31 -> 32.2 | E31: ='TABLE Summary'!E31 -> 8.2 | F31: ='TABLE Summary'!F31 -> 24 | G31: ='TABLE Summary'!G31 -> 0 | H31: ='TABLE Summary'!H31 -> 32.6 | I31: ='TABLE Summary'!I31 -> 34500 | ... L31: ='TABLE Summary'!L31 -> 0 | M31: ='TABLE Summary'!M31*1000 -> 3510000 | N31: ='TABLE Summary'!N31 -> 8325 | O31: ='TABLE Summary'!O31*1000 -> 1968400 | P31: ='TABLE Summary'!P31 -> 1095 | Q31: ='TABLE Summary'!Q31*1000 -> 116700 | R31: ='TABLE Summary'!R31 -> 6846 | S31: ='TABLE Summary'!S31*1000 -> 1635000 | T31: ='TABLE Summary'!T31 -> 380 | U31: ='TABLE Summary'!U31*1000 -> 207800 | V31: ='TABLE Summary'!V31*1000 -> 94800 | W31: ='TABLE Summary'!W31*1000 -> 5600 | X31: ='TABLE Summary'!X31*1000 -> 194600 | Y31: ='TABLE Summary'!Y31*1000 -> 807000 | Z31: ='TABLE Summary'!Z31*1000 -> 439500 | AA31: =SUM(Q31+S31+U31) -> 1959500 | AB31: =AA31/M31 -> 0.55826211 | AC31: R.D. | AD31: =_xlfn.CONCAT(A31," ",AC31) -> Newbury R.D. | AE31: =AD31 -> Newbury R.D. | AF31: =INDEX(Lookup!G$2:G$1349, MATCH($AE31, Lookup!$G$2:$G$1349,0)) -> NEWBURY R.D. | AG31: =INDEX(Lookup!F$2:F$1349, MATCH($AE31, Lookup!$G$2:$G$1349,0)) -> e020027 | AH31: =INDEX(Lookup!C$2:C$1349, MATCH($AE31, Lookup!$G$2:$G$1349,0)) -> Berkshire | AI31: =INDEX(Lookup!D$2:D$1349, MATCH($AE31, Lookup!$G$2:$G$1349,0)) -> South East | AJ31: =INDEX(Lookup!E$2:E$1349, MATCH($AE31, Lookup!$G$2:$G$1349,0)) -> Greater South East
A32: Wallingford | B32: ='TABLE Summary'!B32 -> 23600 | C32: ='TABLE Summary'!C32 -> 69 | D32: ='TABLE Summary'!D32 -> 29.3 | E32: ='TABLE Summary'!E32 -> 5.3 | F32: ='TABLE Summary'!F32 -> 24 | G32: ='TABLE Summary'!G32 -> 0 | H32: ='TABLE Summary'!H32 -> 30.4 | I32: ='TABLE Summary'!I32 -> 21975 | ... L32: ='TABLE Summary'!L32 -> 32.8 | M32: ='TABLE Summary'!M32*1000 -> 2155600 | N32: ='TABLE Summary'!N32 -> 7573 | O32: ='TABLE Summary'!O32*1000 -> 1520800 | P32: ='TABLE Summary'!P32 -> 896 | Q32: ='TABLE Summary'!Q32*1000 -> 93100 | R32: ='TABLE Summary'!R32 -> 6308 | S32: ='TABLE Summary'!S32*1000 -> 1349300 | T32: ='TABLE Summary'!T32 -> 119 | U32: ='TABLE Summary'!U32*1000 -> 61600 | V32: ='TABLE Summary'!V32*1000 -> 165200 | W32: ='TABLE Summary'!W32*1000 -> 19100 | X32: ='TABLE Summary'!X32*1000 -> 119000 | Y32: ='TABLE Summary'!Y32*1000 -> 91200 | Z32: ='TABLE Summary'!Z32*1000 -> 240400 | AA32: =SUM(Q32+S32+U32) -> 1504000 | AB32: =AA32/M32 -> 0.69771757 | AC32: R.D. | AD32: =_xlfn.CONCAT(A32," ",AC32) -> Wallingford R.D. | AE32: =AD32 -> Wallingford R.D. | AF32: =INDEX(Lookup!G$2:G$1349, MATCH($AE32, Lookup!$G$2:$G$1349,0)) -> WALLINGFORD R.D. | AG32: =INDEX(Lookup!F$2:F$1349, MATCH($AE32, Lookup!$G$2:$G$1349,0)) -> e020028 | AH32: =INDEX(Lookup!C$2:C$1349, MATCH($AE32, Lookup!$G$2:$G$1349,0)) -> Oxfordshire | AI32: =INDEX(Lookup!D$2:D$1349, MATCH($AE32, Lookup!$G$2:$G$1349,0)) -> South East | AJ32: =INDEX(Lookup!E$2:E$1349, MATCH($AE32, Lookup!$G$2:$G$1349,0)) -> Greater South East
A33: Wantage | B33: ='TABLE Summary'!B33 -> 20850 | C33: ='TABLE Summary'!C33 -> 76 | D33: ='TABLE Summary'!D33 -> 32 | E33: ='TABLE Summary'!E33 -> 8 | F33: ='TABLE Summary'!F33 -> 24 | G33: ='TABLE Summary'!G33 -> 0 | H33: ='TABLE Summary'!H33 -> 32.9 | I33: ='TABLE Summary'!I33 -> 26482 | ... L33: ='TABLE Summary'!L33 -> 17.9 | M33: ='TABLE Summary'!M33*1000 -> 2268700 | N33: ='TABLE Summary'!N33 -> 6811 | O33: ='TABLE Summary'!O33*1000 -> 1434000 | P33: ='TABLE Summary'!P33 -> 1468 | Q33: ='TABLE Summary'!Q33*1000 -> 152600 | R33: ='TABLE Summary'!R33 -> 5160 | S33: ='TABLE Summary'!S33*1000 -> 1171300 | T33: ='TABLE Summary'!T33 -> 169 | U33: ='TABLE Summary'!U33*1000 -> 92900 | V33: ='TABLE Summary'!V33*1000 -> 51900 | W33: ='TABLE Summary'!W33*1000 -> 3000 | X33: ='TABLE Summary'!X33*1000 -> 93200 | Y33: ='TABLE Summary'!Y33*1000 -> 46200 | Z33: ='TABLE Summary'!Z33*1000 -> 640400 | AA33: =SUM(Q33+S33+U33) -> 1416800 | AB33: =AA33/M33 -> 0.62449861 | AC33: R.D. | AD33: =_xlfn.CONCAT(A33," ",AC33) -> Wantage R.D. | AE33: =AD33 -> Wantage R.D. | AF33: =INDEX(Lookup!G$2:G$1349, MATCH($AE33, Lookup!$G$2:$G$1349,0)) -> WANTAGE R.D. | AG33: =INDEX(Lookup!F$2:F$1349, MATCH($AE33, Lookup!$G$2:$G$1349,0)) -> e020029 | AH33: =INDEX(Lookup!C$2:C$1349, MATCH($AE33, Lookup!$G$2:$G$1349,0)) -> Oxfordshire | AI33: =INDEX(Lookup!D$2:D$1349, MATCH($AE33, Lookup!$G$2:$G$1349,0)) -> South East | AJ33: =INDEX(Lookup!E$2:E$1349, MATCH($AE33, Lookup!$G$2:$G$1349,0)) -> Greater South East
A34: Windsor | B34: ='TABLE Summary'!B34 -> 18100 | C34: ='TABLE Summary'!C34 -> 77 | D34: ='TABLE Summary'!D34 -> 32.5 | E34: ='TABLE Summary'!E34 -> 8.5 | F34: ='TABLE Summary'!F34 -> 24 | G34: ='TABLE Summary'!G34 -> 0 | H34: ='TABLE Summary'!H34 -> 33.2 | I34: ='TABLE Summary'!I34 -> 25607 | ... L34: ='TABLE Summary'!L34 -> 0 | M34: ='TABLE Summary'!M34*1000 -> 2657300 | N34: ='TABLE Summary'!N34 -> 5598 | O34: ='TABLE Summary'!O34*1000 -> 1659100 | P34: ='TABLE Summary'!P34 -> 719 | Q34: ='TABLE Summary'!Q34*1000 -> 82000 | R34: ='TABLE Summary'!R34 -> 3534 | S34: ='TABLE Summary'!S34*1000 -> 878100 | T34: ='TABLE Summary'!T34 -> 1141 | U34: ='TABLE Summary'!U34*1000 -> 682600 | V34: ='TABLE Summary'!V34*1000 -> 148600 | W34: ='TABLE Summary'!W34*1000 -> 156900 | X34: ='TABLE Summary'!X34*1000 -> 136900 | Y34: ='TABLE Summary'!Y34*1000 -> 89200 | Z34: ='TABLE Summary'!Z34*1000 -> 466600 | AA34: =SUM(Q34+S34+U34) -> 1642700 | AB34: =AA34/M34 -> 0.61818387 | AC34: R.D. | AD34: =_xlfn.CONCAT(A34," ",AC34) -> Windsor R.D. | AE34: =AD34 -> Windsor R.D. | AF34: =INDEX(Lookup!G$2:G$1349, MATCH($AE34, Lookup!$G$2:$G$1349,0)) -> WINDSOR R.D. | AG34: =INDEX(Lookup!F$2:F$1349, MATCH($AE34, Lookup!$G$2:$G$1349,0)) -> e020031 | AH34: =INDEX(Lookup!C$2:C$1349, MATCH($AE34, Lookup!$G$2:$G$1349,0)) -> Berkshire | AI34: =INDEX(Lookup!D$2:D$1349, MATCH($AE34, Lookup!$G$2:$G$1349,0)) -> South East | AJ34: =INDEX(Lookup!E$2:E$1349, MATCH($AE34, Lookup!$G$2:$G$1349,0)) -> Greater South East
A35: Wokingham | B35: ='TABLE Summary'!B35 -> 84050 | C35: ='TABLE Summary'!C35 -> 75 | D35: ='TABLE Summary'!D35 -> 31.4 | E35: ='TABLE Summary'!E35 -> 7.4 | F35: ='TABLE Summary'!F35 -> 24 | G35: ='TABLE Summary'!G35 -> 0 | H35: ='TABLE Summary'!H35 -> 32.3 | I35: ='TABLE Summary'!I35 -> 95000 | ... L35: ='TABLE Summary'!L35 -> 12.9 | M35: ='TABLE Summary'!M35*1000 -> 9949500 | N35: ='TABLE Summary'!N35 -> 25818 | O35: ='TABLE Summary'!O35*1000 -> 7046000 | P35: ='TABLE Summary'!P35 -> 1996 | Q35: ='TABLE Summary'!Q35*1000 -> 220400 | R35: ='TABLE Summary'!R35 -> 20937 | S35: ='TABLE Summary'!S35*1000 -> 5524800 | T35: ='TABLE Summary'!T35 -> 2341 | U35: ='TABLE Summary'!U35*1000 -> 1248400 | V35: ='TABLE Summary'!V35*1000 -> 299500 | W35: ='TABLE Summary'!W35*1000 -> 40300 | X35: ='TABLE Summary'!X35*1000 -> 421200 | Y35: ='TABLE Summary'!Y35*1000 -> 707000 | Z35: ='TABLE Summary'!Z35*1000 -> 1435500 | AA35: =SUM(Q35+S35+U35) -> 6993600 | AB35: =AA35/M35 -> 0.70290969 | AC35: R.D. | AD35: =_xlfn.CONCAT(A35," ",AC35) -> Wokingham R.D. | AE35: =AD35 -> Wokingham R.D. | AF35: =INDEX(Lookup!G$2:G$1349, MATCH($AE35, Lookup!$G$2:$G$1349,0)) -> WOKINGHAM R.D. | AG35: =INDEX(Lookup!F$2:F$1349, MATCH($AE35, Lookup!$G$2:$G$1349,0)) -> e020032 | AH35: =INDEX(Lookup!C$2:C$1349, MATCH($AE35, Lookup!$G$2:$G$1349,0)) -> Berkshire | AI35: =INDEX(Lookup!D$2:D$1349, MATCH($AE35, Lookup!$G$2:$G$1349,0)) -> South East | AJ35: =INDEX(Lookup!E$2:E$1349, MATCH($AE35, Lookup!$G$2:$G$1349,0)) -> Greater South East
A36: BUCKINGHAMSHIRE | B36: ='TABLE Summary'!B36 -> 0 | C36: ='TABLE Summary'!C36 -> 0 | D36: ='TABLE Summary'!D36 -> 0 | E36: ='TABLE Summary'!E36 -> 0 | F36: ='TABLE Summary'!F36 -> 0 | G36: ='TABLE Summary'!G36 -> 0 | H36: ='TABLE Summary'!H36 -> 0 | I36: ='TABLE Summary'!I36 -> 0 | ... L36: ='TABLE Summary'!L36 -> 0 | M36: ='TABLE Summary'!M36*1000 -> 0 | N36: ='TABLE Summary'!N36 -> 0 | O36: ='TABLE Summary'!O36*1000 -> 0 | P36: ='TABLE Summary'!P36 -> 0 | Q36: ='TABLE Summary'!Q36*1000 -> 0 | R36: ='TABLE Summary'!R36 -> 0 | S36: ='TABLE Summary'!S36*1000 -> 0 | T36: ='TABLE Summary'!T36 -> 0 | U36: ='TABLE Summary'!U36*1000 -> 0 | V36: ='TABLE Summary'!V36*1000 -> 0 | W36: ='TABLE Summary'!W36*1000 -> 0 | X36: ='TABLE Summary'!X36*1000 -> 0 | Y36: ='TABLE Summary'!Y36*1000 -> 0 | Z36: ='TABLE Summary'!Z36*1000 -> 0 | AA36: =SUM(Q36+S36+U36) -> 0 | AB36: =AA36/M36 -> #DIV/0! | AE36: =AD36 -> 0 | AF36: =INDEX(Lookup!G$2:G$1349, MATCH($AE36, Lookup!$G$2:$G$1349,0)) -> #N/A | AG36: =INDEX(Lookup!F$2:F$1349, MATCH($AE36, Lookup!$G$2:$G$1349,0)) -> #N/A | AH36: =INDEX(Lookup!C$2:C$1349, MATCH($AE36, Lookup!$G$2:$G$1349,0)) -> #N/A | AI36: =INDEX(Lookup!D$2:D$1349, MATCH($AE36, Lookup!$G$2:$G$1349,0)) -> #N/A | AJ36: =INDEX(Lookup!E$2:E$1349, MATCH($AE36, Lookup!$G$2:$G$1349,0)) -> #N/A
A37: General County Precept | B37: ='TABLE Summary'!B37 -> 0 | C37: ='TABLE Summary'!C37 -> 64.8 | D37: ='TABLE Summary'!D37 -> 27.5 | E37: ='TABLE Summary'!E37 -> 0 | F37: ='TABLE Summary'!F37 -> 0 | G37: ='TABLE Summary'!G37 -> 0 | H37: ='TABLE Summary'!H37 -> 0 | I37: ='TABLE Summary'!I37 -> 967758 | ... L37: ='TABLE Summary'!L37 -> 0 | M37: ='TABLE Summary'!M37*1000 -> 0 | N37: ='TABLE Summary'!N37 -> 0 | O37: ='TABLE Summary'!O37*1000 -> 0 | P37: ='TABLE Summary'!P37 -> 0 | Q37: ='TABLE Summary'!Q37*1000 -> 0 | R37: ='TABLE Summary'!R37 -> 0 | S37: ='TABLE Summary'!S37*1000 -> 0 | T37: ='TABLE Summary'!T37 -> 0 | U37: ='TABLE Summary'!U37*1000 -> 0 | V37: ='TABLE Summary'!V37*1000 -> 0 | W37: ='TABLE Summary'!W37*1000 -> 0 | X37: ='TABLE Summary'!X37*1000 -> 0 | Y37: ='TABLE Summary'!Y37*1000 -> 0 | Z37: ='TABLE Summary'!Z37*1000 -> 0 | AA37: =SUM(Q37+S37+U37) -> 0 | AB37: =AA37/M37 -> #DIV/0! | AE37: =AD37 -> 0 | AF37: =INDEX(Lookup!G$2:G$1349, MATCH($AE37, Lookup!$G$2:$G$1349,0)) -> #N/A | AG37: =INDEX(Lookup!F$2:F$1349, MATCH($AE37, Lookup!$G$2:$G$1349,0)) -> #N/A | AH37: =INDEX(Lookup!C$2:C$1349, MATCH($AE37, Lookup!$G$2:$G$1349,0)) -> #N/A | AI37: =INDEX(Lookup!D$2:D$1349, MATCH($AE37, Lookup!$G$2:$G$1349,0)) -> #N/A | AJ37: =INDEX(Lookup!E$2:E$1349, MATCH($AE37, Lookup!$G$2:$G$1349,0)) -> #N/A
A38: County totals | B38: ='TABLE Summary'!B38 -> 598290 | C38: ='TABLE Summary'!C38 -> 0 | D38: ='TABLE Summary'!D38 -> 0 | E38: ='TABLE Summary'!E38 -> 0 | F38: ='TABLE Summary'!F38 -> 0 | G38: ='TABLE Summary'!G38 -> 0 | H38: ='TABLE Summary'!H38 -> 39.2 | I38: ='TABLE Summary'!I38 -> 968356 | ... L38: ='TABLE Summary'!L38 -> 0 | M38: ='TABLE Summary'!M38*1000 -> 97644400 | N38: ='TABLE Summary'!N38 -> 194688 | O38: ='TABLE Summary'!O38*1000 -> 51288400 | P38: ='TABLE Summary'!P38 -> 25120 | Q38: ='TABLE Summary'!Q38*1000 -> 2897900 | R38: ='TABLE Summary'!R38 -> 145628 | S38: ='TABLE Summary'!S38*1000 -> 36064300 | T38: ='TABLE Summary'!T38 -> 22037 | U38: ='TABLE Summary'!U38*1000 -> 12085000 | V38: ='TABLE Summary'!V38*1000 -> 7641000 | W38: ='TABLE Summary'!W38*1000 -> 2569500 | X38: ='TABLE Summary'!X38*1000 -> 8780500 | Y38: ='TABLE Summary'!Y38*1000 -> 17139000 | Z38: ='TABLE Summary'!Z38*1000 -> 10285600 | AA38: =SUM(Q38+S38+U38) -> 51047200 | AB38: =AA38/M38 -> 0.52278677 | AE38: =AD38 -> 0 | AF38: =INDEX(Lookup!G$2:G$1349, MATCH($AE38, Lookup!$G$2:$G$1349,0)) -> #N/A | AG38: =INDEX(Lookup!F$2:F$1349, MATCH($AE38, Lookup!$G$2:$G$1349,0)) -> #N/A | AH38: =INDEX(Lookup!C$2:C$1349, MATCH($AE38, Lookup!$G$2:$G$1349,0)) -> #N/A | AI38: =INDEX(Lookup!D$2:D$1349, MATCH($AE38, Lookup!$G$2:$G$1349,0)) -> #N/A | AJ38: =INDEX(Lookup!E$2:E$1349, MATCH($AE38, Lookup!$G$2:$G$1349,0)) -> #N/A
A39: Aylesbury | B39: ='TABLE Summary'!B39 -> 40860 | C39: ='TABLE Summary'!C39 -> 90 | D39: ='TABLE Summary'!D39 -> 37.8 | E39: ='TABLE Summary'!E39 -> 8.9 | F39: ='TABLE Summary'!F39 -> 28.9 | G39: ='TABLE Summary'!G39 -> 0 | H39: ='TABLE Summary'!H39 -> 0 | I39: ='TABLE Summary'!I39 -> 69308 | ... L39: ='TABLE Summary'!L39 -> 0 | M39: ='TABLE Summary'!M39*1000 -> 6845800 | N39: ='TABLE Summary'!N39 -> 12866 | O39: ='TABLE Summary'!O39*1000 -> 2636900 | P39: ='TABLE Summary'!P39 -> 2191 | Q39: ='TABLE Summary'!Q39*1000 -> 266800 | R39: ='TABLE Summary'!R39 -> 10152 | S39: ='TABLE Summary'!S39*1000 -> 2208800 | T39: ='TABLE Summary'!T39 -> 326 | U39: ='TABLE Summary'!U39*1000 -> 149400 | V39: ='TABLE Summary'!V39*1000 -> 989500 | W39: ='TABLE Summary'!W39*1000 -> 242000 | X39: ='TABLE Summary'!X39*1000 -> 687700 | Y39: ='TABLE Summary'!Y39*1000 -> 1361500 | Z39: ='TABLE Summary'!Z39*1000 -> 928100 | AA39: =SUM(Q39+S39+U39) -> 2625000 | AB39: =AA39/M39 -> 0.38344678 | AC39: M.B. | AD39: =_xlfn.CONCAT(A39," ",AC39) -> Aylesbury M.B. | AE39: =AD39 -> Aylesbury M.B. | AF39: =INDEX(Lookup!G$2:G$1349, MATCH($AE39, Lookup!$G$2:$G$1349,0)) -> AYLESBURY M.B. | AG39: =INDEX(Lookup!F$2:F$1349, MATCH($AE39, Lookup!$G$2:$G$1349,0)) -> e030033 | AH39: =INDEX(Lookup!C$2:C$1349, MATCH($AE39, Lookup!$G$2:$G$1349,0)) -> Buckinghamshire | AI39: =INDEX(Lookup!D$2:D$1349, MATCH($AE39, Lookup!$G$2:$G$1349,0)) -> South East | AJ39: =INDEX(Lookup!E$2:E$1349, MATCH($AE39, Lookup!$G$2:$G$1349,0)) -> Greater South East
A40: Buckingham | B40: ='TABLE Summary'!B40 -> 5200 | C40: ='TABLE Summary'!C40 -> 975.5 | D40: ='TABLE Summary'!D40 -> 40.2 | E40: ='TABLE Summary'!E40 -> 11.1 | F40: ='TABLE Summary'!F40 -> 28.9 | G40: ='TABLE Summary'!G40 -> 0.2 | H40: ='TABLE Summary'!H40 -> 0 | I40: ='TABLE Summary'!I40 -> 7850 | ... L40: ='TABLE Summary'!L40 -> 0 | M40: ='TABLE Summary'!M40*1000 -> 776600 | N40: ='TABLE Summary'!N40 -> 1871 | O40: ='TABLE Summary'!O40*1000 -> 341400 | P40: ='TABLE Summary'!P40 -> 687 | Q40: ='TABLE Summary'!Q40*1000 -> 70000 | R40: ='TABLE Summary'!R40 -> 1145 | S40: ='TABLE Summary'!S40*1000 -> 251000 | T40: ='TABLE Summary'!T40 -> 38 | U40: ='TABLE Summary'!U40*1000 -> 20300 | V40: ='TABLE Summary'!V40*1000 -> 96100 | W40: ='TABLE Summary'!W40*1000 -> 12300 | X40: ='TABLE Summary'!X40*1000 -> 77100 | Y40: ='TABLE Summary'!Y40*1000 -> 172000 | Z40: ='TABLE Summary'!Z40*1000 -> 77700 | AA40: =SUM(Q40+S40+U40) -> 341300 | AB40: =AA40/M40 -> 0.43947978 | AC40: M.B. | AD40: =_xlfn.CONCAT(A40," ",AC40) -> Buckingham M.B. | AE40: =AD40 -> Buckingham M.B. | AF40: =INDEX(Lookup!G$2:G$1349, MATCH($AE40, Lookup!$G$2:$G$1349,0)) -> BUCKINGHAM M.B. | AG40: =INDEX(Lookup!F$2:F$1349, MATCH($AE40, Lookup!$G$2:$G$1349,0)) -> e030036 | AH40: =INDEX(Lookup!C$2:C$1349, MATCH($AE40, Lookup!$G$2:$G$1349,0)) -> Buckinghamshire | AI40: =INDEX(Lookup!D$2:D$1349, MATCH($AE40, Lookup!$G$2:$G$1349,0)) -> South East | AJ40: =INDEX(Lookup!E$2:E$1349, MATCH($AE40, Lookup!$G$2:$G$1349,0)) -> Greater South East
...

Sheet TABLE Summary
C1: Rate Poundage 72-73 | D1: Rate Poundage 73-74 | E1: Rate Poundage 73-74 Local purpose | F1: Rate Poundage 73-74 County Purposes | G1: Rate Poundage 73-74 Other Purpose | H1: Average rate Poundage 1973-74 | I1: Peeny rate Product 1971-73 | J1: Change in penney rate product from 1972-73 | K1: Rate Call 1973-74 | L1: Resources element of rate support Grant | M1: Total rateable value in April 1973 | N1: N Total Domestic(Including Crown Domestic) | O1: POUNDS Total Domestic(Including Crown Domestic) | P1: N £1-£150 | Q1: POUNDS £1-£150 | R1: N£151-£400 | S1: POUNDS £151-£400 | T1: N Over £400 | U1: POUNDS Over £400 | V1: Shops | W1: Offices | X1: Other Commercial | Y1: Industrial | Z1: All other including non-domestic Crown Property | AA1: Domestic heriditaments total | AB1: Domestic heriditaments ratio | AD1: CONCAT | AE1: CONCAT EDITED | AF1: equiv_1971_nm | AG1: equiv_1971_cd | AH1: cty_1981 | AI1: rgn | AJ1: srgn
A2: County totals | B2: 3110000 | H2: 46.4 | I2: 411943 | J2: 158.6 | K2: 19109795 | M2: 41815.3 | N2: 100574 | O2: 21763.9 | P2: 20041 | Q2: 2308.6 | R2: 78229 | S2: 18300.2 | T2: 2176 | U2: 1055 | V2: 3091.4 | W2: 1004.3 | X2: 3426.8 | Y2: 6536.9 | Z2: 5992 | AA2: =SUM(Q2+S2+U2) -> 21663.8 | AB2: =AA2/M2 -> 0.51808309
A3: Bedford | B3: 73960 | C3: 101.5 | D3: 50 | E3: 17 | F3: 33 | G3: 0 | I3: 103250 | J3: 127.7 | K3: 5162500 | L3: 0 | M3: 10503.2 | N3: 23506 | O3: 4835.7 | P3: 6125 | Q3: 751 | R3: 16955 | S3: 3892 | T3: 406 | U3: 185.8 | V3: 1593.9 | W3: 459.9 | X3: 805.5 | Y3: 1219 | Z3: 1589.2 | AA3: =SUM(Q3+S3+U3) -> 4828.8 | AB3: =AA3/M3 -> 0.4597456 | AC3: M.B. | AD3: =_xlfn.CONCAT(A3," ",AC3) -> Bedford M.B. | AE3: =AD3 -> Bedford M.B. | AF3: =INDEX(Lookup!G$2:G$1349, MATCH($AE3, Lookup!$G$2:$G$1349,0)) -> BEDFORD M.B. | AG3: =INDEX(Lookup!F$2:F$1349, MATCH($AE3, Lookup!$G$2:$G$1349,0)) -> e010002 | AH3: =INDEX(Lookup!C$2:C$1349, MATCH($AE3, Lookup!$G$2:$G$1349,0)) -> Bedfordshire | AI3: =INDEX(Lookup!D$2:D$1349, MATCH($AE3, Lookup!$G$2:$G$1349,0)) -> East of England | AJ3: =INDEX(Lookup!E$2:E$1349, MATCH($AE3, Lookup!$G$2:$G$1349,0)) -> Greater South East
