Workbook

Sheet Table A
A1: OG NAME | B1: EDITED NAME | C1: Total amount in the pound of the local rates 1955-56 | E1: Total amount in the pound of the local rates1956-57 | G1: Total amount in the pound of all the local rates levied during 1956 57 in the parish (or part of the parish) having the Highest rate in the pound | I1: Total amount in the pound of all the local rates levied during 1956 57 in the parish (or part of the parish) having the Lowest rate in the pound | K1: Estimated product of a penny general rate, 1956-1957 | L1: Rateable Value Valuation in force in April, 1956 | M1: Rateable Value Increase per cent (April, 1956, compared with April, 1955) | N1: Amount of rates estimated to be collected per head of population 1956-57 | P1: Amount of rates estimated to be collected per head of population Increase(+) or decrease(-) per cent (1956-57 compared with (1955-56) | Q1: Other heriditaments ratio | R1: Other heriditaments estimate | S1: Concat Name | T1: Type of authority | V1: 61 CODE | W1: 1971 CODE | X1: cty_81
C2: s | D2: d | E2: s | F2: d | G2: s | H2: d | I2: s | J2: d | K2: £ | L2: £ | M2: % | N2: £ | O2: s
A3: City of London | B3: City of London | C3: 18 | D3: 9 | E3: 11 | F3: 0 | K3: 56710 | L3: 14032286 | M3: 102.7 | N3: 1412 | O3: 19 | P3: 16 | Q3: ='Table H'!$J$400 -> 0.92034639 | R3: =Q3*L3 -> 12914564 | S3: City of London | T3: MB | V3: J04000321 | W3: e140370 | X3: =INDEX('Lookup 1961'!$C$2:$C$1300, MATCH(V3, 'Lookup 1961'!$A$2:$A$1300,0)) -> Inner London
A4: Battersea | B4: Battersea | C4: 21 | D4: 0 | E4: 14 | F4: 4 | K4: 6400 | L4: 1606495 | M4: 61.8 | N4: 10 | O4: 1 | P4: 10.4 | Q4: ='Table H'!$J$400 -> 0.92034639 | R4: =Q4*L4 -> 1478531.9 | S4: =_xlfn.CONCAT(B4," ",T4) -> Battersea MB | T4: MB | V4: =INDEX('Lookup 1961'!$A$2:$A$1300, MATCH(S4, 'Lookup 1961'!$B$2:$B$1300,0)) -> J04000102 | W4: =INDEX('Lookup 1961'!$F$2:$F$1300, MATCH(S4, 'Lookup 1961'!$B$2:$B$1300,0)) -> e140408 | X4: =INDEX('Lookup 1961'!$C$2:$C$1300, MATCH(V4, 'Lookup 1961'!$A$2:$A$1300,0)) -> Inner London
A5: Bermondsey | B5: Bermondsey | C5: 23 | D5: 6 | E5: 15 | F5: 6 | K5: 5550 | L5: 1402136 | M5: 104.0 | N5: 18 | O5: 9 | P5: 33.3 | Q5: ='Table H'!$J$400 -> 0.92034639 | R5: =Q5*L5 -> 1290450.8 | S5: =_xlfn.CONCAT(B5," ",T5) -> Bermondsey MB | T5: MB | V5: =INDEX('Lookup 1961'!$A$2:$A$1300, MATCH(S5, 'Lookup 1961'!$B$2:$B$1300,0)) -> J04000127 | W5: =INDEX('Lookup 1961'!$F$2:$F$1300, MATCH(S5, 'Lookup 1961'!$B$2:$B$1300,0)) -> e140402 | X5: =INDEX('Lookup 1961'!$C$2:$C$1300, MATCH(V5, 'Lookup 1961'!$A$2:$A$1300,0)) -> Inner London
A6: Bethnal Green | B6: Bethnal Green | C6: 23 | D6: 8 | E6: 16 | F6: 4 | K6: 2700 | L6: 704170 | M6: 57.8 | N6: 10 | O6: 11 | P6: 11.4 | Q6: ='Table H'!$J$400 -> 0.92034639 | R6: =Q6*L6 -> 648080.31 | S6: =_xlfn.CONCAT(B6," ",T6) -> Bethnal Green MB | T6: MB | V6: =INDEX('Lookup 1961'!$A$2:$A$1300, MATCH(S6, 'Lookup 1961'!$B$2:$B$1300,0)) -> J04000130 | W6: =INDEX('Lookup 1961'!$F$2:$F$1300, MATCH(S6, 'Lookup 1961'!$B$2:$B$1300,0)) -> e140405 | X6: =INDEX('Lookup 1961'!$C$2:$C$1300, MATCH(V6, 'Lookup 1961'!$A$2:$A$1300,0)) -> Inner London
A7: Camberwell | B7: Camberwell | C7: 19 | D7: 8 | E7: 14 | F7: 0 | K7: 9710 | L7: 2467129 | M7: 50.1 | N7: 9 | O7: 6 | P7: 3.5 | Q7: ='Table H'!$J$400 -> 0.92034639 | R7: =Q7*L7 -> 2270613.3 | S7: =_xlfn.CONCAT(B7," ",T7) -> Camberwell MB | T7: MB | V7: =INDEX('Lookup 1961'!$A$2:$A$1300, MATCH(S7, 'Lookup 1961'!$B$2:$B$1300,0)) -> J04000254 | W7: =INDEX('Lookup 1961'!$F$2:$F$1300, MATCH(S7, 'Lookup 1961'!$B$2:$B$1300,0)) -> e140402 | X7: =INDEX('Lookup 1961'!$C$2:$C$1300, MATCH(V7, 'Lookup 1961'!$A$2:$A$1300,0)) -> Inner London
A8: Chelsea | B8: Chelsea | C8: 19 | D8: 10 | E8: 14 | F8: 4 | K8: 7850 | L8: 2039636 | M8: 54.5 | N8: 26 | O8: 13 | P8: 8 | Q8: ='Table H'!$J$400 -> 0.92034639 | R8: =Q8*L8 -> 1877171.6 | S8: =_xlfn.CONCAT(B8," ",T8) -> Chelsea MB | T8: MB | V8: =INDEX('Lookup 1961'!$A$2:$A$1300, MATCH(S8, 'Lookup 1961'!$B$2:$B$1300,0)) -> J04000290 | W8: =INDEX('Lookup 1961'!$F$2:$F$1300, MATCH(S8, 'Lookup 1961'!$B$2:$B$1300,0)) -> e140392 | X8: =INDEX('Lookup 1961'!$C$2:$C$1300, MATCH(V8, 'Lookup 1961'!$A$2:$A$1300,0)) -> Inner London
A9: Deptford | B9: Deptford | C9: 20 | D9: 0 | E9: 14 | F9: 8 | K9: 3522 | L9: 912209 | M9: 53.6 | N9: 8 | O9: 17 | P9: 10.9 | Q9: ='Table H'!$J$400 -> 0.92034639 | R9: =Q9*L9 -> 839548.26 | S9: =_xlfn.CONCAT(B9," ",T9) -> Deptford MB | T9: MB | V9: =INDEX('Lookup 1961'!$A$2:$A$1300, MATCH(S9, 'Lookup 1961'!$B$2:$B$1300,0)) -> J04000399 | W9: =INDEX('Lookup 1961'!$F$2:$F$1300, MATCH(S9, 'Lookup 1961'!$B$2:$B$1300,0)) -> e140397 | X9: =INDEX('Lookup 1961'!$C$2:$C$1300, MATCH(V9, 'Lookup 1961'!$A$2:$A$1300,0)) -> Inner London
A10: Finsbury | B10: Finsbury | C10: 23 | D10: 0 | E10: 15 | F10: 0 | K10: 8900 | L10: 2296964 | M10: 124.5 | N10: 46 | O10: 5 | P10: 40.5 | Q10: ='Table H'!$J$400 -> 0.92034639 | R10: =Q10*L10 -> 2114002.5 | S10: =_xlfn.CONCAT(B10," ",T10) -> Finsbury MB | T10: MB | V10: =INDEX('Lookup 1961'!$A$2:$A$1300, MATCH(S10, 'Lookup 1961'!$B$2:$B$1300,0)) -> J04000504 | W10: =INDEX('Lookup 1961'!$F$2:$F$1300, MATCH(S10, 'Lookup 1961'!$B$2:$B$1300,0)) -> e140390 | X10: =INDEX('Lookup 1961'!$C$2:$C$1300, MATCH(V10, 'Lookup 1961'!$A$2:$A$1300,0)) -> Inner London
A11: Fulham | B11: Fulham | C11: 20 | D11: 6 | E11: 14 | F11: 0 | K11: 7200 | L11: 1853383 | M11: 56.2 | N11: 10 | O11: 9 | P11: 3.2 | Q11: ='Table H'!$J$400 -> 0.92034639 | R11: =Q11*L11 -> 1705754.3 | S11: =_xlfn.CONCAT(B11," ",T11) -> Fulham MB | T11: MB | V11: =INDEX('Lookup 1961'!$A$2:$A$1300, MATCH(S11, 'Lookup 1961'!$B$2:$B$1300,0)) -> J04000521 | W11: =INDEX('Lookup 1961'!$F$2:$F$1300, MATCH(S11, 'Lookup 1961'!$B$2:$B$1300,0)) -> e140384 | X11: =INDEX('Lookup 1961'!$C$2:$C$1300, MATCH(V11, 'Lookup 1961'!$A$2:$A$1300,0)) -> Inner London
A12: Greenwich | B12: Greenwich | C12: 20 | D12: 4 | E12: 13 | F12: 0 | K12: 5755 | L12: 1402911 | M12: 68.5 | N12: 10 | O12: 4 | P12: 8.9 | Q12: ='Table H'!$J$400 -> 0.92034639 | R12: =Q12*L12 -> 1291164.1 | S12: =_xlfn.CONCAT(B12," ",T12) -> Greenwich MB | T12: MB | V12: =INDEX('Lookup 1961'!$A$2:$A$1300, MATCH(S12, 'Lookup 1961'!$B$2:$B$1300,0)) -> J04000553 | W12: =INDEX('Lookup 1961'!$F$2:$F$1300, MATCH(S12, 'Lookup 1961'!$B$2:$B$1300,0)) -> e140381 | X12: =INDEX('Lookup 1961'!$C$2:$C$1300, MATCH(V12, 'Lookup 1961'!$A$2:$A$1300,0)) -> Inner London
A13: Hackney | B13: Hackney | C13: 20 | D13: 4 | E13: 13 | F13: 8 | K13: 9860 | L13: 2491633 | M13: 71.8 | N13: 9 | O13: 19 | P13: 14.2 | Q13: ='Table H'!$J$400 -> 0.92034639 | R13: =Q13*L13 -> 2293165.4 | S13: =_xlfn.CONCAT(B13," ",T13) -> Hackney MB | T13: MB | V13: =INDEX('Lookup 1961'!$A$2:$A$1300, MATCH(S13, 'Lookup 1961'!$B$2:$B$1300,0)) -> J04000560 | W13: =INDEX('Lookup 1961'!$F$2:$F$1300, MATCH(S13, 'Lookup 1961'!$B$2:$B$1300,0)) -> e140382 | X13: =INDEX('Lookup 1961'!$C$2:$C$1300, MATCH(V13, 'Lookup 1961'!$A$2:$A$1300,0)) -> Inner London
A14: Hammersmith | B14: Hammersmith | C14: 20 | D14: 4 | E14: 13 | F14: 2 | K14: 8900 | L14: 2218926 | M14: 70.7 | N14: 12 | O14: 9 | P14: 11.6 | Q14: ='Table H'!$J$400 -> 0.92034639 | R14: =Q14*L14 -> 2042180.5 | S14: =_xlfn.CONCAT(B14," ",T14) -> Hammersmith MB | T14: MB | V14: =INDEX('Lookup 1961'!$A$2:$A$1300, MATCH(S14, 'Lookup 1961'!$B$2:$B$1300,0)) -> J04000572 | W14: =INDEX('Lookup 1961'!$F$2:$F$1300, MATCH(S14, 'Lookup 1961'!$B$2:$B$1300,0)) -> e140384 | X14: =INDEX('Lookup 1961'!$C$2:$C$1300, MATCH(V14, 'Lookup 1961'!$A$2:$A$1300,0)) -> Inner London
A15: Hampstead | B15: Hampstead | C15: 20 | D15: 2 | E15: 13 | F15: 10 | K15: 8936 | L15: 2236845 | M15: 31.7 | N15: 15 | O15: 9 | P15: -10.4 | Q15: ='Table H'!$J$400 -> 0.92034639 | R15: =Q15*L15 -> 2058672.2 | S15: =_xlfn.CONCAT(B15," ",T15) -> Hampstead MB | T15: MB | V15: =INDEX('Lookup 1961'!$A$2:$A$1300, MATCH(S15, 'Lookup 1961'!$B$2:$B$1300,0)) -> J04000573 | W15: =INDEX('Lookup 1961'!$F$2:$F$1300, MATCH(S15, 'Lookup 1961'!$B$2:$B$1300,0)) -> e140376 | X15: =INDEX('Lookup 1961'!$C$2:$C$1300, MATCH(V15, 'Lookup 1961'!$A$2:$A$1300,0)) -> Inner London
... A25: Shoreditch | B25: Shoreditch | C25: 23 | D25: 0 | E25: 14 | F25: 8 | K25: 4100 | L25: 1058161 | M25: 64.9 | N25: 16 | O25: 10 | P25: 4.4 | Q25: ='Table H'!$J$400 -> 0.92034639 | R25: =Q25*L25 -> 973874.65 | S25: =_xlfn.CONCAT(B25," ",T25) -> Shoreditch MB | T25: MB | V25: =INDEX('Lookup 1961'!$A$2:$A$1300, MATCH(S25, 'Lookup 1961'!$B$2:$B$1300,0)) -> J04001138 | W25: =INDEX('Lookup 1961'!$F$2:$F$1300, MATCH(S25, 'Lookup 1961'!$B$2:$B$1300,0)) -> e140382 | X25: =INDEX('Lookup 1961'!$C$2:$C$1300, MATCH(V25, 'Lookup 1961'!$A$2:$A$1300,0)) -> Inner London
A26: Southwark: | B26: Southwark | X26: =INDEX('Lookup 1961'!$C$2:$C$1300, MATCH(V26, 'Lookup 1961'!$A$2:$A$1300,0)) -> #N/A
A27: Rating area of-- | B27: Rating area of | X27: =INDEX('Lookup 1961'!$C$2:$C$1300, MATCH(V27, 'Lookup 1961'!$A$2:$A$1300,0)) -> #N/A
A28: St. George-the-Martyr and Christchurch | B28: St. George-the-Martyr and Christchurch | C28: 21 | D28: 0 | E28: 14 | F28: 5 | S28: =_xlfn.CONCAT(B28," ",T28) -> St. George-the-Martyr and Christchurch MB | T28: MB | V28: =INDEX('Lookup 1961'!$A$2:$A$1300, MATCH(S28, 'Lookup 1961'!$B$2:$B$1300,0)) -> #N/A | W28: =INDEX('Lookup 1961'!$F$2:$F$1300, MATCH(S28, 'Lookup 1961'!$B$2:$B$1300,0)) -> #N/A | X28: =INDEX('Lookup 1961'!$C$2:$C$1300, MATCH(V28, 'Lookup 1961'!$A$2:$A$1300,0)) -> #N/A
A29: St. Mary, Newington | B29: Southwark | C29: 20 | D29: 10 | E29: 14 | F29: 3 | K29: 7330 | L29: 1871918 | M29: 74.2 | N29: 13 | O29: 17 | P29: 19 | Q29: ='Table H'!$J$400 -> 0.92034639 | R29: =Q29*L29 -> 1722813 | S29: =_xlfn.CONCAT(B29," ",T29) -> Southwark MB | T29: MB | V29: =INDEX('Lookup 1961'!$A$2:$A$1300, MATCH(S29, 'Lookup 1961'!$B$2:$B$1300,0)) -> J04001169 | W29: =INDEX('Lookup 1961'!$F$2:$F$1300, MATCH(S29, 'Lookup 1961'!$B$2:$B$1300,0)) -> e140402 | X29: =INDEX('Lookup 1961'!$C$2:$C$1300, MATCH(V29, 'Lookup 1961'!$A$2:$A$1300,0)) -> Inner London
A30: St. Saviour | B30: St. Saviour | C30: 20 | D30: 6 | E30: 14 | F30: 1 | S30: =_xlfn.CONCAT(B30," ",T30) -> St. Saviour MB | T30: MB | V30: =INDEX('Lookup 1961'!$A$2:$A$1300, MATCH(S30, 'Lookup 1961'!$B$2:$B$1300,0)) -> #N/A | W30: =INDEX('Lookup 1961'!$F$2:$F$1300, MATCH(S30, 'Lookup 1961'!$B$2:$B$1300,0)) -> #N/A | X30: =INDEX('Lookup 1961'!$C$2:$C$1300, MATCH(V30, 'Lookup 1961'!$A$2:$A$1300,0)) -> #N/A
A31: Stephney | B31: Stepney | C31: 23 | D31: 4 | E31: 15 | F31: 8 | K31: 8500 | L31: 2261525 | M31: 78.0 | N31: 17 | O31: 1 | P31: 16.2 | Q31: ='Table H'!$J$400 -> 0.92034639 | R31: =Q31*L31 -> 2081386.4 | S31: =_xlfn.CONCAT(B31," ",T31) -> Stepney MB | T31: MB | V31: =INDEX('Lookup 1961'!$A$2:$A$1300, MATCH(S31, 'Lookup 1961'!$B$2:$B$1300,0)) -> J04001206 | W31: =INDEX('Lookup 1961'!$F$2:$F$1300, MATCH(S31, 'Lookup 1961'!$B$2:$B$1300,0)) -> e140405 | X31: =INDEX('Lookup 1961'!$C$2:$C$1300, MATCH(V31, 'Lookup 1961'!$A$2:$A$1300,0)) -> Inner London
A32: Stoke Newington | B32: Stoke Newington | C32: 20 | D32: 6 | E32: 15 | F32: 4 | K32: 2700 | L32: 694646 | M32: 52.6 | N32: 10 | O32: 7 | P32: 14.7 | Q32: ='Table H'!$J$400 -> 0.92034639 | R32: =Q32*L32 -> 639314.94 | S32: =_xlfn.CONCAT(B32," ",T32) -> Stoke Newington MB | T32: MB | V32: =INDEX('Lookup 1961'!$A$2:$A$1300, MATCH(S32, 'Lookup 1961'!$B$2:$B$1300,0)) -> J04001212 | W32: =INDEX('Lookup 1961'!$F$2:$F$1300, MATCH(S32, 'Lookup 1961'!$B$2:$B$1300,0)) -> e140382 | X32: =INDEX('Lookup 1961'!$C$2:$C$1300, MATCH(V32, 'Lookup 1961'!$A$2:$A$1300,0)) -> Inner London
A33: Wandsworth | B33: Wandsworth | C33: 19 | D33: 0 | E33: 12 | F33: 8 | K33: 20900 | L33: 5344015 | M33: 53.7 | N33: 9 | O33: 19 | P33: 2.2 | Q33: ='Table H'!$J$400 -> 0.92034639 | R33: =Q33*L33 -> 4918344.9 | S33: =_xlfn.CONCAT(B33," ",T33) -> Wandsworth MB | T33: MB | V33: =INDEX('Lookup 1961'!$A$2:$A$1300, MATCH(S33, 'Lookup 1961'!$B$2:$B$1300,0)) -> J04001334 | W33: =INDEX('Lookup 1961'!$F$2:$F$1300, MATCH(S33, 'Lookup 1961'!$B$2:$B$1300,0)) -> e140408 | X33: =INDEX('Lookup 1961'!$C$2:$C$1300, MATCH(V33, 'Lookup 1961'!$A$2:$A$1300,0)) -> Inner London
A34: Westminster | B34: Westminster | C34: 17 | D34: 4 | E34: 10 | F34: 10 | K34: 91500 | L34: 22459277 | M34: 98.2 | N34: 128 | O34: 12 | P34: 31.5 | Q34: ='Table H'!$J$400 -> 0.92034639 | R34: =Q34*L34 -> 20670314 | S34: =_xlfn.CONCAT(B34," ",T34) -> Westminster MB | T34: MB | V34: =INDEX('Lookup 1961'!$A$2:$A$1300, MATCH(S34, 'Lookup 1961'!$B$2:$B$1300,0)) -> J04001391 | W34: =INDEX('Lookup 1961'!$F$2:$F$1300, MATCH(S34, 'Lookup 1961'!$B$2:$B$1300,0)) -> e140409 | X34: =INDEX('Lookup 1961'!$C$2:$C$1300, MATCH(V34, 'Lookup 1961'!$A$2:$A$1300,0)) -> Inner London
A35: City of Woolwich | B35: Woolwich | C35: 20 | D35: 11 | E35: 13 | F35: 6 | K35: 9827 | L35: 2421106 | M35: 90.8 | N35: 10 | O35: 19 | P35: 23.3 | Q35: ='Table H'!$J$400 -> 0.92034639 | R35: =Q35*L35 -> 2228256.2 | S35: =_xlfn.CONCAT(B35," ",T35) -> Woolwich MB | T35: MB | V35: =INDEX('Lookup 1961'!$A$2:$A$1300, MATCH(S35, 'Lookup 1961'!$B$2:$B$1300,0)) -> J04001449 | W35: =INDEX('Lookup 1961'!$F$2:$F$1300, MATCH(S35, 'Lookup 1961'!$B$2:$B$1300,0)) -> e140381 | X35: =INDEX('Lookup 1961'!$C$2:$C$1300, MATCH(V35, 'Lookup 1961'!$A$2:$A$1300,0)) -> Inner London
A36: Barnsley | B36: Barnsley | C36: 23 | D36: 3 | E36: 18 | F36: 6 | K36: 2703 | L36: 705970 | M36: 64 | N36: 8 | O36: 8 | P36: 31.7 | Q36: ='Table H'!J311 -> 0.92522487 | R36: =Q36*L36 -> 653181 | S36: =_xlfn.CONCAT(B36," ",T36) -> Barnsley CB | T36: CB | V36: =INDEX('Lookup 1961'!$A$2:$A$1300, MATCH(S36, 'Lookup 1961'!$B$2:$B$1300,0)) -> J04000087 | W36: =INDEX('Lookup 1961'!$F$2:$F$1300, MATCH(S36, 'Lookup 1961'!$B$2:$B$1300,0)) -> e461199 | X36: =INDEX('Lookup 1961'!$C$2:$C$1300, MATCH(V36, 'Lookup 1961'!$A$2:$A$1300,0)) -> South Yorkshire
A37: Barrow-in-Furness | B37: Barrow-in-Furness | C37: 25 | D37: 4 | E37: 19 | F37: 0 | K37: 2950 | L37: 734374 | M37: 61.6 | N37: 10 | O37: 10 | P37: 22.2 | Q37: ='Table H'!J312 -> 0.87674945 | R37: =Q37*L37 -> 643862 | S37: =_xlfn.CONCAT(B37," ",T37) -> Barrow-in-Furness CB | T37: CB | V37: =INDEX('Lookup 1961'!$A$2:$A$1300, MATCH(S37, 'Lookup 1961'!$B$2:$B$1300,0)) -> J04000092 | W37: =INDEX('Lookup 1961'!$F$2:$F$1300, MATCH(S37, 'Lookup 1961'!$B$2:$B$1300,0)) -> e200560 | X37: =INDEX('Lookup 1961'!$C$2:$C$1300, MATCH(V37, 'Lookup 1961'!$A$2:$A$1300,0)) -> Cumbria
A38: Bath | B38: Bath, city of | C38: 23 | D38: 4 | E38: 17 | F38: 0 | K38: 4480 | L38: 1145778 | M38: 63.6 | N38: 11 | O38: 9 | P38: 15.3 | Q38: ='Table H'!J313 -> 0.95866651 | R38: =Q38*L38 -> 1098419 | S38: =_xlfn.CONCAT(B38," ",T38) -> Bath, city of CB | T38: CB | V38: =INDEX('Lookup 1961'!$A$2:$A$1300, MATCH(S38, 'Lookup 1961'!$B$2:$B$1300,0)) -> J04000099 | W38: =INDEX('Lookup 1961'!$F$2:$F$1300, MATCH(S38, 'Lookup 1961'!$B$2:$B$1300,0)) -> e320902 | X38: =INDEX('Lookup 1961'!$C$2:$C$1300, MATCH(V38, 'Lookup 1961'!$A$2:$A$1300,0)) -> Avon
A39: Birkinhead | B39: Birkenhead | C39: 23 | D39: 6 | E39: 16 | F39: 3 | K39: 6045 | L39: 1559984 | M39: 46.1 | N39: 8 | O39: 12 | P39: 0.8 | Q39: ='Table H'!J314 -> 0.92126265 | R39: =Q39*L39 -> 1437155 | S39: =_xlfn.CONCAT(B39," ",T39) -> Birkenhead CB | T39: CB | V39: =INDEX('Lookup 1961'!$A$2:$A$1300, MATCH(S39, 'Lookup 1961'!$B$2:$B$1300,0)) -> J04000149 | W39: =INDEX('Lookup 1961'!$F$2:$F$1300, MATCH(S39, 'Lookup 1961'!$B$2:$B$1300,0)) -> e050068 | X39: =INDEX('Lookup 1961'!$C$2:$C$1300, MATCH(V39, 'Lookup 1961'!$A$2:$A$1300,0)) -> Merseyside
A40: Birmingham | B40: Birmingham, city of | C40: 25 | D40: 0 | E40: 18 | F40: 6 | K40: 61850 | L40: 16006667 | M40: 105.1 | N40: 12 | O40: 12 | P40: 48.7 | Q40: ='Table H'!J315 -> 0.89616789 | R40: =Q40*L40 -> 14344661 | S40: =_xlfn.CONCAT(B40," ",T40) -> Birmingham, city of CB | T40: CB | V40: =INDEX('Lookup 1961'!$A$2:$A$1300, MATCH(S40, 'Lookup 1961'!$B$2:$B$1300,0)) -> J04000150 | W40: =INDEX('Lookup 1961'!$F$2:$F$1300, MATCH(S40, 'Lookup 1961'!$B$2:$B$1300,0)) -> e391064 | X40: =INDEX('Lookup 1961'!$C$2:$C$1300, MATCH(V40, 'Lookup 1961'!$A$2:$A$1300,0)) -> West Midlands
A41: Blackburn | B41: Blackburn | C41: 25 | D41: 0 | E41: 19 | F41: 6 | K41: 4368 | L41: 1122356 | M41: 43.1 | N41: 9 | O41: 6 | P41: 9.5 | Q41: ='Table H'!J316 -> 0.90406074 | R41: =Q41*L41 -> 1014678 | S41: =_xlfn.CONCAT(B41," ",T41) -> Blackburn CB | T41: CB | V41: =INDEX('Lookup 1961'!$A$2:$A$1300, MATCH(S41, 'Lookup 1961'!$B$2:$B$1300,0)) -> J04000155 | W41: =INDEX('Lookup 1961'!$F$2:$F$1300, MATCH(S41, 'Lookup 1961'!$B$2:$B$1300,0)) -> e200561 | X41: =INDEX('Lookup 1961'!$C$2:$C$1300, MATCH(V41, 'Lookup 1961'!$A$2:$A$1300,0)) -> Lancashire
A42: Blackpool | B42: Blackpool | C42: 19 | D42: 0 | E42: 11 | F42: 6 | K42: 14000 | L42: 3518409 | M42: 86.6 | N42: 13 | O42: 10 | P42: 12.6 | Q42: ='Table H'!J317 -> 0.9795092 | R42: =Q42*L42 -> 3446314 | S42: =_xlfn.CONCAT(B42," ",T42) -> Blackpool CB | T42: CB | V42: =INDEX('Lookup 1961'!$A$2:$A$1300, MATCH(S42, 'Lookup 1961'!$B$2:$B$1300,0)) -> J04000157 | W42: =INDEX('Lookup 1961'!$F$2:$F$1300, MATCH(S42, 'Lookup 1961'!$B$2:$B$1300,0)) -> e200562 | X42: =INDEX('Lookup 1961'!$C$2:$C$1300, MATCH(V42, 'Lookup 1961'!$A$2:$A$1300,0)) -> Lancashire
A43: Bolton | B43: Bolton | C43: 25 | D43: 6 | E43: 18 | F43: 6 | K43: 7000 | L43: 1824305 | M43: 52.8 | N43: 9 | O43: 11 | P43: 6 | Q43: ='Table H'!J318 -> 0.88360444 | R43: =Q43*L43 -> 1611964 | S43: =_xlfn.CONCAT(B43," ",T43) -> Bolton CB | T43: CB | V43: =INDEX('Lookup 1961'!$A$2:$A$1300, MATCH(S43, 'Lookup 1961'!$B$2:$B$1300,0)) -> J04000173 | W43: =INDEX('Lookup 1961'!$F$2:$F$1300, MATCH(S43, 'Lookup 1961'!$B$2:$B$1300,0)) -> e200563 | X43: =INDEX('Lookup 1961'!$C$2:$C$1300, MATCH(V43, 'Lookup 1961'!$A$2:$A$1300,0)) -> Greater Manchester
A44: Bootle | B44: Bootle | C44: 24 | D44: 11 | E44: 21 | F44: 4 | K44: 3370 | L44: 871470 | M44: 47.7 | N44: 10 | O44: 15 | P44: 18.7 | Q44: ='Table H'!J319 -> 0.84939126 | R44: =Q44*L44 -> 740219 | S44: =_xlfn.CONCAT(B44," ",T44) -> Bootle CB | T44: CB | V44: =INDEX('Lookup 1961'!$A$2:$A$1300, MATCH(S44, 'Lookup 1961'!$B$2:$B$1300,0)) -> J04000174 | W44: =INDEX('Lookup 1961'!$F$2:$F$1300, MATCH(S44, 'Lookup 1961'!$B$2:$B$1300,0)) -> e200564 | X44: =INDEX('Lookup 1961'!$C$2:$C$1300, MATCH(V44, 'Lookup 1961'!$A$2:$A$1300,0)) -> Merseyside
A45: Bournemouth | B45: Bournemouth | C45: 15 | D45: 2 | E45: 10 | F45: 0 | K45: 15700 | L45: 3906018 | M45: 81.9 | N45: 13 | O45: 6 | P45: 16.9 | Q45: ='Table H'!J320 -> 0.98904204 | R45: =Q45*L45 -> 3863216 | S45: =_xlfn.CONCAT(B45," ",T45) -> Bournemouth CB | T45: CB | V45: =INDEX('Lookup 1961'!$A$2:$A$1300, MATCH(S45, 'Lookup 1961'!$B$2:$B$1300,0)) -> J04000179 | W45: =INDEX('Lookup 1961'!$F$2:$F$1300, MATCH(S45, 'Lookup 1961'!$B$2:$B$1300,0)) -> e150411 | X45: =INDEX('Lookup 1961'!$C$2:$C$1300, MATCH(V45, 'Lookup 1961'!$A$2:$A$1300,0)) -> Dorset
A46: Bradford | B46: Bradford, city of | C46: 26 | D46: 0 | E46: 18 | F46: 0 | K46: 12500 | L46: 3283834 | M46: 46.6 | N46: 9 | O46: 11 | P46: -2.7 | Q46: ='Table H'!J321 -> 0.89677462 | R46: =Q46*L46 -> 2944859 | S46: =_xlfn.CONCAT(B46," ",T46) -> Bradford, city of CB | T46: CB | V46: =INDEX('Lookup 1961'!$A$2:$A$1300, MATCH(S46, 'Lookup 1961'!$B$2:$B$1300,0)) -> J04000187 | W46: =INDEX('Lookup 1961'!$F$2:$F$1300, MATCH(S46, 'Lookup 1961'!$B$2:$B$1300,0)) -> e461200 | X46: =INDEX('Lookup 1961'!$C$2:$C$1300, MATCH(V46, 'Lookup 1961'!$A$2:$A$1300,0)) -> West Yorkshire
A47: Brighton | B47: Brighton | C47: 17 | D47: 4 | E47: 12 | F47: 3 | K47: 14397 | L47: 3712135 | M47: 72.3 | N47: 13 | O47: 19 | P47: 19.3 | Q47: ='Table H'!J322 -> 0.9740128 | R47: =Q47*L47 -> 3615667 | S47: =_xlfn.CONCAT(B47," ",T47) -> Brighton CB | T47: CB | V47: =INDEX('Lookup 1961'!$A$2:$A$1300, MATCH(S47, 'Lookup 1961'!$B$2:$B$1300,0)) -> J04000212 | W47: =INDEX('Lookup 1961'!$F$2:$F$1300, MATCH(S47, 'Lookup 1961'!$B$2:$B$1300,0)) -> e371029 | X47: =INDEX('Lookup 1961'!$C$2:$C$1300, MATCH(V47, 'Lookup 1961'!$A$2:$A$1300,0)) -> East Sussex
... A114: York | B114: York, city and county of | C114: 23 | D114: 0 | E114: 16 | F114: 6 | K114: 5100 | L114: 1265547 | M114: 62.3 | N114: 9 | O114: 18 | P114: 18.5 | Q114: ='Table H'!J389 -> 0.94092752 | R114: =Q114*L114 -> 1190788 | S114: =_xlfn.CONCAT(B114," ",T114) -> York, city and county of CB | T114: CB | V114: =INDEX('Lookup 1961'!$A$2:$A$1300, MATCH(S114, 'Lookup 1961'!$B$2:$B$1300,0)) -> J04001466 | W114: =INDEX('Lookup 1961'!$F$2:$F$1300, MATCH(S114, 'Lookup 1961'!$B$2:$B$1300,0)) -> e461209 | X114: =INDEX('Lookup 1961'!$C$2:$C$1300, MATCH(V114, 'Lookup 1961'!$A$2:$A$1300,0)) -> North Yorkshire
A115: BEDFORD: | B115: BEDFORD: | S115: =_xlfn.CONCAT(B115," ",T115) -> BEDFORD: | V115: =INDEX('Lookup 1961'!$A$2:$A$1300, MATCH(S115, 'Lookup 1961'!$B$2:$B$1300,0)) -> #N/A | W115: =INDEX('Lookup 1961'!$F$2:$F$1300, MATCH(S115, 'Lookup 1961'!$B$2:$B$1300,0)) -> #N/A | X115: =INDEX('Lookup 1961'!$C$2:$C$1300, MATCH(V115, 'Lookup 1961'!$A$2:$A$1300,0)) -> #N/A
...

Sheet Table H
B1: TABLE H
B2: April, 1956-Administrative Countries
C3: Rateable value of
B4: NAME OF ADMINISTRATIVE COUNTRIES | C4: Industrial hereditaments apportioned between industrial purposes and non-industrial purposes | E4: Freight-transport hereditaments apportioned between transport purposes and non-transport purposes | G4: Other hereditaments | H4: Value of property occupied by or on behalf of the Crown for public purposes upon which contributions in lieu of rates are paid | I4: Totals | J4: Proportion heriditaments 'other'
B5: £ | C5: £ | D5: £ | E5: £ | F5: £ | G5: £ | H5: £ | I5: £
B6: 1 | C6: 2 | D6: 3 | E6: 4 | F6: 5 | G6: 6 | H6: 7 | I6: 8
B7: ENGLAND
B8: BEDFORD:
B9: Non-County Boroughs | C9: 198533 | D9: 28213 | G9: 2642532 | H9: 22024 | I9: 2891302 | J9: =G9/I9 -> 0.91395918
B10: Urban Districts | C10: 16242 | D10: 2461 | G10: 334661 | H10: 13686 | I10: 367050 | J10: =G10/I10 -> 0.91175862
B11: Rural Districts | C11: 93289 | D11: 1554 | G11: 748669 | H11: 79975 | I11: 923487 | J11: =G11/I11 -> 0.81069793
B12: Totals | C12: 308064 | D12: 32228 | G12: 3725862 | H12: 115685 | I12: 4181839 | J12: =G12/I12 -> 0.89096256
B13: BERKS: | J13: =G13/I13 -> #DIV/0!
B14: Non-County Boroughs | C14: 44669 | D14: 5637 | G14: 1405991 | H14: 27195 | I14: 1483492 | J14: =G14/I14 -> 0.94775772
B15: Urban Districts | C15: 724 | G15: 53611 | H15: 317 | I15: 54652 | J15: =G15/I15 -> 0.98095221
B16: Rural Districts | C16: 83815 | D16: 5317 | G16: 2089338 | H16: 321754 | I16: 2500224 | J16: =G16/I16 -> 0.83566032
B17: Totals | C17: 129208 | D17: 10954 | G17: 3548940 | H17: 349266 | I17: 4038368 | J17: =G17/I17 -> 0.8788055
B18: BUCKINGHAM: | J18: =G18/I18 -> #DIV/0!
B19: Non-County Boroughs | C19: 289265 | D19: 25467 | F19: 54 | G19: 2222687 | H19: 45101 | I19: 2582574 | J19: =G19/I19 -> 0.86064794
B20: Urban Districts | C20: 47912 | D20: 4545 | F20: 80 | G20: 895440 | H20: 9286 | I20: 957263 | J20: =G20/I20 -> 0.93541691
B21: Rural Districts | C21: 126233 | D21: 8858 | G21: 2429173 | H21: 106304 | I21: 2670568 | J21: =G21/I21 -> 0.90960912
B22: Totals | C22: 463410 | D22: 38870 | F22: 134 | G22: 5547300 | H22: 160691 | I22: 6210405 | J22: =G22/I22 -> 0.89322677
B23: CAMBRIDGE: | J23: =G23/I23 -> #DIV/0!
B24: Non-County Boroughs | C24: 27982 | D24: 13163 | G24: 1788530 | H24: 22006 | I24: 1851681 | J24: =G24/I24 -> 0.96589531
B25: Rural Districts | C25: 38756 | D25: 5738 | G25: 530595 | H25: 56707 | I25: 631796 | J25: =G25/I25 -> 0.83982013
B26: Totals | C26: 66738 | D26: 18901 | G26: 2319125 | H26: 78713 | I26: 2483477 | J26: =G26/I26 -> 0.93382182
B27: CHESTER: | J27: =G27/I27 -> #DIV/0!
B28: Non-County Boroughs | C28: 594970 | D28: 15875 | E28: 13243 | F28: 210 | G28: 3543806 | H28: 37851 | I28: 4206035 | J28: =G28/I28 -> 0.84255267
B29: Urban Districts | C29: 302778 | D29: 7029 | E29: 2589 | F29: 731 | G29: 3361901 | H29: 54010 | I29: 3729038 | J29: =G29/I29 -> 0.90154646
B30: Rural Districts | C30: 128182 | D30: 4973 | E30: 4571 | F30: 59 | G30: 1730800 | H30: 99725 | I30: 1968310 | J30: =G30/I30 -> 0.87933303
B31: Totals | C31: 1025930 | D31: 27877 | E31: 20403 | F31: 1000 | G31: 8636587 | H31: 191586 | I31: 9903383 | J31: =G31/I31 -> 0.87208452
B32: CORNWALL: | J32: =G32/I32 -> #DIV/0!
B33: Non-County Boroughs | C33: 31971 | D33: 6138 | E33: 7723 | G33: 1229209 | H33: 27865 | I33: 1302906 | J33: =G33/I33 -> 0.94343644
B34: Urban Districts | C34: 39170 | D34: 4226 | E34: 892 | G34: 970287 | H34: 21316 | I34: 1035891 | J34: =G34/I34 -> 0.93666901
B35: Rural Districts | C35: 59842 | D35: 1635 | E35: 586 | F35: 585 | G35: 1017431 | H35: 36810 | I35: 1116889 | J35: =G35/I35 -> 0.91095086
B36: Totals | C36: 130983 | D36: 11999 | E36: 9201 | F36: 585 | G36: 3216927 | H36: 85991 | I36: 3455686 | J36: =G36/I36 -> 0.93090836
B37: CUMBERLAND: | J37: =G37/I37 -> #DIV/0!
B38: Non-County Boroughs | C38: 76800 | D38: 1139 | E38: 3473 | G38: 437699 | H38: 3168 | I38: 522279 | J38: =G38/I38 -> 0.8380559
B39: Urban Districts | C39: 8751 | D39: 1236 | E39: 89 | G39: 299958 | H39: 3632 | I39: 313666 | J39: =G39/I39 -> 0.95629746
B40: Rural Districts | C40: 60989 | D40: 1029 | E40: 150 | G40: 761721 | H40: 135711 | I40: 959600 | J40: =G40/I40 -> 0.79379012
...

Sheet Lookup 1961
A1: LA61CD | B1: LA61NM | C1: cty_1981 | D1: rgn | E1: srgn | F1: equiv_1971_cd | G1: equiv_1971_nm | H1: equiv_2001_nm | I1: notes
A2: J04000063 | B2: Axbridge RD | C2: Avon | D2: South West | E2: Rest of England | F2: e320923 | G2: AXBRIDGE R.D. | H2: 0 | I2: 0
A3: J04000099 | B3: Bath, City of CB | C3: Avon | D3: South West | E3: Rest of England | F3: e320902 | G3: BATH C.B. | H3: 0 | I3: 0
A4: J04000100 | B4: Bathavon RD | C4: Avon | D4: South West | E4: Rest of England | F4: e320925 | G4: BATHAVON R.D. | H4: 0 | I4: 0
A5: J04000213 | B5: Bristol, City and County of CB | C5: Avon | D5: South West | E5: Rest of England | F5: e130345 | G5: BRISTOL C.B. | H5: 0 | I5: 0
A6: J04000327 | B6: Clevedon UD | C6: Avon | D6: South West | E6: Rest of England | F6: e320906 | G6: CLEVEDON U.D. | H6: 0 | I6: 0
A7: J04000332 | B7: Clutton RD | C7: Avon | D7: South West | E7: Rest of England | F7: e320928 | G7: CLUTTON R.D. | H7: 0 | I7: 0
A8: J04000690 | B8: Keynsham UD | C8: Avon | D8: South West | E8: Rest of England | F8: e320911 | G8: KEYNSHAM U.D. | H8: 0 | I8: 0
A9: J04000701 | B9: Kingswood UD | C9: Avon | D9: South West | E9: Rest of England | F9: e130350 | G9: KINGSWOOD U.D. | H9: 0 | I9: 0
A10: J04000775 | B10: Long Ashton RD | C10: Avon | D10: South West | E10: Rest of England | F10: e320932 | G10: LONG ASHTON R.D. | H10: 0 | I10: 0
A11: J04000822 | B11: Mangotsfield UD | C11: Avon | D11: South West | E11: Rest of England | F11: e130351 | G11: MANGOTSFIELD U.D. | H11: 0 | I11: 0
A12: J04000938 | B12: Norton Radstock UD | C12: Avon | D12: South West | E12: Rest of England | F12: e320913 | G12: NORTON-RADSTOCK U.D. | H12: 0 | I12: 0
A13: J04001008 | B13: Portishead UD | C13: Avon | D13: South West | E13: Rest of England | F13: e320914 | G13: PORTISHEAD U.D. | H13: 0 | I13: 0
... A25: J04000681 | B25: Kempston UD | C25: Bedfordshire | D25: East of England | E25: Greater South East | F25: e010005 | G25: KEMPSTON U.D. | H25: 0 | I25: 0
A26: J04000733 | B26: Leighton Buzzard UD | C26: Bedfordshire | D26: East of England | E26: Greater South East | F26: e010006 | G26: LEIGHTON-LINSLADE U.D. | H26: 0 | I26: Merged into Leighton-Linslade in 1965
A27: J04000747 | B27: Linslade UD | C27: Bedfordshire | D27: East of England | E27: Greater South East | F27: e010006 | G27: LEIGHTON-LINSLADE U.D. | H27: 0 | I27: Merged into Leighton-Linslade in 1965
A28: J04000790 | B28: Luton MB | C28: Bedfordshire | D28: East of England | E28: Greater South East | F28: e010000 | G28: LUTON C.B. | H28: 0 | I28: 0
A29: J04000791 | B29: Luton RD | C29: Bedfordshire | D29: East of England | E29: Greater South East | F29: e010000 | G29: LUTON C.B. | H29: 0 | I29: 0
A30: J04001103 | B30: Sandy UD | C30: Bedfordshire | D30: East of England | E30: Greater South East | F30: e010007 | G30: SANDY U.D. | H30: 0 | I30: 0
A31: J04000184 | B31: Bradfield RD | C31: Berkshire | D31: South East | E31: Greater South East | F31: e020021 | G31: BRADFIELD R.D. | H31: 0 | I31: 0
A32: J04000347 | B32: Cookham RD | C32: Berkshire | D32: South East | E32: Greater South East | F32: e020022 | G32: COOKHAM R.D. | H32: Windsor and Maidenhead UA | I32: 0
A33: J04000456 | B33: Easthampstead RD | C33: Berkshire | D33: South East | E33: Greater South East | F33: e020023 | G33: EASTHAMPSTEAD R.D. | H33: Bracknell Forest UA | I33: 0
A34: J04000483 | B34: Eton UD | C34: Berkshire | D34: South East | E34: Greater South East | F34: e030038 | G34: ETON U.D. | H34: Windsor and Maidenhead UA | I34: 0
A35: J04000658 | B35: Hungerford RD | C35: Berkshire | D35: South East | E35: Greater South East | F35: e020026 | G35: HUNGERFORD R.D. | H35: 0 | I35: 0
A36: J04000808 | B36: Maidenhead MB | C36: Berkshire | D36: South East | E36: Greater South East | F36: e020014 | G36: MAIDENHEAD M.B. | H36: Windsor and Maidenhead UA | I36: 0
A37: J04000891 | B37: New Windsor MB | C37: Berkshire | D37: South East | E37: Greater South East | F37: e020016 | G37: NEW WINDSOR M.B. | H37: Windsor and Maidenhead UA | I37: 0
A38: J04000896 | B38: Newbury MB | C38: Berkshire | D38: South East | E38: Greater South East | F38: e020015 | G38: NEWBURY M.B. | H38: 0 | I38: 0
A39: J04000897 | B39: Newbury RD | C39: Berkshire | D39: South East | E39: Greater South East | F39: e020027 | G39: NEWBURY R.D. | H39: 0 | I39: 0
A40: J04001036 | B40: Reading CB | C40: Berkshire | D40: South East | E40: Greater South East | F40: e020012 | G40: READING C.B. | H40: Reading UA | I40: 0
A41: J04001150 | B41: Slough MB | C41: Berkshire | D41: South East | E41: Greater South East | F41: e030043 | G41: SLOUGH M.B. | H41: Slough UA | I41: 0
A42: J04001425 | B42: Windsor RD | C42: Berkshire | D42: South East | E42: Greater South East | F42: e020031 | G42: WINDSOR R.D. | H42: Windsor and Maidenhead UA | I42: 0
A43: J04001440 | B43: Wokingham MB | C43: Berkshire | D43: South East | E43: Greater South East | F43: e020019 | G43: WOKINGHAM M.B. | H43: Wokingham | I43: 0
A44: J04001441 | B44: Wokingham RD | C44: Berkshire | D44: South East | E44: Greater South East | F44: e020032 | G44: WOKINGHAM R.D. | H44: Wokingham | I44: 0
A45: J04000037 | B45: Amersham RD | C45: Buckinghamshire | D45: South East | E45: Greater South East | F45: e030046 | G45: AMERSHAM R.D. | H45: Chiltern | I45: 0
A46: J04000065 | B46: Aylesbury MB | C46: Buckinghamshire | D46: South East | E46: Greater South East | F46: e030033 | G46: AYLESBURY M.B. | H46: 0 | I46: 0
A47: J04000066 | B47: Aylesbury RD | C47: Buckinghamshire | D47: South East | E47: Greater South East | F47: e030047 | G47: AYLESBURY R.D. | H47: 0 | I47: 0
A48: J04000104 | B48: Beaconsfield UD | C48: Buckinghamshire | D48: South East | E48: Greater South East | F48: e030034 | G48: BEACONSFIELD U.D. | H48: South Bucks | I48: 0
A49: J04000164 | B49: Bletchley UD | C49: Buckinghamshire | D49: South East | E49: Greater South East | F49: e030035 | G49: BLETCHLEY U.D. | H49: 0 | I49: 0
A50: J04000226 | B50: Buckingham MB | C50: Buckinghamshire | D50: South East | E50: Greater South East | F50: e030036 | G50: BUCKINGHAM M.B. | H50: 0 | I50: 0
A51: J04000227 | B51: Buckingham RD | C51: Buckinghamshire | D51: South East | E51: Greater South East | F51: e030048 | G51: BUCKINGHAM R.D. | H51: 0 | I51: 0
...
