Workbook

Sheet Poundage_63-64_London_62
A2: RATE POUNDAGES, PENNY RATE PRODUCTS, RATEABLE VALUES, POPULATION, AND RATE-DEFICIENCY GRANT PERCENTAGES
F3: <NOTE THIS IS BEFORE THE CREATION OF GREATER LONDON - COUNTY OF LONDON GEOGRAPHY
A4: City of London and Metropolitan Boroughs
A6: TABLE 6 (PART I)
B7: Rate Poundage | D7: Rate poundage 1963-64 for | H7: Average rate poundage 1963-64 | I7: Penny rate product 1963-64 | J7: Change in penny rate product from 1962-63 | K7: Rate call 1963-64 | L7: Rateable values in April 1963 | O7: Population mid 1962 | P7: Rate deficiency grant 1963-64
A8: Local Authority | B8: 1962-63 | C8: 1963-64 | D8: Local purposes | E8: County purposes | F8: Transitional adjustment | G8: London Scheme | L8: Domestic | N8: Total
A9: Table 4 & Table 6 excluding WALES | B9: 1 | C9: 2 | D9: 3 | E9: 4 | F9: 5 | G9: 6 | H9: 7 | I9: 8 | J9: 9 | K9: 10 | L9: 11 | M9: 12 | N9: 13 | O9: 14 | P9: 15
B10: pence | C10: pence | D10: pence | E10: pence | F10: pence | G10: pence | H10: pence | I10: £ | J10: % | K10: £ | L10: Nos. | M10: £000 | N10: £000 | P10: %
A11: LONDON | B11: 135 | C11: 50.5 | I11: 1360000 | J11: 200 | K11: 68680000 | L11: 862321 | M11: 106227.7 | N11: 332908.4 | O11: 3185770
A12: City of London | B12: 211 | C12: 81 | D12: 22.3 | E12: 50.5 | F12: 0.1 | G12: 8.1 | I12: 173000 | J12: 188 | K12: 14013000 | L12: 1193 | M12: 171.4 | N12: 43766.3 | O12: 4610 | Q12: MB
A13: Battersea | B13: 264 | C13: 99 | D13: 70.2 | E13: 51 | F13: 0.3 | G13: -22.5 | I13: 18450 | J13: 161 | K13: 1826550 | L13: 28191 | M13: 2408.2 | N13: 4654 | O13: 104020 | Q13: MB
A14: Bermondsey | B14: 268 | C14: 102 | D14: 74.6 | E14: 51 | F14: 0.2 | G14: -23.7 | I14: 16450 | J14: 155 | K14: 1677900 | L14: 15183 | M14: 918.4 | N14: 4088.7 | O14: 51000 | Q14: MB
A15: Bethnal Green | B15: 284 | C15: 106 | D15: 97.4 | E15: 51 | F15: 0.6 | G15: -43 | I15: 9050 | J15: 217 | K15: 959300 | L15: 14687 | M15: 1088.8 | N15: 2409.4 | O15: 46230 | Q15: MB
A16: Camberwell | B16: 272 | C16: 100 | D16: 69.4 | E16: 51 | F16: 0.7 | G16: -21.1 | I16: 28975 | J16: 177 | K16: 2897500 | L16: 45664 | M16: 4181.3 | N16: 7269.7 | O16: 173720 | P16: 5.2 | Q16: MB
A17: Chelsea | B17: 232 | C17: 84 | D17: 29.4 | E17: 51 | F17: 0.2 | G17: 3.4 | I17: 27500 | J17: 243 | K17: 2310000 | L17: 17020 | M17: 4361.3 | N17: 6984.7 | O17: 48550 | Q17: MB
A18: Deptford | B18: 244 | C18: 92 | D18: 60.1 | E18: 51 | F18: 0.7 | G18: -19.8 | I18: 11100 | J18: 189 | K18: 1021200 | L18: 18402 | M18: 1442.1 | N18: 2831.2 | O18: 68980 | P18: 7.4 | Q18: MB
A19: Finsbury | B19: 230 | C19: 90 | D19: 35.6 | E19: 51 | F19: 0.5 | G19: 3 | I19: 35000 | J19: 192 | K19: 3150000 | L19: 9024 | M19: 955.6 | N19: 9026.5 | O19: 32540 | Q19: MB
A20: Fulham | B20: 256 | C20: 96 | D20: 60.6 | E20: 51 | F20: 0.3 | G20: -15.9 | I20: 23400 | J20: 187 | K20: 2246400 | L20: 30269 | M20: 3336.5 | N20: 5748 | O20: 110570 | Q20: MB
A21: Greewich | B21: 240 | C21: 96 | D21: 53.5 | E21: 51 | F21: 0.1 | G21: -18.6 | I21: 20500 | J21: 182 | K21: 1968000 | L21: 24638 | M21: 1983.1 | N21: 4974.8 | O21: 84730 | Q21: MB
A22: Hackney | B22: 272 | C22: 96 | D22: 64.5 | E22: 51 | F22: 0.3 | G22: -19.9 | I22: 31750 | J22: 197 | K22: 3048000 | L22: 41104 | M22: 4303.9 | N22: 8128.1 | O22: 163400 | Q22: MB
A23: Hammersmith | B23: 238 | C23: 90 | D23: 43.7 | E23: 51 | F23: 0.3 | G23: -5 | I23: 31500 | J23: 230 | K23: 2835000 | L23: 25249 | M23: 2883.9 | N23: 7688.7 | O23: 108120 | Q23: MB
A24: Hampstead | B24: 237 | C24: 93 | D24: 43.4 | E24: 51 | F24: 0.4 | G24: -1.9 | I24: 30480 | J24: 228 | K24: 2834640 | L24: 24586 | M24: 5391 | N24: 7559.5 | O24: 98240 | Q24: MB
A25: Holborn | B25: 220 | C25: 83 | D25: 24.4 | E25: 51 | G25: 7.6 | I25: 44700 | J25: 175 | K25: 310100 | L25: 5847 | M25: 724.7 | N25: 10900 | O25: 20640 | Q25: MB
A26: Islington | B26: 228 | C26: 92 | D26: 50.5 | E26: 51 | F26: 0.6 | G26: -10 | I26: 38600 | J26: 189 | K26: 3551200 | L26: 45479 | M26: 4953.3 | N26: 9702.3 | O26: 227870 | P26: 2 | Q26: MB
A27: Kensington | B27: 230 | C27: 83 | D27: 28 | E27: 51 | F27: 0.1 | G27: 3.9 | I27: 71200 | J27: 233 | K27: 5909600 | L27: 41907 | M27: 10361.3 | N27: 17995.8 | O27: 172020 | Q27: MB
A28: Lambeth | B28: 239 | C28: 88 | D28: 43 | E28: 51 | F28: 0.4 | G28: -6.4 | I28: 53000 | J28: 184 | K28: 4664000 | L28: 57077 | M28: 5470.9 | N28: 12887.7 | O28: 223370 | Q28: MB
A29: Lewisham | B29: 234 | C29: 96 | D29: 54.3 | E29: 51 | F29: 0.7 | G29: -10 | I29: 35750 | J29: 175 | K29: 3432000 | L29: 66307 | M29: 6164.6 | N29: 8854 | O29: 222170 | P29: 10.1 | Q29: MB
A30: Paddington | B30: 236 | C30: 88 | D30: 37.6 | E30: 51 | F30: 0.4 | G30: -1 | I30: 37200 | J30: 235 | K30: 3273600 | L30: 31656 | M30: 5375.1 | N30: 9028.1 | O30: 113600 | Q30: MB
A31: Poplar | B31: 264 | C31: 94 | D31: 58.9 | E31: 51 | G31: -15.9 | I31: 18400 | J31: 255 | K31: 1729600 | L31: 18336 | M31: 1437.6 | N31: 4639.8 | O31: 67340 | Q31: MB
A32: St. Marylebone | B32: 221 | C32: 85 | D32: 23.5 | E32: 51 | F32: 0.2 | G32: 10.3 | I32: 95000 | J32: 217 | K32: 8075000 | L32: 25165 | M32: 6116.5 | N32: 23623.6 | O32: 68070 | Q32: MB
A33: St. Pancras | B33: 236 | C33: 96 | D33: 46.2 | E33: 51 | F33: 0.4 | G33: -1.5 | I33: 49975 | J33: 205 | K33: 4797600 | L33: 29444 | M33: 3865.3 | N33: 12959.8 | O33: 124470 | Q33: MB
A34: Shoreditch | B34: 260 | C34: 98 | D34: 60.5 | E34: 51 | F34: 0.1 | G34: -13.6 | I34: 15228 | J34: 201 | K34: 1492344 | L34: 11801 | M34: 999.8 | N34: 3908 | O34: 39580 | Q34: MB
A35: Southwark | B35: 236 | C35: 92 | D35: 50.7 | E35: 51 | F35: 0.3 | G35: -9.9 | I35: 25200 | J35: 172 | K35: 2318400 | L35: 25072 | M35: 1632.5 | N35: 5872 | O35: 86440 | Q35: MB
A36: Stepney | B36: 244 | C36: 92 | D36: 56.9 | E36: 51 | F36: 0.3 | G36: -16.2 | I36: 28130 | J36: 193 | K36: 2587960 | L36: 26366 | M36: 2054.9 | N36: 7332 | O36: 90480 | Q36: MB
A37: Stoke Newington | B37: 234 | C37: 90 | D37: 54.1 | E37: 51 | F37: 0.7 | G37: -15.8 | I37: 8325 | J37: 191 | K37: 749250 | L37: 12106 | M37: 1384.4 | N37: 2089.6 | O37: 52950 | P37: 10.8 | Q37: MB
A38: Wandsworth | B38: 224 | C38: 94 | D38: 47.1 | E38: 51 | F38: 0.4 | G38: -4.5 | I38: 65200 | J38: 190 | K38: 6128800 | L38: 96873 | M38: 10155.2 | N38: 15831.2 | O38: 374810 | Q38: MB
A39: Westminster, City of | B39: 210 | C39: 82 | D39: 17.7 | E39: 51 | F39: 0.1 | G39: 13.2 | I39: 275000 | J39: 197 | K39: 22550000 | L39: 28215 | M39: 8305.4 | N39: 64590.3 | O39: 86110 | Q39: MB
A40: Woolwich | B40: 248 | C40: 94 | D40: 60.4 | E40: 51 | F40: 0.4 | G40: -17.8 | I40: 32030 | J40: 178 | K40: 3010820 | L40: 45460 | M40: 3801 | N40: 7564.6 | O40: 148140 | Q40: MB
A41: Barnsley | B41: 324 | C41: 141 | D41: 141.5 | E41: -0.5 | I41: 8417 | J41: 157 | K41: 1186797 | L41: 23685 | M41: 903.6 | N41: 2135.6 | O41: 74910 | P41: 35.8 | Q41: CB
A42: Barrow-in-Furness | B42: 288 | C42: 126 | D42: 125.6 | E42: 0.4 | I42: 8100 | J42: 132 | K42: 1020600 | L42: 20718 | M42: 1004.9 | N42: 2095.3 | O42: 64890 | P42: 26.6 | Q42: CB
...

Sheet Poundage_63-64_County_Boroug_62
A2: RATE POUNDAGES, PENNY RATE PRODUCTS, RATEABLE VALUES, POPULATION, AND RATE-DEFICIENCY GRANT PERCENTAGES
A4: County Boroughs
A6: TABLE 6 (PART II)
B7: Rate Poundage | D7: Rate poundage 1963-64 for | F7: Penny rate product 1963-64 | G7: Change in penny rate product from 1962-63 | H7: Rate call 1963-64 | I7: Rateable values in April 1963 | L7: Population mid 1962 | M7: Rate deficiency grant 1963-64
A8: Local Authority | B8: 1962-63 | C8: 1963-64 | D8: Local purposes | E8: Transitional adjustment | I8: Domestic | K8: Total
A9: Table 4 & Table 6 excluding WALES | B9: 1 | C9: 2 | D9: 3 | E9: 4 | F9: 5 | G9: 6 | H9: 7 | I9: 8 | J9: 9 | K9: 10 | L9: 11 | M9: 12
B10: pence | C10: pence | D10: pence | E10: pence | F10: £ | G10: % | H10: £ | I10: Nos. | J10: £000 | K10: £000 | M10: %
A11: ENGLAND
A12: Barnsley | B12: 324 | C12: 141 | D12: 141.5 | E12: -0.5 | F12: 8417 | G12: 157 | H12: 1186797 | I12: 23685 | J12: 903.6 | K12: 2135.6 | L12: 74910 | M12: 35.8
A13: Barrow-in-Furness | B13: 288 | C13: 126 | D13: 125.6 | E13: 0.4 | F13: 8100 | G13: 132 | H13: 1020600 | I13: 20718 | J13: 1004.9 | K13: 2095.3 | L13: 64890 | M13: 26.6
A14: Bath | B14: 288 | C14: 126 | D14: 126.5 | E14: -0.5 | F14: 12090 | G14: 136 | H14: 1523340 | I14: 25404 | J14: 1725.2 | K14: 2999.3 | L14: 82170 | M14: 16.6
A15: Birkenhead | B15: 257 | C15: 101 | D15: 100.6 | E15: 0.4 | F15: 18275 | G15: 150 | H15: 1845775 | I15: 41193 | J15: 2588.2 | K15: 4661.1 | L15: 142940 | M15: 26.2
A16: Birmingham | B16: 324 | C16: 124 | D16: 123.1 | E16: 0.9 | F16: 200300 | G16: 173 | H16: 24837200 | I16: 317287 | J16: 18187.3 | K16: 49603.3 | L16: 1115080
A17: Blackburn | B17: 306 | C17: 132 | D17: 131.1 | E17: 0.9 | F17: 12060 | G17: 144 | H17: 1591920 | I17: 36918 | J17: 1405.1 | K17: 3092 | L17: 105740 | M17: 34
A18: Blackpool | B18: 209 | C18: 107 | D18: 108.1 | E18: -1.1 | F18: 30800 | G18: 116 | H18: 3295600 | I18: 47632 | J18: 4059 | K18: 7812 | L18: 151250
A19: Bolton | B19: 312 | C19: 124 | D19: 124.3 | E19: -0.3 | F19: 20750 | G19: 152 | H19: 2573000 | I19: 54591 | J19: 2386.2 | K19: 5316.6 | L19: 160650 | M19: 26
A20: Bootle | B20: 253.9 | C20: 125 | D20: 124.3 | E20: 0.7 | F20: 10719 | G20: 147 | H20: 1339875 | I20: 21235 | J20: 1156 | K20: 2730.3 | L20: 83220 | M20: 25.8
A21: Bournemouth | B21: 188 | C21: 96 | D21: 97.6 | E21: -1.6 | F21: 37700 | G21: 136 | H21: 3619200 | I21: 48235 | J21: 5570.4 | K21: 9580.9 | L21: 149830
A22: Bradford | B22: 294 | C22: 123 | D22: 122.3 | E22: 0.7 | F22: 37000 | G22: 143 | H22: 4551000 | I22: 99708 | J22: 4051.9 | K22: 9187.8 | L22: 296220 | M22: 30.5
A23: Brighton | B23: 226 | C23: 90 | D23: 90.8 | E23: -0.8 | F23: 43350 | G23: 174 | H23: 3901500 | I23: 53878 | J23: 6673.7 | K23: 10821.2 | L23: 162200
A24: Bristol | B24: 246 | C24: 117 | D24: 117.3 | E24: -0.3 | F24: 80500 | G24: 156 | H24: 9418500 | I24: 130015 | J24: 9046.8 | K24: 19525.4 | L24: 434260
A25: Burnley | B25: 306 | C25: 132 | D25: 132 | E25: 0.1 | F25: 9250 | G25: 143 | H25: 1221000 | I25: 27637 | J25: 918.8 | K25: 2335.7 | L25: 80540 | M25: 34.8
A26: Burton-upon-Trent | B26: 308 | C26: 124 | D26: 123.7 | E26: 0.3 | F26: 9125 | G26: 204 | H26: 1131500 | I26: 16113 | J26: 815.8 | K26: 2216.9 | L26: 50610
A27: Bury | B27: 252 | C27: 104 | D27: 103.3 | E27: 0.7 | F27: 7550 | G27: 140 | H27: 785200 | I27: 21499 | J27: 950.5 | K27: 1897.7 | L27: 61120 | M27: 29.7
A28: Canterbury | B28: 225 | C28: 104 | D28: 104.2 | E28: -0.2 | F28: 5500 | G28: 132 | H28: 572000 | I28: 9787 | J28: 590.3 | K28: 1334.3 | L28: 30720
A29: Carlisle | B29: 300 | C29: 118 | D29: 121 | E29: -3 | F29: 9955 | G29: 168 | H29: 1174690 | I29: 23369 | J29: 1177 | K29: 2440.6 | L29: 70800 | M29: 20.6
A30: Chester | B30: 270 | C30: 118 | D30: 118 | F30: 11060 | G30: 172 | H30: 1305080 | I30: 18867 | J30: 1225.7 | K30: 2709.9 | L30: 59030
A31: Coventry | B31: 300 | C31: 126 | D31: 125.8 | E31: 0.2 | F31: 50000 | G31: 140 | H31: 6300000 | I31: 95028 | J31: 5793.5 | K31: 12201.2 | L31: 310640 | M31: 9.4
A32: Croydon | B32: 240 | C32: 96 | D32: 96 | F32: 58806 | G32: 175 | H32: 5645376 | I32: 76424 | J32: 7333.5 | K32: 13885.8 | L32: 253690
A33: Darlington | B33: 258 | C33: 108 | D33: 106.8 | E33: 1.2 | F33: 14100 | G33: 151 | H33: 1552800 | I33: 27076 | J33: 1570 | K33: 3573.2 | L33: 84400 | M33: 3.8
A34: Derby | B34: 306 | C34: 114 | D34: 112.9 | E34: 1.1 | F34: 26200 | G34: 187 | H34: 2986800 | I34: 41340 | J34: 2133.2 | K34: 6532.9 | L34: 131910
A35: Dewsbury | B35: 298 | C35: 134 | D35: 133.7 | E35: 0.3 | F35: 5590 | G35: 132 | H35: 749060 | I35: 18731 | J35: 620 | K35: 1477.7 | L35: 53520 | M35: 38.9
A36: Doncaster | B36: 312 | C36: 128 | D36: 129.2 | E36: -1.2 | F36: 15000 | G36: 176 | H36: 1920000 | I36: 27010 | J36: 1582.5 | K36: 3662.7 | L36: 86460 | M36: 3.4
A37: Dudley | B37: 294 | C37: 116 | D37: 116 | F37: 10825 | G37: 209 | H37: 1255700 | I37: 18688 | J37: 1022.7 | K37: 2677.5 | L37: 63820 | M37: 5
A38: Eastbourne | B38: 214 | C38: 110 | D38: 112.3 | E38: -2.3 | F38: 12950 | G38: 111 | H38: 1424500 | I38: 20876 | J38: 2106.8 | K38: 3269.7 | L38: 61250
A39: East Ham | B39: 328 | C39: 120 | D39: 120.8 | E39: -0.8 | F39: 16250 | G39: 168 | H39: 1950000 | I39: 31621 | J39: 2270 | K39: 4017.4 | L39: 105430 | M39: 14.8
A40: Exeter | B40: 252 | C40: 124 | D40: 125.4 | E40: -1.4 | F40: 17200 | G40: 133 | H40: 2132800 | I40: 24284 | J40: 1843.5 | K40: 4394.1 | L40: 78950
A41: Gateshead | B41: 330 | C41: 142 | D41: 141.5 | E41: 0.5 | F41: 12500 | G41: 150 | H41: 1775000 | I41: 33694 | J41: 1371.1 | K41: 3200.3 | L41: 103120 | M41: 30
A42: Gloucester | B42: 314 | C42: 150 | D42: 152.8 | E42: -2.8 | F42: 10460 | G42: 122 | H42: 1569000 | I42: 19966 | J42: 1083 | K42: 2559.6 | L42: 70180 | M42: 17.1
A43: Great Yarmouh | B43: 272 | C43: 136 | D43: 137.4 | E43: -1.4 | F43: 9010 | G43: 126 | H43: 1225360 | I43: 17319 | J43: 843.8 | K43: 2226.2 | L43: 52450 | M43: 4.5
...

Sheet 1963-64 PI Table 6(III)
A2: RATE POUNDAGES, PENNY RATE PRODUCTS, RATEABLE VALUES, POPULATION, AND RATE-DEFICIENCY GRANT PERCENTAGES
A4: County District Councils
A6: TABLE 6 (PART III)
B7: Rate Poundage | D7: Rate poundage 1963-64 for | G7: Average rate poundage 1963-64 | H7: Penny rate product 1963-64 | I7: Change in peny rate product from 1962-63 | J7: Rate call 1963-64 | K7: Rateable values in 1963 | M7: Total | N7: Population mid 1962 | O7: Rate deficiency grant 1963-64
A8: Local Authority | B8: 1962-63 | C8: 1963-64 | D8: Local purposes | E8: County purposes | F8: Transitional adjustment | K8: Domestic
B9: 1 | C9: 2 | D9: 3 | E9: 4 | F9: 5 | G9: 6 | H9: 7 | I9: 8 | J9: 9 | K9: 10 | L9: 11 | M9: 12 | N9: 13 | O9: 14
B10: pence | C10: pence | D10: pence | E10: pence | F10: pence | G10: pence | H10: £ | I10: % | J10: £ | K10: No. | L10: £000 | M10: £000 | O10: %
A11: ENGLAND
A12: BEDFORD | B12: 181.8 | C12: 62.8 | H12: 82863 | I12: 252 | J12: 5203796 | K12: 120413 | L12: 9075.9 | M12: 19919.7 | N12: 395990
A13: Bedford | B13: 300 | C13: 105 | D13: 40.6 | E13: 63.5 | F13: 0.9 | H13: 14675 | I13: 228 | J13: 1540875 | K13: 19131 | L13: 1505.3 | M13: 3471.7 | N13: 64740
A14: Dunstable | B14: 290 | C14: 88 | D14: 20.7 | E14: 66.8 | F14: 0.5 | H14: 9054 | I14: 372 | J14: 796752 | K14: 8447 | L14: 771.4 | M14: 2209.3 | N14: 26480
A15: Luton | B15: 280 | C15: 92 | D15: 28.5 | E15: 63.2 | F15: 0.3 | H15: 34000 | I15: 266 | J15: 3128000 | K15: 41861 | L15: 3702.2 | M15: 8377.4 | N15: 134820
A16: Ampthill | B16: 252 | C16: 86 | D16: 18.8 | E16: 66.9 | F16: 0.3 | H16: 500 | I16: 184 | J16: 43000 | K16: 1310 | L16: 79.8 | M16: 125.8 | N16: 4020 | O16: 32.4
A17: Biggleswade | B17: 274 | C17: 96 | D17: 28.4 | E17: 66.9 | F17: 0.7 | H17: 1338 | I17: 208 | J17: 128448 | K17: 2640 | L17: 137 | M17: 319.9 | N17: 8460 | O17: 13.1
A18: Kempston | B18: 286 | C18: 98 | D18: 30.6 | E18: 66.9 | F18: 0.5 | H18: 1560 | I18: 259 | J18: 152880 | K18: 2905 | L18: 200.5 | M18: 367.3 | N18: 9370 | O18: 9.1
A19: Leighton Buzzard | B19: 264 | C19: 94 | D19: 27 | E19: 66.9 | F19: 0.1 | H19: 2175 | I19: 260 | J19: 204450 | K19: 3706 | L19: 264.5 | M19: 572 | N19: 12060 | O19: 1.3
A20: Sandy | B20: 256 | C20: 92 | D20: 24.4 | E20: 66.9 | F20: 0.7 | H20: 472 | I20: 178 | J20: 43424 | K20: 1292 | L20: 61 | M20: 109 | N20: 3990 | O20: 33.3
A21: Ampthill | B21: 250 | C21: 87 | D21: 19.2 | E21: 66.9 | F21: 0.9 | G21: 89.1 | H21: 3424 | I21: 190 | J21: 304986 | K21: 8585 | L21: 446.2 | M21: 861.9 | N21: 27110 | O21: 26.8
A22: Beford | B22: 250 | C22: 87 | D22: 19.3 | E22: 66.9 | F22: 0.8 | G22: 88.6 | H22: 6250 | I22: 188 | J22: 553552 | K22: 10870 | L22: 591.2 | M22: 1307 | N22: 34460 | O22: 5.7
A23: Biggleswade | B23: 224 | C23: 81 | D23: 12.6 | E23: 66.9 | F23: 1.6 | G23: 85.8 | H23: 2800 | I23: 175 | J23: 240153 | K23: 7725 | L23: 352.9 | M23: 605.9 | N23: 29390 | O23: 48.4
A24: Luton | B24: 261 | C24: 89.3 | D24: 21.9 | E24: 66.9 | F24: 0.5 | G24: 91 | H24: 6655 | I24: 302 | J24: 605668 | K24: 11941 | L24: 963.9 | M24: 1637.6 | N24: 41090 | O24: 9.6
A25: BERKSHIRE | B25: 209 | C25: 81.8 | H25: 71580 | I25: 204 | J25: 5855244 | K25: 116455 | L25: 9678.5 | M25: 16754.9 | N25: 405900 | O25: 2.3
A26: Abingdon | B26: 328 | C26: 124 | D26: 41.4 | E26: 84 | F26: -1.4 | H26: 2400 | I26: 176 | J26: 297600 | K26: 4258 | L26: 300.1 | M26: 578.9 | N26: 14940 | O26: 11.4
A27: Maidenhead | B27: 310 | C27: 114 | D27: 33 | E27: 82.3 | F27: -1.3 | H27: 8460 | I27: 238 | J27: 964440 | K27: 11045 | L27: 1104.6 | M27: 2043.2 | N27: 35850
A28: Newbury | B28: 282 | C28: 114 | D28: 34.3 | E28: 81.8 | F28: -2.1 | H28: 4050 | I28: 180 | J28: 461700 | K28: 6622 | L28: 499.8 | M28: 1004 | N28: 20700
A29: New Windsor | B29: 294 | C29: 111 | D29: 28.7 | E29: 83.5 | F29: -1.2 | H29: 4951 | I29: 200 | J29: 549561 | K29: 7792 | L29: 676.7 | M29: 1177.5 | N29: 28350 | O29: 3.9
A30: Wallingford | B30: 318 | C30: 122 | D30: 38.9 | E30: 84 | F30: -0.9 | H30: 1110 | I30: 231 | J30: 135420 | K30: 1542 | L30: 106.6 | M30: 269.1 | N30: 5100
A31: Wokingham | B31: 312 | C31: 112 | D31: 29 | E31: 84 | F31: -1 | H31: 2810 | I31: 285 | J31: 314720 | K31: 4043 | L31: 387.5 | M31: 693.1 | N31: 12260
A32: Wantage | B32: 294 | C32: 112 | D32: 28 | E32: 84 | H32: 833 | I32: 187 | J32: 93296 | K32: 1776 | L32: 119.5 | M32: 201.5 | N32: 6350 | O32: 28.4
A33: Abingdon | B33: 273 | C33: 104 | D33: 20.5 | E33: 84 | F33: -0.5 | G33: 106 | H33: 4452 | I33: 161 | J33: 471792 | K33: 8489 | L33: 690.2 | M33: 1062.8 | N33: 32510 | O33: 23.2
A34: Bradfield | B34: 268 | C34: 102 | D34: 18.5 | E34: 84 | F34: -0.5 | G34: 104.1 | H34: 5300 | I34: 176 | J34: 551724 | K34: 9035 | L34: 657.8 | M34: 1120.2 | N34: 30180 | O34: 5.2
A35: Cookham | B35: 312 | C35: 121 | D35: 36.9 | E35: 84 | F35: 0.1 | G35: 122.4 | H35: 3100 | I35: 216 | J35: 379414 | K35: 5113 | L35: 511.1 | M35: 768.1 | N35: 17110
A36: Easthampstead | B36: 281 | C36: 108 | D36: 24 | E36: 84 | G36: 109.3 | H36: 9303 | I36: 228 | J36: 1016691 | K36: 13062 | L36: 1151.4 | M36: 2108.3 | N36: 47500
A37: Farringdon | B37: 260 | C37: 100 | D37: 15.7 | E37: 84 | F37: 0.4 | G37: 102.1 | H37: 1520 | I37: 165 | J37: 155223 | K37: 3730 | L37: 190.7 | M37: 322.6 | N37: 14420 | O37: 41.3
A38: Hungerford | B38: 271 | C38: 108 | D38: 23.1 | E38: 84 | F38: 0.9 | G38: 111.2 | H38: 1025 | I38: 184 | J38: 113992 | K38: 3097 | L38: 161.3 | M38: 254 | N38: 10270 | O38: 43.8
A39: Newbury | B39: 263 | C39: 104 | D39: 20.6 | E39: 84 | F39: -0.6 | G39: 106.1 | H39: 3589 | I39: 173 | J39: 380614 | K39: 5533 | L39: 386.3 | M39: 880 | N39: 21650 | O39: 6.1
A40: Wallingford | B40: 286 | C40: 104 | D40: 19 | E40: 84 | F40: 0.9 | G40: 107.6 | H40: 2189 | I40: 177 | J40: 235556 | K40: 5173 | L40: 337.7 | M40: 521.9 | N40: 19770 | O40: 34.9
A41: Wantage | B41: 261 | C41: 104 | D41: 20.9 | E41: 84 | F41: -0.9 | G41: 104.8 | H41: 2889 | I41: 138 | J41: 302787 | K41: 4769 | L41: 272.2 | M41: 558.3 | N41: 17050 | O41: 5.3
A42: Windsor | B42: 273 | C42: 100 | D42: 16.6 | E42: 84 | F42: -0.6 | G42: 102.4 | H42: 3144 | I42: 208 | J42: 322066 | K42: 4402 | L42: 476.1 | M42: 776.8 | N42: 15940
A43: Wokingham | B43: 270 | C43: 103 | D43: 18.8 | E43: 84 | F43: 0.2 | G43: 105.1 | H43: 10400 | I43: 241 | J43: 1092559 | K43: 16974 | L43: 1648.8 | M43: 2414.7 | N43: 55950 | O43: 0.2
...

Sheet RVs_Cty_62_Checked
A1: Local Authority | B1: Domestic
B2: £1-£100(1) | D2: £101-£200(2) | F2: Over £200(3) | H2: Shops (4) | J2: Offices | L2: Other Commerical(6) | N2: Industrial(7) | P2: Crown(8) | Q2: Other(9) | R2: Total(10)
B3: Nos. | C3: Value(£) | D3: Nos. | E3: Value(£) | F3: Nos. | G3: Value(£) | H3: Nos. | I3: Value£ | J3: Nos. | K3: Value(£) | L3: Nos. | M3: Value(£) | N3: Nos. | O3: Value(£) | P3: Value(£) | Q3: Value(£) | R3: Value(£)
A4: ENGLAND
A5: Bedford | B5: 94395 | C5: 5995951 | D5: 23474 | E5: 2801957 | F5: 669 | G5: 165895 | H5: 4544 | I5: 2026133 | J5: 892 | K5: 222767 | L5: 12011 | M5: 1111506 | N5: 890 | O5: 4956717 | P5: 305242 | Q5: 2333528 | R5: 19919697
A6: Berkshire | B6: 83883 | C6: 5411141 | D6: 24584 | E6: 3129517 | F6: 3050 | G6: 860872 | H6: 3739 | I6: 1319046 | J6: 636 | K6: 185437 | L6: 11562 | M6: 1010592 | N6: 464 | O6: 2013695 | P6: 776706 | Q6: 2047869 | R6: 16754875
A7: Buckingham | B7: 102530 | C7: 6796285 | D7: 40009 | E7: 5152642 | F7: 5992 | G7: 1681620 | H7: 5147 | I7: 2226308 | J7: 903 | K7: 328388 | L7: 14654 | M7: 1828457 | N7: 1354 | O7: 5615628 | P7: 367820 | Q7: 3026046 | R7: 27063194
A8: Cambridge | B8: 46726 | C8: 2404320 | D8: 8230 | E8: 1068055 | F8: 1187 | G8: 297774 | H8: 2013 | I8: 932272 | J8: 401 | K8: 184723 | L8: 4969 | M8: 486667 | N8: 274 | O8: 807693 | P8: 177294 | Q8: 1404288 | R8: 7763086
A9: Chester | B9: 256314 | C9: 14094145 | D9: 43814 | E9: 5678392 | F9: 4214 | G9: 1085954 | H9: 12659 | I9: 2578173 | J9: 1562 | K9: 310200 | L9: 23702 | M9: 1390582 | N9: 1653 | O9: 7097824 | P9: 321987 | Q9: 4796295 | R9: 37353552
A10: Cornwall | B10: 98374 | C10: 4136909 | D10: 7446 | E10: 953733 | F10: 590 | G10: 157404 | H10: 6045 | I10: 928449 | J10: 928 | K10: 83639 | L10: 14053 | M10: 1135069 | N10: 494 | O10: 587643 | P10: 190016 | Q10: 1981759 | R10: 10154621
A11: Cumberland | B11: 61003 | C11: 2626887 | D11: 2056 | E11: 247805 | F11: 80 | G11: 19005 | H11: 2946 | I11: 450563 | J11: 404 | K11: 39998 | L11: 7848 | M11: 370195 | N11: 264 | O11: 867835 | P11: 347680 | Q11: 1203004 | R11: 6172972
A12: Derbyshire | B12: 230298 | C12: 10785102 | D12: 8199 | E12: 1024212 | F12: 526 | G12: 133080 | H12: 9285 | I12: 1424686 | J12: 1008 | K12: 148121 | L12: 20521 | M12: 1060641 | N12: 1344 | O12: 3972681 | P12: 182270 | Q12: 4835440 | R12: 23566233
A13: Devon | B13: 135252 | C13: 7059758 | D13: 23419 | E13: 2996185 | F13: 2104 | G13: 529044 | H13: 8918 | I13: 1772755 | J13: 1310 | K13: 123053 | L13: 18111 | M13: 2104264 | N13: 780 | O13: 957112 | P13: 250390 | Q13: 2912159 | R13: 18704720
A14: Dorset | B14: 72986 | C14: 4220148 | D14: 18494 | E14: 2383755 | F14: 2473 | G14: 680434 | H14: 4304 | I14: 1097889 | J14: 606 | K14: 121308 | L14: 8443 | M14: 826112 | N14: 469 | O14: 836531 | P14: 264055 | Q14: 1715802 | R14: 12146034
A15: Durham | B15: 294596 | C15: 12415350 | D15: 4173 | E15: 505704 | F15: 148 | G15: 37709 | H15: 10089 | I15: 1768081 | J15: 1321 | K15: 222969 | L15: 32932 | M15: 110744 | N15: 882 | O15: 6531299 | P15: 246352 | Q15: 5402078 | R15: 28236986
A16: Essex | B16: 466003 | C16: 30964912 | D16: 110911 | E16: 13621243 | F16: 3806 | G16: 938051 | H16: 20980 | I16: 7674626 | J16: 2872 | K16: 895153 | L16: 48602 | M16: 4590577 | N16: 2691 | O16: 15972553 | P16: 695523 | Q16: 9756874 | R16: 85109512
... A53: Yorkshire, West Riding | B53: 527584 | C53: 20401304 | D53: 12998 | E53: 1644913 | F53: 1092 | G53: 282938 | H53: 22771 | I53: 2357561 | J53: 2670 | K53: 289770 | L53: 55646 | M53: 2299475 | N53: 4335 | O53: 6549402 | P53: 481777 | Q53: 9017865 | R53: 43325005

Sheet RVs_Districts_62_Checked
B1: Local Authority | C1: Domestic Nos. £1-£100(1) | D1: Domestic Value(£) £1-£100(1) | E1: Domestic Nos. £101-£200(2) | F1: Domestic Value(£) £101-£200(2) | G1: Domestic Nos. Over £200(3) | H1: Domestic Value(£) Over £200(3) | I1: Nos. Shops (4) | J1: Value£ Shops (4) | K1: Nos. Shops (4) | L1: Value(£) Shops (4) | M1: Nos. Other Commerical(6) | N1: Value(£) Other Commerical(6) | O1: Nos. Industrial(7) | P1: Value(£) Industrial(7) | Q1: Value(£) Crown(8) | R1: Value(£)Other(9) | S1: Value(£) Total(10) | T1: Domestic heriditaments total | U1: Domestic heriditaments ratio | V1: Type of authority | W1: Concat Name | X1: 1961 Lookup | Y1: 1971 Lookup | Z1: 81_cty
A2: City of London | B2: City of London | C2: 521 | D2: 30955 | E2: 492 | F2: 68621 | G2: 180 | H2: 71777 | I2: 1609 | J2: 2159501 | K2: 10939 | L2: 34130573 | M2: 2632 | N2: 3572588 | O2: 101 | P2: 1254849 | Q2: 880766 | R2: 159688 | S2: 43766318 | T2: =SUM(D2+F2+H2) -> 171353 | U2: =T2/S2 -> 0.0039151797 | W2: City of London (County Corporate) LCC | X2: =INDEX(Lookup!$A$2:$A$1349, MATCH(W2, Lookup!$B$2:$B$1349,0)) -> J04000321 | Y2: =INDEX(Lookup!$F$2:$F$1349, MATCH(W2, Lookup!$B$2:$B$1349,0)) -> e140370 | Z2: =INDEX(Lookup!$C$2:$C$1300, MATCH(X2, Lookup!$A$2:$A$1300,0)) -> Inner London
A3: Battersea | B3: Battersea | C3: 21091 | D3: 1430988 | E3: 6695 | F3: 886364 | G3: 405 | H3: 90799 | I3: 1649 | J3: 460965 | K3: 205 | L3: 44039 | M3: 1644 | N3: 390391 | O3: 217 | P3: 712069 | Q3: 32587 | R3: 605786 | S3: 4653988 | T3: =SUM(D3+F3+H3) -> 2408151 | U3: =T3/S3 -> 0.51743816 | V3: MB | W3: =_xlfn.CONCAT(B3," ",V3) -> Battersea MB | X3: =INDEX(Lookup!$A$2:$A$1349, MATCH(W3, Lookup!$B$2:$B$1349,0)) -> J04000102 | Y3: =INDEX(Lookup!$F$2:$F$1349, MATCH(W3, Lookup!$B$2:$B$1349,0)) -> e140408 | Z3: =INDEX(Lookup!$C$2:$C$1300, MATCH(X3, Lookup!$A$2:$A$1300,0)) -> Inner London
A4: Bermondsey | B4: Bermondsey | C4: 14876 | D4: 881394 | E4: 302 | F4: 35783 | G4: 5 | H4: 1218 | I4: 954 | J4: 191855 | K4: 370 | L4: 159355 | M4: 1402 | N4: 1418735 | O4: 362 | P4: 1046104 | Q4: 75645 | R4: 278577 | S4: 4088666 | T4: =SUM(D4+F4+H4) -> 918395 | U4: =T4/S4 -> 0.22461972 | V4: MB | W4: =_xlfn.CONCAT(B4," ",V4) -> Bermondsey MB | X4: =INDEX(Lookup!$A$2:$A$1349, MATCH(W4, Lookup!$B$2:$B$1349,0)) -> J04000127 | Y4: =INDEX(Lookup!$F$2:$F$1349, MATCH(W4, Lookup!$B$2:$B$1349,0)) -> e140402 | Z4: =INDEX(Lookup!$C$2:$C$1300, MATCH(X4, Lookup!$A$2:$A$1300,0)) -> Inner London
A5: Bethnal Green | B5: Bethnal Green | C5: 12261 | D5: 825291 | E5: 2419 | F5: 261791 | G5: 7 | H5: 1694 | I5: 984 | J5: 229247 | K5: 58 | L5: 14364 | M5: 1110 | N5: 266681 | O5: 691 | P5: 576420 | Q5: 15354 | R5: 218554 | S5: 2409396 | T5: =SUM(D5+F5+H5) -> 1088776 | U5: =T5/S5 -> 0.45188753 | V5: MB | W5: =_xlfn.CONCAT(B5," ",V5) -> Bethnal Green MB | X5: =INDEX(Lookup!$A$2:$A$1349, MATCH(W5, Lookup!$B$2:$B$1349,0)) -> J04000130 | Y5: =INDEX(Lookup!$F$2:$F$1349, MATCH(W5, Lookup!$B$2:$B$1349,0)) -> e140405 | Z5: =INDEX(Lookup!$C$2:$C$1300, MATCH(X5, Lookup!$A$2:$A$1300,0)) -> Inner London
A6: Camberwell | B6: Camberwell | C6: 31924 | D6: 2355689 | E6: 12981 | F6: 1635281 | G6: 756 | H6: 190258 | I6: 2807 | J6: 848595 | K6: 240 | L6: 70753 | M6: 3763 | N6: 598370 | O6: 480 | P6: 895262 | Q6: 50783 | R6: 624746 | S6: 7269737 | T6: =SUM(D6+F6+H6) -> 4181228 | U6: =T6/S6 -> 0.57515533 | V6: MB | W6: =_xlfn.CONCAT(B6," ",V6) -> Camberwell MB | X6: =INDEX(Lookup!$A$2:$A$1349, MATCH(W6, Lookup!$B$2:$B$1349,0)) -> J04000254 | Y6: =INDEX(Lookup!$F$2:$F$1349, MATCH(W6, Lookup!$B$2:$B$1349,0)) -> e140402 | Z6: =INDEX(Lookup!$C$2:$C$1300, MATCH(X6, Lookup!$A$2:$A$1300,0)) -> Inner London
A7: Chelsea | B7: Chelsea | C7: 3047 | D7: 182556 | E7: 5158 | F7: 759914 | G7: 8815 | H7: 3418873 | I7: 864 | J7: 900311 | K7: 274 | L7: 251374 | M7: 1524 | N7: 817912 | O7: 60 | P7: 150890 | Q7: 71385 | R7: 431530 | S7: 6984745 | T7: =SUM(D7+F7+H7) -> 4361343 | U7: =T7/S7 -> 0.62440977 | V7: MB | W7: =_xlfn.CONCAT(B7," ",V7) -> Chelsea MB | X7: =INDEX(Lookup!$A$2:$A$1349, MATCH(W7, Lookup!$B$2:$B$1349,0)) -> J04000290 | Y7: =INDEX(Lookup!$F$2:$F$1349, MATCH(W7, Lookup!$B$2:$B$1349,0)) -> e140392 | Z7: =INDEX(Lookup!$C$2:$C$1300, MATCH(X7, Lookup!$A$2:$A$1300,0)) -> Inner London
A8: Deptford | B8: Deptford | C8: 14819 | D8: 985657 | E8: 3471 | F8: 432051 | G8: 112 | H8: 24360 | I8: 1098 | J8: 310067 | K8: 93 | L8: 14422 | M8: 1626 | N8: 244613 | O8: 141 | P8: 539827 | Q8: 9775 | R8: 270398 | S8: 2831170 | T8: =SUM(D8+F8+H8) -> 1442068 | U8: =T8/S8 -> 0.50935408 | V8: MB | W8: =_xlfn.CONCAT(B8," ",V8) -> Deptford MB | X8: =INDEX(Lookup!$A$2:$A$1349, MATCH(W8, Lookup!$B$2:$B$1349,0)) -> J04000399 | Y8: =INDEX(Lookup!$F$2:$F$1349, MATCH(W8, Lookup!$B$2:$B$1349,0)) -> e140397 | Z8: =INDEX(Lookup!$C$2:$C$1300, MATCH(X8, Lookup!$A$2:$A$1300,0)) -> Inner London
A9: Finsbury | B9: Finsbury | C9: 4355 | D9: 262712 | E9: 4371 | F9: 619516 | G9: 298 | H9: 73366 | I9: 951 | J9: 632624 | K9: 1113 | L9: 2633238 | M9: 2579 | N9: 2680231 | O9: 103 | P9: 1273025 | Q9: 380542 | R9: 471288 | S9: 9026542 | T9: =SUM(D9+F9+H9) -> 955594 | U9: =T9/S9 -> 0.1058649 | V9: MB | W9: =_xlfn.CONCAT(B9," ",V9) -> Finsbury MB | X9: =INDEX(Lookup!$A$2:$A$1349, MATCH(W9, Lookup!$B$2:$B$1349,0)) -> J04000504 | Y9: =INDEX(Lookup!$F$2:$F$1349, MATCH(W9, Lookup!$B$2:$B$1349,0)) -> e140390 | Z9: =INDEX(Lookup!$C$2:$C$1300, MATCH(X9, Lookup!$A$2:$A$1300,0)) -> Inner London
A10: Fulham | B10: Fulham | C10: 14286 | D10: 1102886 | E10: 14673 | F10: 1887633 | G10: 1310 | H10: 345931 | I10: 1917 | J10: 504944 | K10: 193 | L10: 156662 | M10: 1424 | N10: 495663 | O10: 209 | P10: 576694 | Q10: 112679 | R10: 564904 | S10: 5747996 | T10: =SUM(D10+F10+H10) -> 3336450 | U10: =T10/S10 -> 0.58045447 | V10: MB | W10: =_xlfn.CONCAT(B10," ",V10) -> Fulham MB | X10: =INDEX(Lookup!$A$2:$A$1349, MATCH(W10, Lookup!$B$2:$B$1349,0)) -> J04000521 | Y10: =INDEX(Lookup!$F$2:$F$1349, MATCH(W10, Lookup!$B$2:$B$1349,0)) -> e140384 | Z10: =INDEX(Lookup!$C$2:$C$1300, MATCH(X10, Lookup!$A$2:$A$1300,0)) -> Inner London
A11: Greenwich | B11: Greenwich | C11: 18986 | D11: 1216827 | E11: 5254 | F11: 672408 | G11: 397 | H11: 93830 | I11: 1005 | J11: 146188 | K11: 106 | L11: 18928 | M11: 2193 | N11: 465856 | O11: 180 | P11: 1316830 | Q11: 139121 | R11: 904857 | S11: 4974845 | T11: =SUM(D11+F11+H11) -> 1983065 | U11: =T11/S11 -> 0.39861845 | V11: MB | W11: =_xlfn.CONCAT(B11," ",V11) -> Greenwich MB | X11: =INDEX(Lookup!$A$2:$A$1349, MATCH(W11, Lookup!$B$2:$B$1349,0)) -> J04000553 | Y11: =INDEX(Lookup!$F$2:$F$1349, MATCH(W11, Lookup!$B$2:$B$1349,0)) -> e140381 | Z11: =INDEX(Lookup!$C$2:$C$1300, MATCH(X11, Lookup!$A$2:$A$1300,0)) -> Inner London
A12: Hackney | B12: Hackney | C12: 21631 | D12: 1678613 | E12: 18720 | F12: 2454814 | G12: 753 | H12: 170425 | I12: 2726 | J12: 846994 | K12: 224 | L12: 80811 | M12: 3348 | N12: 600339 | O12: 1107 | P12: 1569788 | Q12: 48046 | R12: 678255 | S12: 8128085 | T12: =SUM(D12+F12+H12) -> 4303852 | U12: =T12/S12 -> 0.52950381 | V12: MB | W12: =_xlfn.CONCAT(B12," ",V12) -> Hackney MB | X12: =INDEX(Lookup!$A$2:$A$1349, MATCH(W12, Lookup!$B$2:$B$1349,0)) -> J04000560 | Y12: =INDEX(Lookup!$F$2:$F$1349, MATCH(W12, Lookup!$B$2:$B$1349,0)) -> e140382 | Z12: =INDEX(Lookup!$C$2:$C$1300, MATCH(X12, Lookup!$A$2:$A$1300,0)) -> Inner London
A13: Hammersmith | B13: Hammersmith | C13: 11284 | D13: 879768 | E13: 12815 | F13: 1707302 | G13: 1149 | H13: 296839 | I13: 1725 | J13: 913223 | K13: 263 | L13: 482021 | M13: 1534 | N13: 628238 | O13: 250 | P13: 1514683 | Q13: 127038 | R13: 1139569 | S13: 7688681 | T13: =SUM(D13+F13+H13) -> 2883909 | U13: =T13/S13 -> 0.37508501 | V13: MB | W13: =_xlfn.CONCAT(B13," ",V13) -> Hammersmith MB | X13: =INDEX(Lookup!$A$2:$A$1349, MATCH(W13, Lookup!$B$2:$B$1349,0)) -> J04000572 | Y13: =INDEX(Lookup!$F$2:$F$1349, MATCH(W13, Lookup!$B$2:$B$1349,0)) -> e140384 | Z13: =INDEX(Lookup!$C$2:$C$1300, MATCH(X13, Lookup!$A$2:$A$1300,0)) -> Inner London
A14: Hampstead | B14: Hampstead | C14: 1769 | D14: 125011 | E14: 12211 | F14: 1864792 | G14: 10606 | H14: 3401215 | I14: 1509 | J14: 806015 | K14: 213 | L14: 82191 | M14: 3415 | N14: 701408 | O14: 24 | P14: 76495 | Q14: 4851 | R14: 453822 | S14: 7559461 | T14: =SUM(D14+F14+H14) -> 5391018 | U14: =T14/S14 -> 0.71314846 | V14: MB | W14: =_xlfn.CONCAT(B14," ",V14) -> Hampstead MB | X14: =INDEX(Lookup!$A$2:$A$1349, MATCH(W14, Lookup!$B$2:$B$1349,0)) -> J04000573 | Y14: =INDEX(Lookup!$F$2:$F$1349, MATCH(W14, Lookup!$B$2:$B$1349,0)) -> e140376 | Z14: =INDEX(Lookup!$C$2:$C$1300, MATCH(X14, Lookup!$A$2:$A$1300,0)) -> Inner London
... A30: Woolwich | B30: Woolwich | C30: 35894 | D30: 2644842 | E30: 9426 | F30: 1123459 | G30: 138 | H30: 32562 | I30: 1654 | J30: 873344 | K30: 212 | L30: 109729 | M30: 3329 | N30: 434119 | O30: 129 | P30: 953561 | Q30: 317484 | R30: 1075469 | S30: 7564569 | T30: =SUM(D30+F30+H30) -> 3800863 | U30: =T30/S30 -> 0.50245599 | V30: MB | W30: =_xlfn.CONCAT(B30," ",V30) -> Woolwich MB | X30: =INDEX(Lookup!$A$2:$A$1349, MATCH(W30, Lookup!$B$2:$B$1349,0)) -> J04001449 | Y30: =INDEX(Lookup!$F$2:$F$1349, MATCH(W30, Lookup!$B$2:$B$1349,0)) -> e140381 | Z30: =INDEX(Lookup!$C$2:$C$1300, MATCH(X30, Lookup!$A$2:$A$1300,0)) -> Inner London
A31: ENGLAND | B31: ENGLAND | W31: =_xlfn.CONCAT(B31," ",V31) -> ENGLAND | X31: =INDEX(Lookup!$A$2:$A$1349, MATCH(W31, Lookup!$B$2:$B$1349,0)) -> #N/A | Y31: =INDEX(Lookup!$F$2:$F$1349, MATCH(W31, Lookup!$B$2:$B$1349,0)) -> #N/A | Z31: =INDEX(Lookup!$C$2:$C$1300, MATCH(X31, Lookup!$A$2:$A$1300,0)) -> #N/A
A32: County Boroughs-- | B32: County Boroughs-- | W32: =_xlfn.CONCAT(B32," ",V32) -> County Boroughs-- | X32: =INDEX(Lookup!$A$2:$A$1349, MATCH(W32, Lookup!$B$2:$B$1349,0)) -> #N/A | Y32: =INDEX(Lookup!$F$2:$F$1349, MATCH(W32, Lookup!$B$2:$B$1349,0)) -> #N/A | Z32: =INDEX(Lookup!$C$2:$C$1300, MATCH(X32, Lookup!$A$2:$A$1300,0)) -> #N/A
A33: Barnsley | B33: Barnsley | C33: 23444 | D33: 875640 | E33: 216 | F33: 26155 | G33: 4 | H33: 932 | I33: 1063 | J33: 416081 | K33: 163 | L33: 27086 | M33: 2402 | N33: 162525 | O33: 118 | P33: 198882 | Q33: 16607 | R33: 411708 | S33: 2135616 | T33: =SUM(D33+F33+H33) -> 902727 | U33: =T33/S33 -> 0.42270099 | V33: CB | W33: =_xlfn.CONCAT(B33," ",V33) -> Barnsley CB | X33: =INDEX(Lookup!$A$2:$A$1349, MATCH(W33, Lookup!$B$2:$B$1349,0)) -> J04000087 | Y33: =INDEX(Lookup!$F$2:$F$1349, MATCH(W33, Lookup!$B$2:$B$1349,0)) -> e461199 | Z33: =INDEX(Lookup!$C$2:$C$1300, MATCH(X33, Lookup!$A$2:$A$1300,0)) -> South Yorkshire
A34: Barrow-in-Furness | B34: Barrow-in-Furness | C34: 20299 | D34: 961141 | E34: 356 | F34: 41398 | G34: 1 | H34: 202 | I34: 1079 | J34: 174073 | K34: 132 | L34: 16816 | M34: 1754 | N34: 77607 | O34: 59 | P34: 514594 | Q34: 20343 | R34: 289138 | S34: 2095312 | T34: =SUM(D34+F34+H34) -> 1002741 | U34: =T34/S34 -> 0.47856405 | V34: CB | W34: =_xlfn.CONCAT(B34," ",V34) -> Barrow-in-Furness CB | X34: =INDEX(Lookup!$A$2:$A$1349, MATCH(W34, Lookup!$B$2:$B$1349,0)) -> J04000092 | Y34: =INDEX(Lookup!$F$2:$F$1349, MATCH(W34, Lookup!$B$2:$B$1349,0)) -> e200560 | Z34: =INDEX(Lookup!$C$2:$C$1300, MATCH(X34, Lookup!$A$2:$A$1300,0)) -> Cumbria
A35: Bath | B35: Bath, CITY OF | C35: 21135 | D35: 1157161 | E35: 4007 | F35: 514717 | G35: 212 | H35: 51026 | I35: 1448 | J35: 481372 | K35: 301 | L35: 40881 | M35: 3151 | N35: 196374 | O35: 121 | P35: 174381 | Q35: 46812 | R35: 336580 | S35: 2999304 | T35: =SUM(D35+F35+H35) -> 1722904 | U35: =T35/S35 -> 0.5744346 | V35: CB | W35: =_xlfn.CONCAT(B35," ",V35) -> Bath, CITY OF CB | X35: =INDEX(Lookup!$A$2:$A$1349, MATCH(W35, Lookup!$B$2:$B$1349,0)) -> J04000099 | Y35: =INDEX(Lookup!$F$2:$F$1349, MATCH(W35, Lookup!$B$2:$B$1349,0)) -> e320902 | Z35: =INDEX(Lookup!$C$2:$C$1300, MATCH(X35, Lookup!$A$2:$A$1300,0)) -> Avon
A36: Birkenhead | B36: Birkenhead | C36: 37106 | D36: 2048259 | E36: 3840 | F36: 478440 | G36: 232 | H36: 60836 | I36: 2427 | J36: 494646 | K36: 380 | L36: 55099 | M36: 2845 | N36: 228978 | O36: 225 | P36: 623009 | Q36: 23511 | R36: 648336 | S36: 4661114 | T36: =SUM(D36+F36+H36) -> 2587535 | U36: =T36/S36 -> 0.55513231 | V36: CB | W36: =_xlfn.CONCAT(B36," ",V36) -> Birkenhead CB | X36: =INDEX(Lookup!$A$2:$A$1349, MATCH(W36, Lookup!$B$2:$B$1349,0)) -> J04000149 | Y36: =INDEX(Lookup!$F$2:$F$1349, MATCH(W36, Lookup!$B$2:$B$1349,0)) -> e050068 | Z36: =INDEX(Lookup!$C$2:$C$1300, MATCH(X36, Lookup!$A$2:$A$1300,0)) -> Merseyside
A37: Birmingham | B37: Birmingham, city of | C37: 298127 | D37: 15620023 | E37: 17713 | F37: 2210280 | G37: 1426 | H37: 335902 | I37: 16927 | J37: 6237203 | K37: 4075 | L37: 2322500 | M37: 23294 | N37: 4322194 | O37: 4850 | P37: 12538511 | Q37: 520025 | R37: 5476681 | S37: 49603319 | T37: =SUM(D37+F37+H37) -> 18166205 | U37: =T37/S37 -> 0.36622963 | V37: CB | W37: =_xlfn.CONCAT(B37," ",V37) -> Birmingham, city of CB | X37: =INDEX(Lookup!$A$2:$A$1349, MATCH(W37, Lookup!$B$2:$B$1349,0)) -> J04000150 | Y37: =INDEX(Lookup!$F$2:$F$1349, MATCH(W37, Lookup!$B$2:$B$1349,0)) -> e391064 | Z37: =INDEX(Lookup!$C$2:$C$1300, MATCH(X37, Lookup!$A$2:$A$1300,0)) -> West Midlands
A38: Blackburn | B38: Blackburn | C38: 36202 | D38: 1312575 | E38: 618 | F38: 80297 | G38: 44 | H38: 10751 | I38: 2732 | J38: 376537 | K38: 362 | L38: 42817 | M38: 5916 | N38: 224512 | O38: 444 | P38: 648539 | Q38: 35319 | R38: 360615 | S38: 3091962 | T38: =SUM(D38+F38+H38) -> 1403623 | U38: =T38/S38 -> 0.45395868 | V38: CB | W38: =_xlfn.CONCAT(B38," ",V38) -> Blackburn CB | X38: =INDEX(Lookup!$A$2:$A$1349, MATCH(W38, Lookup!$B$2:$B$1349,0)) -> J04000155 | Y38: =INDEX(Lookup!$F$2:$F$1349, MATCH(W38, Lookup!$B$2:$B$1349,0)) -> e200561 | Z38: =INDEX(Lookup!$C$2:$C$1300, MATCH(X38, Lookup!$A$2:$A$1300,0)) -> Lancashire
A39: Blackpool | B39: Blackpool | C39: 34752 | D39: 2485935 | E39: 12629 | F39: 1520254 | G39: 205 | H39: 49456 | I39: 3479 | J39: 1300317 | K39: 590 | L39: 111950 | M39: 7766 | N39: 1135972 | O39: 369 | P39: 251552 | Q39: 41338 | R39: 915197 | S39: 7811971 | T39: =SUM(D39+F39+H39) -> 4055645 | U39: =T39/S39 -> 0.51915771 | V39: CB | W39: =_xlfn.CONCAT(B39," ",V39) -> Blackpool CB | X39: =INDEX(Lookup!$A$2:$A$1349, MATCH(W39, Lookup!$B$2:$B$1349,0)) -> J04000157 | Y39: =INDEX(Lookup!$F$2:$F$1349, MATCH(W39, Lookup!$B$2:$B$1349,0)) -> e200562 | Z39: =INDEX(Lookup!$C$2:$C$1300, MATCH(X39, Lookup!$A$2:$A$1300,0)) -> Lancashire
A40: Bolton | B40: Bolton | C40: 52745 | D40: 2142426 | E40: 1612 | F40: 209031 | G40: 127 | H40: 30445 | I40: 3336 | J40: 651397 | K40: 470 | L40: 68930 | M40: 5327 | N40: 413499 | O40: 543 | P40: 1074152 | Q40: 37408 | R40: 689293 | S40: 5316581 | T40: =SUM(D40+F40+H40) -> 2381902 | U40: =T40/S40 -> 0.44801386 | V40: CB | W40: =_xlfn.CONCAT(B40," ",V40) -> Bolton CB | X40: =INDEX(Lookup!$A$2:$A$1349, MATCH(W40, Lookup!$B$2:$B$1349,0)) -> J04000173 | Y40: =INDEX(Lookup!$F$2:$F$1349, MATCH(W40, Lookup!$B$2:$B$1349,0)) -> e200563 | Z40: =INDEX(Lookup!$C$2:$C$1300, MATCH(X40, Lookup!$A$2:$A$1300,0)) -> Greater Manchester
A41: Bootle | B41: Bootle | C41: 21009 | D41: 1130490 | E41: 223 | F41: 24807 | G41: 3 | H41: 750 | I41: 920 | J41: 139191 | K41: 221 | L41: 52449 | M41: 1316 | N41: 392272 | O41: 164 | P41: 534430 | Q41: 8452 | R41: 447480 | S41: 2730321 | T41: =SUM(D41+F41+H41) -> 1156047 | U41: =T41/S41 -> 0.42341065 | V41: CB | W41: =_xlfn.CONCAT(B41," ",V41) -> Bootle CB | X41: =INDEX(Lookup!$A$2:$A$1349, MATCH(W41, Lookup!$B$2:$B$1349,0)) -> J04000174 | Y41: =INDEX(Lookup!$F$2:$F$1349, MATCH(W41, Lookup!$B$2:$B$1349,0)) -> e200564 | Z41: =INDEX(Lookup!$C$2:$C$1300, MATCH(X41, Lookup!$A$2:$A$1300,0)) -> Merseyside
A42: Bournemouth | B42: Bournemouth | C42: 22105 | D42: 1811831 | E42: 22142 | F42: 2945582 | G42: 3877 | H42: 805974 | I42: 3225 | J42: 1605835 | K42: 817 | L42: 247813 | M42: 5767 | N42: 1116669 | O42: 161 | P42: 222387 | Q42: 58966 | R42: 765817 | S42: 9580874 | T42: =SUM(D42+F42+H42) -> 5563387 | U42: =T42/S42 -> 0.58067636 | V42: CB | W42: =_xlfn.CONCAT(B42," ",V42) -> Bournemouth CB | X42: =INDEX(Lookup!$A$2:$A$1349, MATCH(W42, Lookup!$B$2:$B$1349,0)) -> J04000179 | Y42: =INDEX(Lookup!$F$2:$F$1349, MATCH(W42, Lookup!$B$2:$B$1349,0)) -> e150411 | Z42: =INDEX(Lookup!$C$2:$C$1300, MATCH(X42, Lookup!$A$2:$A$1300,0)) -> Dorset
A43: Bradford | B43: Bradford, city of | C43: 98258 | D43: 3899162 | E43: 1111 | F43: 138110 | G43: 33 | H43: 7458 | I43: 5256 | J43: 1148744 | K43: 1302 | L43: 303018 | M43: 11690 | N43: 684441 | O43: 1678 | P43: 1810134 | Q43: 100276 | R43: 1096481 | S43: 9187824 | T43: =SUM(D43+F43+H43) -> 4044730 | U43: =T43/S43 -> 0.4402272 | V43: CB | W43: =_xlfn.CONCAT(B43," ",V43) -> Bradford, city of CB | X43: =INDEX(Lookup!$A$2:$A$1349, MATCH(W43, Lookup!$B$2:$B$1349,0)) -> J04000187 | Y43: =INDEX(Lookup!$F$2:$F$1349, MATCH(W43, Lookup!$B$2:$B$1349,0)) -> e461200 | Z43: =INDEX(Lookup!$C$2:$C$1300, MATCH(X43, Lookup!$A$2:$A$1300,0)) -> West Yorkshire
A44: Brighton | B44: Brighton | C44: 20233 | D44: 1649094 | E44: 29417 | F44: 3937245 | G44: 4150 | H44: 1081353 | I44: 3382 | J44: 1715810 | K44: 819 | L44: 271582 | M44: 4528 | N44: 722154 | O44: 340 | P44: 540628 | Q44: 69459 | R44: 833888 | S44: 10821213 | T44: =SUM(D44+F44+H44) -> 6667692 | U44: =T44/S44 -> 0.61616863 | V44: CB | W44: =_xlfn.CONCAT(B44," ",V44) -> Brighton CB | X44: =INDEX(Lookup!$A$2:$A$1349, MATCH(W44, Lookup!$B$2:$B$1349,0)) -> J04000212 | Y44: =INDEX(Lookup!$F$2:$F$1349, MATCH(W44, Lookup!$B$2:$B$1349,0)) -> e371029 | Z44: =INDEX(Lookup!$C$2:$C$1300, MATCH(X44, Lookup!$A$2:$A$1300,0)) -> East Sussex
... A62: Gateshead | B62: Gateshead | C62: 33143 | D62: 1306395 | E62: 537 | F62: 62939 | G62: 6 | H62: 1452 | I62: 1489 | J62: 229802 | K62: 155 | L62: 25178 | M62: 1858 | N62: 257658 | O62: 195 | P62: 840132 | Q62: 22766 | R62: 453979 | S62: 3200301 | T62: =SUM(D62+F62+H62) -> 1370786 | U62: =T62/S62 -> 0.42833034 | V62: CB | W62: =_xlfn.CONCAT(B62," ",V62) -> Gateshead CB | X62: =INDEX(Lookup!$A$2:$A$1349, MATCH(W62, Lookup!$B$2:$B$1349,0)) -> J04000528 | Y62: =INDEX(Lookup!$F$2:$F$1349, MATCH(W62, Lookup!$B$2:$B$1349,0)) -> e110261 | Z62: =INDEX(Lookup!$C$2:$C$1300, MATCH(X62, Lookup!$A$2:$A$1300,0)) -> Tyne And Wear
A63: ENGLAND | B63: ENGLAND | V63: CB | W63: =_xlfn.CONCAT(B63," ",V63) -> ENGLAND CB | X63: =INDEX(Lookup!$A$2:$A$1349, MATCH(W63, Lookup!$B$2:$B$1349,0)) -> #N/A | Y63: =INDEX(Lookup!$F$2:$F$1349, MATCH(W63, Lookup!$B$2:$B$1349,0)) -> #N/A | Z63: =INDEX(Lookup!$C$2:$C$1300, MATCH(X63, Lookup!$A$2:$A$1300,0)) -> #N/A
A64: County Boroughs--contd. | B64: County Boroughs--contd. | V64: CB | W64: =_xlfn.CONCAT(B64," ",V64) -> County Boroughs--contd. CB | X64: =INDEX(Lookup!$A$2:$A$1349, MATCH(W64, Lookup!$B$2:$B$1349,0)) -> #N/A | Y64: =INDEX(Lookup!$F$2:$F$1349, MATCH(W64, Lookup!$B$2:$B$1349,0)) -> #N/A | Z64: =INDEX(Lookup!$C$2:$C$1300, MATCH(X64, Lookup!$A$2:$A$1300,0)) -> #N/A
A65: Gloucester | B65: Gloucester, city and county of | C65: 18935 | D65: 960031 | E65: 1011 | F65: 120557 | G65: 7 | H65: 2004 | I65: 1126 | J65: 427087 | K65: 360 | L65: 62100 | M65: 2027 | N65: 223832 | O65: 127 | P65: 405461 | Q65: 32363 | R65: 326172 | S65: 2559607 | T65: =SUM(D65+F65+H65) -> 1082592 | U65: =T65/S65 -> 0.42295243 | V65: CB | W65: =_xlfn.CONCAT(B65," ",V65) -> Gloucester, city and county of CB | X65: =INDEX(Lookup!$A$2:$A$1349, MATCH(W65, Lookup!$B$2:$B$1349,0)) -> J04000537 | Y65: =INDEX(Lookup!$F$2:$F$1349, MATCH(W65, Lookup!$B$2:$B$1349,0)) -> e130346 | Z65: =INDEX(Lookup!$C$2:$C$1300, MATCH(X65, Lookup!$A$2:$A$1300,0)) -> Gloucestershire
A66: Great Yarmouth | B66: Great Yarmouth | C66: 16551 | D66: 746097 | E66: 729 | F66: 87446 | G66: 36 | H66: 10161 | I66: 1156 | J66: 289704 | K66: 205 | L66: 24641 | M66: 2108 | N66: 308643 | O66: 189 | P66: 328013 | Q66: 17523 | R66: 413968 | S66: 2226196 | T66: =SUM(D66+F66+H66) -> 843704 | U66: =T66/S66 -> 0.37898909 | V66: CB | W66: =_xlfn.CONCAT(B66," ",V66) -> Great Yarmouth CB | X66: =INDEX(Lookup!$A$2:$A$1349, MATCH(W66, Lookup!$B$2:$B$1349,0)) -> J04000552 | Y66: =INDEX(Lookup!$F$2:$F$1349, MATCH(W66, Lookup!$B$2:$B$1349,0)) -> e250758 | Z66: =INDEX(Lookup!$C$2:$C$1300, MATCH(X66, Lookup!$A$2:$A$1300,0)) -> Norfolk
A67: Grimsby | B67: Grimsby | C67: 27934 | D67: 1431700 | E67: 1523 | F67: 196401 | G67: 84 | H67: 20483 | I67: 1833 | J67: 458484 | K67: 876 | L67: 80022 | M67: 1675 | N67: 350837 | O67: 319 | P67: 479710 | Q67: 17857 | R67: 385183 | S67: 3420677 | T67: =SUM(D67+F67+H67) -> 1648584 | U67: =T67/S67 -> 0.4819467 | V67: CB | W67: =_xlfn.CONCAT(B67," ",V67) -> Grimsby CB | X67: =INDEX(Lookup!$A$2:$A$1349, MATCH(W67, Lookup!$B$2:$B$1349,0)) -> J04000554 | Y67: =INDEX(Lookup!$F$2:$F$1349, MATCH(W67, Lookup!$B$2:$B$1349,0)) -> e240736 | Z67: =INDEX(Lookup!$C$2:$C$1300, MATCH(X67, Lookup!$A$2:$A$1300,0)) -> Humberside
A68: Halifax | B68: Halifax | C68: 33863 | D68: 1058679 | E68: 377 | F68: 48347 | G68: 28 | H68: 6967 | I68: 1895 | J68: 316541 | K68: 318 | L68: 54001 | M68: 4781 | N68: 204676 | O68: 465 | P68: 487846 | Q68: 39681 | R68: 361533 | S68: 2578274 | T68: =SUM(D68+F68+H68) -> 1113993 | U68: =T68/S68 -> 0.43206928 | V68: CB | W68: =_xlfn.CONCAT(B68," ",V68) -> Halifax CB | X68: =INDEX(Lookup!$A$2:$A$1349, MATCH(W68, Lookup!$B$2:$B$1349,0)) -> J04000566 | Y68: =INDEX(Lookup!$F$2:$F$1349, MATCH(W68, Lookup!$B$2:$B$1349,0)) -> e461203 | Z68: =INDEX(Lookup!$C$2:$C$1300, MATCH(X68, Lookup!$A$2:$A$1300,0)) -> West Yorkshire
A69: Hastings | B69: Hastings | C69: 18897 | D69: 1160802 | E69: 4057 | F69: 512232 | G69: 295 | H69: 71318 | I69: 1504 | J69: 326730 | K69: 229 | L69: 29600 | M69: 2225 | N69: 179224 | O69: 124 | P69: 87502 | Q69: 25094 | R69: 245069 | S69: 2637571 | T69: =SUM(D69+F69+H69) -> 1744352 | U69: =T69/S69 -> 0.66134788 | V69: CB | W69: =_xlfn.CONCAT(B69," ",V69) -> Hastings CB | X69: =INDEX(Lookup!$A$2:$A$1349, MATCH(W69, Lookup!$B$2:$B$1349,0)) -> J04000584 | Y69: =INDEX(Lookup!$F$2:$F$1349, MATCH(W69, Lookup!$B$2:$B$1349,0)) -> e371031 | Z69: =INDEX(Lookup!$C$2:$C$1300, MATCH(X69, Lookup!$A$2:$A$1300,0)) -> East Sussex
A70: Huddersfield | B70: Huddersfield | C70: 45045 | D70: 1576792 | E70: 892 | F70: 113813 | G70: 65 | H70: 17248 | I70: 2153 | J70: 445194 | K70: 443 | L70: 65205 | M70: 6440 | N70: 280980 | O70: 534 | P70: 867566 | Q70: 31274 | R70: 603572 | S70: 4001644 | T70: =SUM(D70+F70+H70) -> 1707853 | U70: =T70/S70 -> 0.42678784 | V70: CB | W70: =_xlfn.CONCAT(B70," ",V70) -> Huddersfield CB | X70: =INDEX(Lookup!$A$2:$A$1349, MATCH(W70, Lookup!$B$2:$B$1349,0)) -> J04000657 | Y70: =INDEX(Lookup!$F$2:$F$1349, MATCH(W70, Lookup!$B$2:$B$1349,0)) -> e461204 | Z70: =INDEX(Lookup!$C$2:$C$1300, MATCH(X70, Lookup!$A$2:$A$1300,0)) -> West Yorkshire
A71: Ipswich | B71: Ipswich | C71: 34720 | D71: 2024568 | E71: 2234 | F71: 270399 | G71: 38 | H71: 9471 | I71: 1581 | J71: 690249 | K71: 442 | L71: 152271 | M71: 2811 | N71: 347806 | O71: 173 | P71: 739435 | Q71: 34244 | R71: 660506 | S71: 4928949 | T71: =SUM(D71+F71+H71) -> 2304438 | U71: =T71/S71 -> 0.46753131 | V71: CB | W71: =_xlfn.CONCAT(B71," ",V71) -> Ipswich CB | X71: =INDEX(Lookup!$A$2:$A$1349, MATCH(W71, Lookup!$B$2:$B$1349,0)) -> J04000671 | Y71: =INDEX(Lookup!$F$2:$F$1349, MATCH(W71, Lookup!$B$2:$B$1349,0)) -> e340971 | Z71: =INDEX(Lookup!$C$2:$C$1300, MATCH(X71, Lookup!$A$2:$A$1300,0)) -> Suffolk
A72: Kingston upon Hull | B72: Kingston upon Hull, city and county of | C72: 92686 | D72: 3589054 | E72: 825 | F72: 101940 | G72: 23 | H72: 5214 | I72: 4617 | J72: 1342001 | K72: 1591 | L72: 200498 | M72: 5849 | N72: 620175 | O72: 808 | P72: 1416887 | Q72: 54878 | R72: 1381152 | S72: 8711799 | T72: =SUM(D72+F72+H72) -> 3696208 | U72: =T72/S72 -> 0.42427609 | V72: CB | W72: =_xlfn.CONCAT(B72," ",V72) -> Kingston upon Hull, city and county of CB | X72: =INDEX(Lookup!$A$2:$A$1349, MATCH(W72, Lookup!$B$2:$B$1349,0)) -> J04000699 | Y72: =INDEX(Lookup!$F$2:$F$1349, MATCH(W72, Lookup!$B$2:$B$1349,0)) -> e441148 | Z72: =INDEX(Lookup!$C$2:$C$1300, MATCH(X72, Lookup!$A$2:$A$1300,0)) -> Humberside
...

Sheet Lookup
A1: LA61CD | B1: LA61NM | C1: cty_1981 | D1: rgn | E1: srgn | F1: equiv_1971_cd | G1: equiv_1971_nm | H1: equiv_2001_nm | I1: notes
A2: J04000063 | B2: Axbridge RD | C2: Avon | D2: South West | E2: Rest of England | F2: e320923 | G2: AXBRIDGE R.D. | H2: 0 | I2: 0
A3: J04000099 | B3: Bath, City of CB | C3: Avon | D3: South West | E3: Rest of England | F3: e320902 | G3: BATH C.B. | H3: 0 | I3: 0
A4: J04000100 | B4: Bathavon RD | C4: Avon | D4: South West | E4: Rest of England | F4: e320925 | G4: BATHAVON R.D. | H4: 0 | I4: 0
A5: J04000213 | B5: Bristol, City and County of CB | C5: Avon | D5: South West | E5: Rest of England | F5: e130345 | G5: BRISTOL C.B. | H5: 0 | I5: 0
A6: J04000327 | B6: Clevedon UD | C6: Avon | D6: South West | E6: Rest of England | F6: e320906 | G6: CLEVEDON U.D. | H6: 0 | I6: 0
A7: J04000332 | B7: Clutton RD | C7: Avon | D7: South West | E7: Rest of England | F7: e320928 | G7: CLUTTON R.D. | H7: 0 | I7: 0
A8: J04000690 | B8: Keynsham UD | C8: Avon | D8: South West | E8: Rest of England | F8: e320911 | G8: KEYNSHAM U.D. | H8: 0 | I8: 0
A9: J04000701 | B9: Kingswood UD | C9: Avon | D9: South West | E9: Rest of England | F9: e130350 | G9: KINGSWOOD U.D. | H9: 0 | I9: 0
A10: J04000775 | B10: Long Ashton RD | C10: Avon | D10: South West | E10: Rest of England | F10: e320932 | G10: LONG ASHTON R.D. | H10: 0 | I10: 0
A11: J04000822 | B11: Mangotsfield UD | C11: Avon | D11: South West | E11: Rest of England | F11: e130351 | G11: MANGOTSFIELD U.D. | H11: 0 | I11: 0
A12: J04000938 | B12: Norton Radstock UD | C12: Avon | D12: South West | E12: Rest of England | F12: e320913 | G12: NORTON-RADSTOCK U.D. | H12: 0 | I12: 0
A13: J04001008 | B13: Portishead UD | C13: Avon | D13: South West | E13: Rest of England | F13: e320914 | G13: PORTISHEAD U.D. | H13: 0 | I13: 0
... A25: J04000681 | B25: Kempston UD | C25: Bedfordshire | D25: East of England | E25: Greater South East | F25: e010005 | G25: KEMPSTON U.D. | H25: 0 | I25: 0
A26: J04000733 | B26: Leighton Buzzard UD | C26: Bedfordshire | D26: East of England | E26: Greater South East | F26: e010006 | G26: LEIGHTON-LINSLADE U.D. | H26: 0 | I26: Merged into Leighton-Linslade in 1965
A27: J04000747 | B27: Linslade UD | C27: Bedfordshire | D27: East of England | E27: Greater South East | F27: e010006 | G27: LEIGHTON-LINSLADE U.D. | H27: 0 | I27: Merged into Leighton-Linslade in 1965
A28: J04000790 | B28: Luton MB | C28: Bedfordshire | D28: East of England | E28: Greater South East | F28: e010000 | G28: LUTON C.B. | H28: 0 | I28: 0
A29: J04000791 | B29: Luton RD | C29: Bedfordshire | D29: East of England | E29: Greater South East | F29: e010000 | G29: LUTON C.B. | H29: 0 | I29: 0
A30: J04001103 | B30: Sandy UD | C30: Bedfordshire | D30: East of England | E30: Greater South East | F30: e010007 | G30: SANDY U.D. | H30: 0 | I30: 0
A31: J04000184 | B31: Bradfield RD | C31: Berkshire | D31: South East | E31: Greater South East | F31: e020021 | G31: BRADFIELD R.D. | H31: 0 | I31: 0
A32: J04000347 | B32: Cookham RD | C32: Berkshire | D32: South East | E32: Greater South East | F32: e020022 | G32: COOKHAM R.D. | H32: Windsor and Maidenhead UA | I32: 0
A33: J04000456 | B33: Easthampstead RD | C33: Berkshire | D33: South East | E33: Greater South East | F33: e020023 | G33: EASTHAMPSTEAD R.D. | H33: Bracknell Forest UA | I33: 0
A34: J04000483 | B34: Eton UD | C34: Berkshire | D34: South East | E34: Greater South East | F34: e030038 | G34: ETON U.D. | H34: Windsor and Maidenhead UA | I34: 0
A35: J04000658 | B35: Hungerford RD | C35: Berkshire | D35: South East | E35: Greater South East | F35: e020026 | G35: HUNGERFORD R.D. | H35: 0 | I35: 0
A36: J04000808 | B36: Maidenhead MB | C36: Berkshire | D36: South East | E36: Greater South East | F36: e020014 | G36: MAIDENHEAD M.B. | H36: Windsor and Maidenhead UA | I36: 0
A37: J04000891 | B37: New Windsor MB | C37: Berkshire | D37: South East | E37: Greater South East | F37: e020016 | G37: NEW WINDSOR M.B. | H37: Windsor and Maidenhead UA | I37: 0
A38: J04000896 | B38: Newbury MB | C38: Berkshire | D38: South East | E38: Greater South East | F38: e020015 | G38: NEWBURY M.B. | H38: 0 | I38: 0
A39: J04000897 | B39: Newbury RD | C39: Berkshire | D39: South East | E39: Greater South East | F39: e020027 | G39: NEWBURY R.D. | H39: 0 | I39: 0
A40: J04001036 | B40: Reading CB | C40: Berkshire | D40: South East | E40: Greater South East | F40: e020012 | G40: READING C.B. | H40: Reading UA | I40: 0
A41: J04001150 | B41: Slough MB | C41: Berkshire | D41: South East | E41: Greater South East | F41: e030043 | G41: SLOUGH M.B. | H41: Slough UA | I41: 0
A42: J04001425 | B42: Windsor RD | C42: Berkshire | D42: South East | E42: Greater South East | F42: e020031 | G42: WINDSOR R.D. | H42: Windsor and Maidenhead UA | I42: 0
A43: J04001440 | B43: Wokingham MB | C43: Berkshire | D43: South East | E43: Greater South East | F43: e020019 | G43: WOKINGHAM M.B. | H43: Wokingham | I43: 0
A44: J04001441 | B44: Wokingham RD | C44: Berkshire | D44: South East | E44: Greater South East | F44: e020032 | G44: WOKINGHAM R.D. | H44: Wokingham | I44: 0
A45: J04000037 | B45: Amersham RD | C45: Buckinghamshire | D45: South East | E45: Greater South East | F45: e030046 | G45: AMERSHAM R.D. | H45: Chiltern | I45: 0
A46: J04000065 | B46: Aylesbury MB | C46: Buckinghamshire | D46: South East | E46: Greater South East | F46: e030033 | G46: AYLESBURY M.B. | H46: 0 | I46: 0
A47: J04000066 | B47: Aylesbury RD | C47: Buckinghamshire | D47: South East | E47: Greater South East | F47: e030047 | G47: AYLESBURY R.D. | H47: 0 | I47: 0
A48: J04000104 | B48: Beaconsfield UD | C48: Buckinghamshire | D48: South East | E48: Greater South East | F48: e030034 | G48: BEACONSFIELD U.D. | H48: South Bucks | I48: 0
A49: J04000164 | B49: Bletchley UD | C49: Buckinghamshire | D49: South East | E49: Greater South East | F49: e030035 | G49: BLETCHLEY U.D. | H49: 0 | I49: 0
A50: J04000226 | B50: Buckingham MB | C50: Buckinghamshire | D50: South East | E50: Greater South East | F50: e030036 | G50: BUCKINGHAM M.B. | H50: 0 | I50: 0
A51: J04000227 | B51: Buckingham RD | C51: Buckinghamshire | D51: South East | E51: Greater South East | F51: e030048 | G51: BUCKINGHAM R.D. | H51: 0 | I51: 0
...
